2019-04-11 17:21:36,672 - telegram.ext.updater - INFO - Received signal 2 (SIGINT), stopping...
2019-04-11 17:23:10,273 - telegram.ext.updater - INFO - Received signal 2 (SIGINT), stopping...
2019-04-11 17:23:21,049 - telegram.ext.dispatcher - ERROR - An uncaught error was raised while processing the update
Traceback (most recent call last):
  File "C:\Users\Administrator\AppData\Local\Programs\Python\Python37-32\lib\site-packages\telegram\ext\dispatcher.py", line 279, in process_update
    handler.handle_update(update, self)
  File "C:\Users\Administrator\AppData\Local\Programs\Python\Python37-32\lib\site-packages\telegram\ext\conversationhandler.py", line 305, in handle_update
    new_state = self.current_handler.handle_update(update, dispatcher)
  File "C:\Users\Administrator\AppData\Local\Programs\Python\Python37-32\lib\site-packages\telegram\ext\regexhandler.py", line 173, in handle_update
    return self.callback(dispatcher.bot, update, **optional_args)
  File "telegrambot.py", line 90, in day
    if stock_id == '/cancel':
NameError: name 'stock_id' is not defined
2019-04-11 17:23:50,197 - telegram.ext.updater - INFO - Received signal 2 (SIGINT), stopping...
2019-04-11 17:32:59,296 - telegram.ext.updater - INFO - Received signal 2 (SIGINT), stopping...
2019-04-11 17:34:50,888 - telegram.ext.updater - INFO - Received signal 2 (SIGINT), stopping...
2019-04-11 17:35:04,664 - telegram.ext.dispatcher - ERROR - An uncaught error was raised while processing the update
Traceback (most recent call last):
  File "C:\Users\Administrator\AppData\Local\Programs\Python\Python37-32\lib\site-packages\telegram\ext\dispatcher.py", line 279, in process_update
    handler.handle_update(update, self)
  File "C:\Users\Administrator\AppData\Local\Programs\Python\Python37-32\lib\site-packages\telegram\ext\conversationhandler.py", line 305, in handle_update
    new_state = self.current_handler.handle_update(update, dispatcher)
  File "C:\Users\Administrator\AppData\Local\Programs\Python\Python37-32\lib\site-packages\telegram\ext\regexhandler.py", line 173, in handle_update
    return self.callback(dispatcher.bot, update, **optional_args)
  File "telegrambot.py", line 111, in stock
    update.message.reply_text(data.to_json)
  File "C:\Users\Administrator\AppData\Local\Programs\Python\Python37-32\lib\site-packages\telegram\message.py", line 455, in reply_text
    return self.bot.send_message(self.chat_id, *args, **kwargs)
  File "C:\Users\Administrator\AppData\Local\Programs\Python\Python37-32\lib\site-packages\telegram\bot.py", line 65, in decorator
    result = func(self, *args, **kwargs)
  File "C:\Users\Administrator\AppData\Local\Programs\Python\Python37-32\lib\site-packages\telegram\bot.py", line 90, in decorator
    result = self._request.post(url, data, timeout=kwargs.get('timeout'))
  File "C:\Users\Administrator\AppData\Local\Programs\Python\Python37-32\lib\site-packages\telegram\utils\request.py", line 308, in post
    body=json.dumps(data).encode('utf-8'),
  File "C:\Users\Administrator\AppData\Local\Programs\Python\Python37-32\lib\json\__init__.py", line 231, in dumps
    return _default_encoder.encode(obj)
  File "C:\Users\Administrator\AppData\Local\Programs\Python\Python37-32\lib\json\encoder.py", line 199, in encode
    chunks = self.iterencode(o, _one_shot=True)
  File "C:\Users\Administrator\AppData\Local\Programs\Python\Python37-32\lib\json\encoder.py", line 257, in iterencode
    return _iterencode(o, 0)
  File "C:\Users\Administrator\AppData\Local\Programs\Python\Python37-32\lib\json\encoder.py", line 179, in default
    raise TypeError(f'Object of type {o.__class__.__name__} '
TypeError: Object of type method is not JSON serializable
2019-04-11 17:37:33,376 - telegram.ext.updater - INFO - Received signal 2 (SIGINT), stopping...
2019-04-11 17:52:43,817 - telegram.ext.updater - INFO - Received signal 2 (SIGINT), stopping...
2019-04-11 17:53:12,099 - telegram.ext.dispatcher - ERROR - An uncaught error was raised while processing the update
Traceback (most recent call last):
  File "C:\Users\Administrator\AppData\Local\Programs\Python\Python37-32\lib\site-packages\telegram\ext\dispatcher.py", line 279, in process_update
    handler.handle_update(update, self)
  File "C:\Users\Administrator\AppData\Local\Programs\Python\Python37-32\lib\site-packages\telegram\ext\conversationhandler.py", line 305, in handle_update
    new_state = self.current_handler.handle_update(update, dispatcher)
  File "C:\Users\Administrator\AppData\Local\Programs\Python\Python37-32\lib\site-packages\telegram\ext\regexhandler.py", line 173, in handle_update
    return self.callback(dispatcher.bot, update, **optional_args)
  File "telegrambot.py", line 115, in stock
    update.message.reply_text(data)
  File "C:\Users\Administrator\AppData\Local\Programs\Python\Python37-32\lib\site-packages\telegram\message.py", line 455, in reply_text
    return self.bot.send_message(self.chat_id, *args, **kwargs)
  File "C:\Users\Administrator\AppData\Local\Programs\Python\Python37-32\lib\site-packages\telegram\bot.py", line 65, in decorator
    result = func(self, *args, **kwargs)
  File "C:\Users\Administrator\AppData\Local\Programs\Python\Python37-32\lib\site-packages\telegram\bot.py", line 90, in decorator
    result = self._request.post(url, data, timeout=kwargs.get('timeout'))
  File "C:\Users\Administrator\AppData\Local\Programs\Python\Python37-32\lib\site-packages\telegram\utils\request.py", line 308, in post
    body=json.dumps(data).encode('utf-8'),
  File "C:\Users\Administrator\AppData\Local\Programs\Python\Python37-32\lib\json\__init__.py", line 231, in dumps
    return _default_encoder.encode(obj)
  File "C:\Users\Administrator\AppData\Local\Programs\Python\Python37-32\lib\json\encoder.py", line 199, in encode
    chunks = self.iterencode(o, _one_shot=True)
  File "C:\Users\Administrator\AppData\Local\Programs\Python\Python37-32\lib\json\encoder.py", line 257, in iterencode
    return _iterencode(o, 0)
  File "C:\Users\Administrator\AppData\Local\Programs\Python\Python37-32\lib\json\encoder.py", line 179, in default
    raise TypeError(f'Object of type {o.__class__.__name__} '
TypeError: Object of type method is not JSON serializable
2019-04-11 17:54:10,081 - telegram.ext.updater - INFO - Received signal 2 (SIGINT), stopping...
2019-04-11 17:54:35,969 - telegram.ext.dispatcher - ERROR - An uncaught error was raised while processing the update
Traceback (most recent call last):
  File "C:\Users\Administrator\AppData\Local\Programs\Python\Python37-32\lib\site-packages\telegram\ext\dispatcher.py", line 279, in process_update
    handler.handle_update(update, self)
  File "C:\Users\Administrator\AppData\Local\Programs\Python\Python37-32\lib\site-packages\telegram\ext\conversationhandler.py", line 305, in handle_update
    new_state = self.current_handler.handle_update(update, dispatcher)
  File "C:\Users\Administrator\AppData\Local\Programs\Python\Python37-32\lib\site-packages\telegram\ext\regexhandler.py", line 173, in handle_update
    return self.callback(dispatcher.bot, update, **optional_args)
  File "telegrambot.py", line 115, in stock
    update.message.reply_text(type(data))
  File "C:\Users\Administrator\AppData\Local\Programs\Python\Python37-32\lib\site-packages\telegram\message.py", line 455, in reply_text
    return self.bot.send_message(self.chat_id, *args, **kwargs)
  File "C:\Users\Administrator\AppData\Local\Programs\Python\Python37-32\lib\site-packages\telegram\bot.py", line 65, in decorator
    result = func(self, *args, **kwargs)
  File "C:\Users\Administrator\AppData\Local\Programs\Python\Python37-32\lib\site-packages\telegram\bot.py", line 90, in decorator
    result = self._request.post(url, data, timeout=kwargs.get('timeout'))
  File "C:\Users\Administrator\AppData\Local\Programs\Python\Python37-32\lib\site-packages\telegram\utils\request.py", line 308, in post
    body=json.dumps(data).encode('utf-8'),
  File "C:\Users\Administrator\AppData\Local\Programs\Python\Python37-32\lib\json\__init__.py", line 231, in dumps
    return _default_encoder.encode(obj)
  File "C:\Users\Administrator\AppData\Local\Programs\Python\Python37-32\lib\json\encoder.py", line 199, in encode
    chunks = self.iterencode(o, _one_shot=True)
  File "C:\Users\Administrator\AppData\Local\Programs\Python\Python37-32\lib\json\encoder.py", line 257, in iterencode
    return _iterencode(o, 0)
  File "C:\Users\Administrator\AppData\Local\Programs\Python\Python37-32\lib\json\encoder.py", line 179, in default
    raise TypeError(f'Object of type {o.__class__.__name__} '
TypeError: Object of type type is not JSON serializable
2019-04-11 17:54:38,921 - telegram.ext.updater - INFO - Received signal 2 (SIGINT), stopping...
2019-04-11 17:54:42,913 - telegram.ext.updater - INFO - Received signal 2 (SIGINT), stopping...
2019-04-11 17:55:06,353 - telegram.ext.dispatcher - ERROR - An uncaught error was raised while processing the update
Traceback (most recent call last):
  File "C:\Users\Administrator\AppData\Local\Programs\Python\Python37-32\lib\site-packages\telegram\ext\dispatcher.py", line 279, in process_update
    handler.handle_update(update, self)
  File "C:\Users\Administrator\AppData\Local\Programs\Python\Python37-32\lib\site-packages\telegram\ext\conversationhandler.py", line 305, in handle_update
    new_state = self.current_handler.handle_update(update, dispatcher)
  File "C:\Users\Administrator\AppData\Local\Programs\Python\Python37-32\lib\site-packages\telegram\ext\regexhandler.py", line 173, in handle_update
    return self.callback(dispatcher.bot, update, **optional_args)
  File "telegrambot.py", line 115, in stock
    update.message.reply_text(type(data))
  File "C:\Users\Administrator\AppData\Local\Programs\Python\Python37-32\lib\site-packages\telegram\message.py", line 455, in reply_text
    return self.bot.send_message(self.chat_id, *args, **kwargs)
  File "C:\Users\Administrator\AppData\Local\Programs\Python\Python37-32\lib\site-packages\telegram\bot.py", line 65, in decorator
    result = func(self, *args, **kwargs)
  File "C:\Users\Administrator\AppData\Local\Programs\Python\Python37-32\lib\site-packages\telegram\bot.py", line 90, in decorator
    result = self._request.post(url, data, timeout=kwargs.get('timeout'))
  File "C:\Users\Administrator\AppData\Local\Programs\Python\Python37-32\lib\site-packages\telegram\utils\request.py", line 308, in post
    body=json.dumps(data).encode('utf-8'),
  File "C:\Users\Administrator\AppData\Local\Programs\Python\Python37-32\lib\json\__init__.py", line 231, in dumps
    return _default_encoder.encode(obj)
  File "C:\Users\Administrator\AppData\Local\Programs\Python\Python37-32\lib\json\encoder.py", line 199, in encode
    chunks = self.iterencode(o, _one_shot=True)
  File "C:\Users\Administrator\AppData\Local\Programs\Python\Python37-32\lib\json\encoder.py", line 257, in iterencode
    return _iterencode(o, 0)
  File "C:\Users\Administrator\AppData\Local\Programs\Python\Python37-32\lib\json\encoder.py", line 179, in default
    raise TypeError(f'Object of type {o.__class__.__name__} '
TypeError: Object of type type is not JSON serializable
2019-04-11 17:57:08,273 - telegram.ext.updater - INFO - Received signal 2 (SIGINT), stopping...
2019-04-11 18:00:01,777 - telegram.ext.updater - INFO - Received signal 2 (SIGINT), stopping...
2019-04-11 18:08:55,450 - telegram.ext.updater - INFO - Received signal 2 (SIGINT), stopping...
2019-04-11 18:09:16,185 - telegram.ext.dispatcher - ERROR - An uncaught error was raised while processing the update
Traceback (most recent call last):
  File "C:\Users\Administrator\AppData\Local\Programs\Python\Python37-32\lib\site-packages\telegram\ext\dispatcher.py", line 279, in process_update
    handler.handle_update(update, self)
  File "C:\Users\Administrator\AppData\Local\Programs\Python\Python37-32\lib\site-packages\telegram\ext\conversationhandler.py", line 305, in handle_update
    new_state = self.current_handler.handle_update(update, dispatcher)
  File "C:\Users\Administrator\AppData\Local\Programs\Python\Python37-32\lib\site-packages\telegram\ext\regexhandler.py", line 173, in handle_update
    return self.callback(dispatcher.bot, update, **optional_args)
  File "telegrambot.py", line 115, in stock
    update.message.reply_text(type(data.style))
AttributeError: 'str' object has no attribute 'style'
2019-04-11 18:09:52,385 - telegram.ext.updater - INFO - Received signal 2 (SIGINT), stopping...
2019-04-11 18:10:09,277 - telegram.ext.dispatcher - ERROR - An uncaught error was raised while processing the update
Traceback (most recent call last):
  File "C:\Users\Administrator\AppData\Local\Programs\Python\Python37-32\lib\site-packages\telegram\ext\dispatcher.py", line 279, in process_update
    handler.handle_update(update, self)
  File "C:\Users\Administrator\AppData\Local\Programs\Python\Python37-32\lib\site-packages\telegram\ext\conversationhandler.py", line 305, in handle_update
    new_state = self.current_handler.handle_update(update, dispatcher)
  File "C:\Users\Administrator\AppData\Local\Programs\Python\Python37-32\lib\site-packages\telegram\ext\regexhandler.py", line 173, in handle_update
    return self.callback(dispatcher.bot, update, **optional_args)
  File "telegrambot.py", line 115, in stock
    update.message.reply_text(type(data))
  File "C:\Users\Administrator\AppData\Local\Programs\Python\Python37-32\lib\site-packages\telegram\message.py", line 455, in reply_text
    return self.bot.send_message(self.chat_id, *args, **kwargs)
  File "C:\Users\Administrator\AppData\Local\Programs\Python\Python37-32\lib\site-packages\telegram\bot.py", line 65, in decorator
    result = func(self, *args, **kwargs)
  File "C:\Users\Administrator\AppData\Local\Programs\Python\Python37-32\lib\site-packages\telegram\bot.py", line 90, in decorator
    result = self._request.post(url, data, timeout=kwargs.get('timeout'))
  File "C:\Users\Administrator\AppData\Local\Programs\Python\Python37-32\lib\site-packages\telegram\utils\request.py", line 308, in post
    body=json.dumps(data).encode('utf-8'),
  File "C:\Users\Administrator\AppData\Local\Programs\Python\Python37-32\lib\json\__init__.py", line 231, in dumps
    return _default_encoder.encode(obj)
  File "C:\Users\Administrator\AppData\Local\Programs\Python\Python37-32\lib\json\encoder.py", line 199, in encode
    chunks = self.iterencode(o, _one_shot=True)
  File "C:\Users\Administrator\AppData\Local\Programs\Python\Python37-32\lib\json\encoder.py", line 257, in iterencode
    return _iterencode(o, 0)
  File "C:\Users\Administrator\AppData\Local\Programs\Python\Python37-32\lib\json\encoder.py", line 179, in default
    raise TypeError(f'Object of type {o.__class__.__name__} '
TypeError: Object of type type is not JSON serializable
2019-04-11 18:17:57,114 - telegram.ext.updater - INFO - Received signal 2 (SIGINT), stopping...
2019-04-11 18:18:08,915 - telegram.ext.dispatcher - ERROR - An uncaught error was raised while processing the update
Traceback (most recent call last):
  File "C:\Users\Administrator\AppData\Local\Programs\Python\Python37-32\lib\site-packages\telegram\ext\dispatcher.py", line 279, in process_update
    handler.handle_update(update, self)
  File "C:\Users\Administrator\AppData\Local\Programs\Python\Python37-32\lib\site-packages\telegram\ext\conversationhandler.py", line 305, in handle_update
    new_state = self.current_handler.handle_update(update, dispatcher)
  File "C:\Users\Administrator\AppData\Local\Programs\Python\Python37-32\lib\site-packages\telegram\ext\regexhandler.py", line 173, in handle_update
    return self.callback(dispatcher.bot, update, **optional_args)
  File "telegrambot.py", line 115, in stock
    update.message.reply_text(data.replace('\n','\n----------------------------\n'))
AttributeError: 'function' object has no attribute 'replace'
2019-04-11 18:18:33,010 - telegram.ext.updater - INFO - Received signal 2 (SIGINT), stopping...
2019-04-11 18:25:13,435 - telegram.ext.updater - INFO - Received signal 2 (SIGINT), stopping...
2019-04-11 18:25:34,489 - telegram.ext.dispatcher - ERROR - An uncaught error was raised while processing the update
Traceback (most recent call last):
  File "C:\Users\Administrator\AppData\Local\Programs\Python\Python37-32\lib\site-packages\telegram\ext\dispatcher.py", line 279, in process_update
    handler.handle_update(update, self)
  File "C:\Users\Administrator\AppData\Local\Programs\Python\Python37-32\lib\site-packages\telegram\ext\regexhandler.py", line 173, in handle_update
    return self.callback(dispatcher.bot, update, **optional_args)
  File "E:/Program/GITHUBKIVY/MY/Kivy/telegrambot.py", line 153, in location
    update.message.reply_text(str(update.message.location.latitude) +'\n'+str(update.message.location.longtitude))
AttributeError: 'NoneType' object has no attribute 'latitude'
2019-04-11 18:25:35,526 - telegram.ext.dispatcher - ERROR - An uncaught error was raised while processing the update
Traceback (most recent call last):
  File "C:\Users\Administrator\AppData\Local\Programs\Python\Python37-32\lib\site-packages\telegram\ext\dispatcher.py", line 279, in process_update
    handler.handle_update(update, self)
  File "C:\Users\Administrator\AppData\Local\Programs\Python\Python37-32\lib\site-packages\telegram\ext\regexhandler.py", line 173, in handle_update
    return self.callback(dispatcher.bot, update, **optional_args)
  File "E:/Program/GITHUBKIVY/MY/Kivy/telegrambot.py", line 153, in location
    update.message.reply_text(str(update.message.location.latitude) +'\n'+str(update.message.location.longtitude))
AttributeError: 'NoneType' object has no attribute 'latitude'
2019-04-11 18:54:13,229 - telegram.ext.dispatcher - ERROR - An uncaught error was raised while processing the update
Traceback (most recent call last):
  File "C:\Users\Administrator\AppData\Local\Programs\Python\Python37-32\lib\site-packages\telegram\ext\dispatcher.py", line 279, in process_update
    handler.handle_update(update, self)
  File "C:\Users\Administrator\AppData\Local\Programs\Python\Python37-32\lib\site-packages\telegram\ext\regexhandler.py", line 173, in handle_update
    return self.callback(dispatcher.bot, update, **optional_args)
  File "E:/Program/GITHUBKIVY/MY/Kivy/telegrambot.py", line 154, in location
    update.message.reply_text('Tell me your location',reply_markup = ReplyKeyboardMarkup(location_keyboard))
  File "C:\Users\Administrator\AppData\Local\Programs\Python\Python37-32\lib\site-packages\telegram\message.py", line 455, in reply_text
    return self.bot.send_message(self.chat_id, *args, **kwargs)
  File "C:\Users\Administrator\AppData\Local\Programs\Python\Python37-32\lib\site-packages\telegram\bot.py", line 65, in decorator
    result = func(self, *args, **kwargs)
  File "C:\Users\Administrator\AppData\Local\Programs\Python\Python37-32\lib\site-packages\telegram\bot.py", line 86, in decorator
    data['reply_markup'] = reply_markup.to_json()
  File "C:\Users\Administrator\AppData\Local\Programs\Python\Python37-32\lib\site-packages\telegram\base.py", line 57, in to_json
    return json.dumps(self.to_dict())
  File "C:\Users\Administrator\AppData\Local\Programs\Python\Python37-32\lib\site-packages\telegram\replykeyboardmarkup.py", line 79, in to_dict
    for row in self.keyboard:
  File "C:\Users\Administrator\AppData\Local\Programs\Python\Python37-32\lib\site-packages\telegram\base.py", line 39, in __getitem__
    return self.__dict__[item]
KeyError: 0
2019-04-11 18:55:03,610 - telegram.ext.dispatcher - ERROR - An uncaught error was raised while processing the update
Traceback (most recent call last):
  File "C:\Users\Administrator\AppData\Local\Programs\Python\Python37-32\lib\site-packages\telegram\ext\dispatcher.py", line 279, in process_update
    handler.handle_update(update, self)
  File "C:\Users\Administrator\AppData\Local\Programs\Python\Python37-32\lib\site-packages\telegram\ext\regexhandler.py", line 173, in handle_update
    return self.callback(dispatcher.bot, update, **optional_args)
  File "E:/Program/GITHUBKIVY/MY/Kivy/telegrambot.py", line 155, in location
    update.message.reply_text(str(update.message.location.latitude) +'\n'+str(update.message.location.longtitude))
AttributeError: 'NoneType' object has no attribute 'latitude'
