2019-04-14 03:21:51,813 - telegram.ext.updater - INFO - Received signal 2 (SIGINT), stopping...
2019-04-14 03:22:18,599 - telegram.ext.dispatcher - ERROR - An uncaught error was raised while processing the update
Traceback (most recent call last):
  File "C:\Users\Administrator\AppData\Local\Programs\Python\Python37-32\lib\site-packages\telegram\ext\dispatcher.py", line 279, in process_update
    handler.handle_update(update, self)
  File "C:\Users\Administrator\AppData\Local\Programs\Python\Python37-32\lib\site-packages\telegram\ext\regexhandler.py", line 173, in handle_update
    return self.callback(dispatcher.bot, update, **optional_args)
  File "telegrambot.py", line 61, in news
    bot.sendMessage('\n'.join(newsarray),disable_web_page_preview = True ,reply_markup = InlineKeyboardMarkup(keyboard))
  File "C:\Users\Administrator\AppData\Local\Programs\Python\Python37-32\lib\site-packages\telegram\bot.py", line 65, in decorator
    result = func(self, *args, **kwargs)
  File "C:\Users\Administrator\AppData\Local\Programs\Python\Python37-32\lib\site-packages\telegram\bot.py", line 76, in decorator
    url, data = func(self, *args, **kwargs)
TypeError: send_message() missing 1 required positional argument: 'text'
2019-04-14 03:22:38,229 - telegram.ext.updater - INFO - Received signal 2 (SIGINT), stopping...
2019-04-14 03:23:09,364 - telegram.ext.dispatcher - ERROR - An uncaught error was raised while processing the update
Traceback (most recent call last):
  File "C:\Users\Administrator\AppData\Local\Programs\Python\Python37-32\lib\site-packages\telegram\ext\dispatcher.py", line 279, in process_update
    handler.handle_update(update, self)
  File "C:\Users\Administrator\AppData\Local\Programs\Python\Python37-32\lib\site-packages\telegram\ext\regexhandler.py", line 173, in handle_update
    return self.callback(dispatcher.bot, update, **optional_args)
  File "telegrambot.py", line 61, in news
    bot.sendMessage(text = '\n'.join(newsarray),disable_web_page_preview = True ,reply_markup = InlineKeyboardMarkup(keyboard))
  File "C:\Users\Administrator\AppData\Local\Programs\Python\Python37-32\lib\site-packages\telegram\bot.py", line 65, in decorator
    result = func(self, *args, **kwargs)
  File "C:\Users\Administrator\AppData\Local\Programs\Python\Python37-32\lib\site-packages\telegram\bot.py", line 76, in decorator
    url, data = func(self, *args, **kwargs)
TypeError: send_message() missing 1 required positional argument: 'chat_id'
2019-04-14 03:23:37,501 - telegram.ext.updater - INFO - Received signal 2 (SIGINT), stopping...
2019-04-14 03:24:52,770 - telegram.ext.dispatcher - ERROR - An uncaught error was raised while processing the update
Traceback (most recent call last):
  File "C:\Users\Administrator\AppData\Local\Programs\Python\Python37-32\lib\site-packages\telegram\ext\dispatcher.py", line 279, in process_update
    handler.handle_update(update, self)
  File "C:\Users\Administrator\AppData\Local\Programs\Python\Python37-32\lib\site-packages\telegram\ext\regexhandler.py", line 173, in handle_update
    return self.callback(dispatcher.bot, update, **optional_args)
  File "telegrambot.py", line 65, in news
    print(update.message.message_id[-1])
TypeError: 'int' object is not subscriptable
2019-04-14 03:24:53,748 - telegram.ext.dispatcher - ERROR - An uncaught error was raised while processing the update
Traceback (most recent call last):
  File "C:\Users\Administrator\AppData\Local\Programs\Python\Python37-32\lib\site-packages\telegram\ext\dispatcher.py", line 279, in process_update
    handler.handle_update(update, self)
  File "C:\Users\Administrator\AppData\Local\Programs\Python\Python37-32\lib\site-packages\telegram\ext\callbackqueryhandler.py", line 143, in handle_update
    return self.callback(dispatcher.bot, update, **optional_args)
  File "telegrambot.py", line 44, in button
    bot.delete_message(message_id=update.message.message_id[-i])
AttributeError: 'NoneType' object has no attribute 'message_id'
2019-04-14 03:26:13,733 - telegram.ext.updater - INFO - Received signal 2 (SIGINT), stopping...
2019-04-14 03:26:50,038 - telegram.ext.dispatcher - ERROR - An uncaught error was raised while processing the update
Traceback (most recent call last):
  File "C:\Users\Administrator\AppData\Local\Programs\Python\Python37-32\lib\site-packages\telegram\ext\dispatcher.py", line 279, in process_update
    handler.handle_update(update, self)
  File "C:\Users\Administrator\AppData\Local\Programs\Python\Python37-32\lib\site-packages\telegram\ext\regexhandler.py", line 173, in handle_update
    return self.callback(dispatcher.bot, update, **optional_args)
  File "telegrambot.py", line 65, in news
    print(update.message.message_id[-1])
TypeError: 'int' object is not subscriptable
2019-04-14 03:26:51,424 - telegram.ext.dispatcher - ERROR - An uncaught error was raised while processing the update
Traceback (most recent call last):
  File "C:\Users\Administrator\AppData\Local\Programs\Python\Python37-32\lib\site-packages\telegram\ext\dispatcher.py", line 279, in process_update
    handler.handle_update(update, self)
  File "C:\Users\Administrator\AppData\Local\Programs\Python\Python37-32\lib\site-packages\telegram\ext\callbackqueryhandler.py", line 143, in handle_update
    return self.callback(dispatcher.bot, update, **optional_args)
  File "telegrambot.py", line 44, in button
    bot.delete_message(message_id=update.message.message_id[-i])
AttributeError: 'NoneType' object has no attribute 'message_id'
2019-04-14 03:29:47,277 - telegram.ext.updater - INFO - Received signal 2 (SIGINT), stopping...
2019-04-14 03:30:18,392 - telegram.ext.dispatcher - ERROR - An uncaught error was raised while processing the update
Traceback (most recent call last):
  File "C:\Users\Administrator\AppData\Local\Programs\Python\Python37-32\lib\site-packages\telegram\ext\dispatcher.py", line 279, in process_update
    handler.handle_update(update, self)
  File "C:\Users\Administrator\AppData\Local\Programs\Python\Python37-32\lib\site-packages\telegram\ext\regexhandler.py", line 173, in handle_update
    return self.callback(dispatcher.bot, update, **optional_args)
  File "telegrambot.py", line 65, in news
    print(update.message.message_id[-1])
TypeError: 'int' object is not subscriptable
2019-04-14 03:30:19,478 - telegram.ext.dispatcher - ERROR - An uncaught error was raised while processing the update
Traceback (most recent call last):
  File "C:\Users\Administrator\AppData\Local\Programs\Python\Python37-32\lib\site-packages\telegram\ext\dispatcher.py", line 279, in process_update
    handler.handle_update(update, self)
  File "C:\Users\Administrator\AppData\Local\Programs\Python\Python37-32\lib\site-packages\telegram\ext\callbackqueryhandler.py", line 143, in handle_update
    return self.callback(dispatcher.bot, update, **optional_args)
  File "telegrambot.py", line 44, in button
    bot.delete_message()
  File "C:\Users\Administrator\AppData\Local\Programs\Python\Python37-32\lib\site-packages\telegram\bot.py", line 65, in decorator
    result = func(self, *args, **kwargs)
TypeError: delete_message() missing 2 required positional arguments: 'chat_id' and 'message_id'
2019-04-14 03:30:59,469 - telegram.ext.updater - INFO - Received signal 2 (SIGINT), stopping...
2019-04-14 03:32:07,327 - telegram.ext.dispatcher - ERROR - An uncaught error was raised while processing the update
Traceback (most recent call last):
  File "C:\Users\Administrator\AppData\Local\Programs\Python\Python37-32\lib\site-packages\telegram\ext\dispatcher.py", line 279, in process_update
    handler.handle_update(update, self)
  File "C:\Users\Administrator\AppData\Local\Programs\Python\Python37-32\lib\site-packages\telegram\ext\regexhandler.py", line 173, in handle_update
    return self.callback(dispatcher.bot, update, **optional_args)
  File "telegrambot.py", line 65, in news
    print(update.message.message_id[-1])
TypeError: 'int' object is not subscriptable
2019-04-14 03:32:08,182 - telegram.ext.dispatcher - ERROR - An uncaught error was raised while processing the update
Traceback (most recent call last):
  File "C:\Users\Administrator\AppData\Local\Programs\Python\Python37-32\lib\site-packages\telegram\ext\dispatcher.py", line 279, in process_update
    handler.handle_update(update, self)
  File "C:\Users\Administrator\AppData\Local\Programs\Python\Python37-32\lib\site-packages\telegram\ext\callbackqueryhandler.py", line 143, in handle_update
    return self.callback(dispatcher.bot, update, **optional_args)
  File "telegrambot.py", line 44, in button
    bot.delete_message(chat_id = update.message.chat_id)
AttributeError: 'NoneType' object has no attribute 'chat_id'
2019-04-14 03:41:31,366 - telegram.ext.updater - INFO - Received signal 2 (SIGINT), stopping...
2019-04-14 03:42:08,448 - telegram.ext.dispatcher - ERROR - An uncaught error was raised while processing the update
Traceback (most recent call last):
  File "C:\Users\Administrator\AppData\Local\Programs\Python\Python37-32\lib\site-packages\telegram\ext\dispatcher.py", line 279, in process_update
    handler.handle_update(update, self)
  File "C:\Users\Administrator\AppData\Local\Programs\Python\Python37-32\lib\site-packages\telegram\ext\regexhandler.py", line 173, in handle_update
    return self.callback(dispatcher.bot, update, **optional_args)
  File "telegrambot.py", line 64, in news
    print(update.message.message_id[-1])
TypeError: 'int' object is not subscriptable
2019-04-14 03:42:10,123 - telegram.ext.dispatcher - WARNING - A TelegramError was raised while processing the Update
2019-04-14 03:42:10,123 - telegram.ext.dispatcher - ERROR - No error handlers are registered, logging exception.
Traceback (most recent call last):
  File "C:\Users\Administrator\AppData\Local\Programs\Python\Python37-32\lib\site-packages\telegram\ext\dispatcher.py", line 279, in process_update
    handler.handle_update(update, self)
  File "C:\Users\Administrator\AppData\Local\Programs\Python\Python37-32\lib\site-packages\telegram\ext\callbackqueryhandler.py", line 143, in handle_update
    return self.callback(dispatcher.bot, update, **optional_args)
  File "telegrambot.py", line 44, in button
    bot.delete_message(chat_id = update.effective_message.chat_id,message_id = update.effective_message.message_id)
  File "C:\Users\Administrator\AppData\Local\Programs\Python\Python37-32\lib\site-packages\telegram\bot.py", line 65, in decorator
    result = func(self, *args, **kwargs)
  File "C:\Users\Administrator\AppData\Local\Programs\Python\Python37-32\lib\site-packages\telegram\bot.py", line 296, in delete_message
    result = self._request.post(url, data, timeout=timeout)
  File "C:\Users\Administrator\AppData\Local\Programs\Python\Python37-32\lib\site-packages\telegram\utils\request.py", line 309, in post
    headers={'Content-Type': 'application/json'})
  File "C:\Users\Administrator\AppData\Local\Programs\Python\Python37-32\lib\site-packages\telegram\utils\request.py", line 223, in _request_wrapper
    raise BadRequest(message)
telegram.error.BadRequest: Message to delete not found
2019-04-14 03:43:53,365 - telegram.ext.updater - INFO - Received signal 2 (SIGINT), stopping...
2019-04-14 03:44:27,953 - telegram.ext.dispatcher - ERROR - An uncaught error was raised while processing the update
Traceback (most recent call last):
  File "C:\Users\Administrator\AppData\Local\Programs\Python\Python37-32\lib\site-packages\telegram\ext\dispatcher.py", line 279, in process_update
    handler.handle_update(update, self)
  File "C:\Users\Administrator\AppData\Local\Programs\Python\Python37-32\lib\site-packages\telegram\ext\regexhandler.py", line 173, in handle_update
    return self.callback(dispatcher.bot, update, **optional_args)
  File "telegrambot.py", line 64, in news
    print(update.message.message_id[-1])
TypeError: 'int' object is not subscriptable
2019-04-14 03:44:29,343 - telegram.ext.dispatcher - ERROR - An uncaught error was raised while processing the update
Traceback (most recent call last):
  File "C:\Users\Administrator\AppData\Local\Programs\Python\Python37-32\lib\site-packages\telegram\ext\dispatcher.py", line 279, in process_update
    handler.handle_update(update, self)
  File "C:\Users\Administrator\AppData\Local\Programs\Python\Python37-32\lib\site-packages\telegram\ext\callbackqueryhandler.py", line 143, in handle_update
    return self.callback(dispatcher.bot, update, **optional_args)
  File "telegrambot.py", line 44, in button
    bot.delete_message(chat_id = update.effective_message.chat_id,message_id = update.effective_message.message_id[-(i+1)])
TypeError: 'int' object is not subscriptable
2019-04-14 03:46:57,670 - telegram.ext.updater - INFO - Received signal 2 (SIGINT), stopping...
2019-04-14 03:47:29,733 - telegram.ext.dispatcher - ERROR - An uncaught error was raised while processing the update
Traceback (most recent call last):
  File "C:\Users\Administrator\AppData\Local\Programs\Python\Python37-32\lib\site-packages\telegram\ext\dispatcher.py", line 279, in process_update
    handler.handle_update(update, self)
  File "C:\Users\Administrator\AppData\Local\Programs\Python\Python37-32\lib\site-packages\telegram\ext\regexhandler.py", line 173, in handle_update
    return self.callback(dispatcher.bot, update, **optional_args)
  File "telegrambot.py", line 64, in news
    print(update.message.message_id[-1])
TypeError: 'int' object is not subscriptable
2019-04-14 03:47:37,138 - telegram.ext.dispatcher - WARNING - A TelegramError was raised while processing the Update
2019-04-14 03:47:37,138 - telegram.ext.dispatcher - ERROR - No error handlers are registered, logging exception.
Traceback (most recent call last):
  File "C:\Users\Administrator\AppData\Local\Programs\Python\Python37-32\lib\site-packages\telegram\ext\dispatcher.py", line 279, in process_update
    handler.handle_update(update, self)
  File "C:\Users\Administrator\AppData\Local\Programs\Python\Python37-32\lib\site-packages\telegram\ext\callbackqueryhandler.py", line 143, in handle_update
    return self.callback(dispatcher.bot, update, **optional_args)
  File "telegrambot.py", line 44, in button
    bot.delete_message(chat_id = update.effective_message.chat_id,message_id = update.effective_message.message_id -(i+1))
  File "C:\Users\Administrator\AppData\Local\Programs\Python\Python37-32\lib\site-packages\telegram\bot.py", line 65, in decorator
    result = func(self, *args, **kwargs)
  File "C:\Users\Administrator\AppData\Local\Programs\Python\Python37-32\lib\site-packages\telegram\bot.py", line 296, in delete_message
    result = self._request.post(url, data, timeout=timeout)
  File "C:\Users\Administrator\AppData\Local\Programs\Python\Python37-32\lib\site-packages\telegram\utils\request.py", line 309, in post
    headers={'Content-Type': 'application/json'})
  File "C:\Users\Administrator\AppData\Local\Programs\Python\Python37-32\lib\site-packages\telegram\utils\request.py", line 223, in _request_wrapper
    raise BadRequest(message)
telegram.error.BadRequest: Message to delete not found
2019-04-14 03:51:16,359 - telegram.ext.updater - INFO - Received signal 2 (SIGINT), stopping...
2019-04-14 03:51:56,510 - telegram.ext.dispatcher - ERROR - An uncaught error was raised while processing the update
Traceback (most recent call last):
  File "C:\Users\Administrator\AppData\Local\Programs\Python\Python37-32\lib\site-packages\telegram\ext\dispatcher.py", line 279, in process_update
    handler.handle_update(update, self)
  File "C:\Users\Administrator\AppData\Local\Programs\Python\Python37-32\lib\site-packages\telegram\ext\regexhandler.py", line 173, in handle_update
    return self.callback(dispatcher.bot, update, **optional_args)
  File "telegrambot.py", line 62, in news
    print(update.message.message_id[-1])
TypeError: 'int' object is not subscriptable
2019-04-14 03:52:48,082 - telegram.ext.dispatcher - ERROR - An uncaught error was raised while processing the update
Traceback (most recent call last):
  File "C:\Users\Administrator\AppData\Local\Programs\Python\Python37-32\lib\site-packages\telegram\ext\dispatcher.py", line 279, in process_update
    handler.handle_update(update, self)
  File "C:\Users\Administrator\AppData\Local\Programs\Python\Python37-32\lib\site-packages\telegram\ext\regexhandler.py", line 173, in handle_update
    return self.callback(dispatcher.bot, update, **optional_args)
  File "telegrambot.py", line 62, in news
    print(update.message.message_id[-1])
TypeError: 'int' object is not subscriptable
2019-04-14 03:52:59,880 - telegram.ext.dispatcher - WARNING - A TelegramError was raised while processing the Update
2019-04-14 03:52:59,880 - telegram.ext.dispatcher - ERROR - No error handlers are registered, logging exception.
Traceback (most recent call last):
  File "C:\Users\Administrator\AppData\Local\Programs\Python\Python37-32\lib\site-packages\telegram\ext\dispatcher.py", line 279, in process_update
    handler.handle_update(update, self)
  File "C:\Users\Administrator\AppData\Local\Programs\Python\Python37-32\lib\site-packages\telegram\ext\callbackqueryhandler.py", line 143, in handle_update
    return self.callback(dispatcher.bot, update, **optional_args)
  File "telegrambot.py", line 44, in button
    bot.delete_message(chat_id = update.effective_message.chat_id,message_id = update.effective_message.message_id -i)
  File "C:\Users\Administrator\AppData\Local\Programs\Python\Python37-32\lib\site-packages\telegram\bot.py", line 65, in decorator
    result = func(self, *args, **kwargs)
  File "C:\Users\Administrator\AppData\Local\Programs\Python\Python37-32\lib\site-packages\telegram\bot.py", line 296, in delete_message
    result = self._request.post(url, data, timeout=timeout)
  File "C:\Users\Administrator\AppData\Local\Programs\Python\Python37-32\lib\site-packages\telegram\utils\request.py", line 309, in post
    headers={'Content-Type': 'application/json'})
  File "C:\Users\Administrator\AppData\Local\Programs\Python\Python37-32\lib\site-packages\telegram\utils\request.py", line 223, in _request_wrapper
    raise BadRequest(message)
telegram.error.BadRequest: Message to delete not found
2019-04-14 03:56:01,637 - telegram.ext.dispatcher - ERROR - An uncaught error was raised while processing the update
Traceback (most recent call last):
  File "C:\Users\Administrator\AppData\Local\Programs\Python\Python37-32\lib\site-packages\telegram\ext\dispatcher.py", line 279, in process_update
    handler.handle_update(update, self)
  File "C:\Users\Administrator\AppData\Local\Programs\Python\Python37-32\lib\site-packages\telegram\ext\regexhandler.py", line 173, in handle_update
    return self.callback(dispatcher.bot, update, **optional_args)
  File "telegrambot.py", line 62, in news
    print(update.message.message_id[-1])
TypeError: 'int' object is not subscriptable
2019-04-14 03:57:21,655 - telegram.ext.updater - INFO - Received signal 2 (SIGINT), stopping...
2019-04-14 03:59:10,224 - telegram.ext.dispatcher - WARNING - A TelegramError was raised while processing the Update
2019-04-14 03:59:10,224 - telegram.ext.dispatcher - ERROR - No error handlers are registered, logging exception.
Traceback (most recent call last):
  File "C:\Users\Administrator\AppData\Local\Programs\Python\Python37-32\lib\site-packages\telegram\ext\dispatcher.py", line 279, in process_update
    handler.handle_update(update, self)
  File "C:\Users\Administrator\AppData\Local\Programs\Python\Python37-32\lib\site-packages\telegram\ext\callbackqueryhandler.py", line 143, in handle_update
    return self.callback(dispatcher.bot, update, **optional_args)
  File "telegrambot.py", line 44, in button
    bot.delete_message(chat_id = update.effective_message.chat_id,message_id = message_id -i)
  File "C:\Users\Administrator\AppData\Local\Programs\Python\Python37-32\lib\site-packages\telegram\bot.py", line 65, in decorator
    result = func(self, *args, **kwargs)
  File "C:\Users\Administrator\AppData\Local\Programs\Python\Python37-32\lib\site-packages\telegram\bot.py", line 296, in delete_message
    result = self._request.post(url, data, timeout=timeout)
  File "C:\Users\Administrator\AppData\Local\Programs\Python\Python37-32\lib\site-packages\telegram\utils\request.py", line 309, in post
    headers={'Content-Type': 'application/json'})
  File "C:\Users\Administrator\AppData\Local\Programs\Python\Python37-32\lib\site-packages\telegram\utils\request.py", line 223, in _request_wrapper
    raise BadRequest(message)
telegram.error.BadRequest: Message to delete not found
2019-04-14 03:59:10,478 - telegram.ext.dispatcher - WARNING - A TelegramError was raised while processing the Update
2019-04-14 03:59:10,478 - telegram.ext.dispatcher - ERROR - No error handlers are registered, logging exception.
Traceback (most recent call last):
  File "C:\Users\Administrator\AppData\Local\Programs\Python\Python37-32\lib\site-packages\telegram\ext\dispatcher.py", line 279, in process_update
    handler.handle_update(update, self)
  File "C:\Users\Administrator\AppData\Local\Programs\Python\Python37-32\lib\site-packages\telegram\ext\callbackqueryhandler.py", line 143, in handle_update
    return self.callback(dispatcher.bot, update, **optional_args)
  File "telegrambot.py", line 44, in button
    bot.delete_message(chat_id = update.effective_message.chat_id,message_id = message_id -i)
  File "C:\Users\Administrator\AppData\Local\Programs\Python\Python37-32\lib\site-packages\telegram\bot.py", line 65, in decorator
    result = func(self, *args, **kwargs)
  File "C:\Users\Administrator\AppData\Local\Programs\Python\Python37-32\lib\site-packages\telegram\bot.py", line 296, in delete_message
    result = self._request.post(url, data, timeout=timeout)
  File "C:\Users\Administrator\AppData\Local\Programs\Python\Python37-32\lib\site-packages\telegram\utils\request.py", line 309, in post
    headers={'Content-Type': 'application/json'})
  File "C:\Users\Administrator\AppData\Local\Programs\Python\Python37-32\lib\site-packages\telegram\utils\request.py", line 223, in _request_wrapper
    raise BadRequest(message)
telegram.error.BadRequest: Message to delete not found
2019-04-14 03:59:10,730 - telegram.ext.dispatcher - WARNING - A TelegramError was raised while processing the Update
2019-04-14 03:59:10,730 - telegram.ext.dispatcher - ERROR - No error handlers are registered, logging exception.
Traceback (most recent call last):
  File "C:\Users\Administrator\AppData\Local\Programs\Python\Python37-32\lib\site-packages\telegram\ext\dispatcher.py", line 279, in process_update
    handler.handle_update(update, self)
  File "C:\Users\Administrator\AppData\Local\Programs\Python\Python37-32\lib\site-packages\telegram\ext\callbackqueryhandler.py", line 143, in handle_update
    return self.callback(dispatcher.bot, update, **optional_args)
  File "telegrambot.py", line 44, in button
    bot.delete_message(chat_id = update.effective_message.chat_id,message_id = message_id -i)
  File "C:\Users\Administrator\AppData\Local\Programs\Python\Python37-32\lib\site-packages\telegram\bot.py", line 65, in decorator
    result = func(self, *args, **kwargs)
  File "C:\Users\Administrator\AppData\Local\Programs\Python\Python37-32\lib\site-packages\telegram\bot.py", line 296, in delete_message
    result = self._request.post(url, data, timeout=timeout)
  File "C:\Users\Administrator\AppData\Local\Programs\Python\Python37-32\lib\site-packages\telegram\utils\request.py", line 309, in post
    headers={'Content-Type': 'application/json'})
  File "C:\Users\Administrator\AppData\Local\Programs\Python\Python37-32\lib\site-packages\telegram\utils\request.py", line 223, in _request_wrapper
    raise BadRequest(message)
telegram.error.BadRequest: Message to delete not found
2019-04-14 03:59:10,984 - telegram.ext.dispatcher - WARNING - A TelegramError was raised while processing the Update
2019-04-14 03:59:10,984 - telegram.ext.dispatcher - ERROR - No error handlers are registered, logging exception.
Traceback (most recent call last):
  File "C:\Users\Administrator\AppData\Local\Programs\Python\Python37-32\lib\site-packages\telegram\ext\dispatcher.py", line 279, in process_update
    handler.handle_update(update, self)
  File "C:\Users\Administrator\AppData\Local\Programs\Python\Python37-32\lib\site-packages\telegram\ext\callbackqueryhandler.py", line 143, in handle_update
    return self.callback(dispatcher.bot, update, **optional_args)
  File "telegrambot.py", line 44, in button
    bot.delete_message(chat_id = update.effective_message.chat_id,message_id = message_id -i)
  File "C:\Users\Administrator\AppData\Local\Programs\Python\Python37-32\lib\site-packages\telegram\bot.py", line 65, in decorator
    result = func(self, *args, **kwargs)
  File "C:\Users\Administrator\AppData\Local\Programs\Python\Python37-32\lib\site-packages\telegram\bot.py", line 296, in delete_message
    result = self._request.post(url, data, timeout=timeout)
  File "C:\Users\Administrator\AppData\Local\Programs\Python\Python37-32\lib\site-packages\telegram\utils\request.py", line 309, in post
    headers={'Content-Type': 'application/json'})
  File "C:\Users\Administrator\AppData\Local\Programs\Python\Python37-32\lib\site-packages\telegram\utils\request.py", line 223, in _request_wrapper
    raise BadRequest(message)
telegram.error.BadRequest: Message to delete not found
2019-04-14 03:59:20,925 - telegram.ext.dispatcher - WARNING - A TelegramError was raised while processing the Update
2019-04-14 03:59:20,925 - telegram.ext.dispatcher - ERROR - No error handlers are registered, logging exception.
Traceback (most recent call last):
  File "C:\Users\Administrator\AppData\Local\Programs\Python\Python37-32\lib\site-packages\telegram\ext\dispatcher.py", line 279, in process_update
    handler.handle_update(update, self)
  File "C:\Users\Administrator\AppData\Local\Programs\Python\Python37-32\lib\site-packages\telegram\ext\callbackqueryhandler.py", line 143, in handle_update
    return self.callback(dispatcher.bot, update, **optional_args)
  File "telegrambot.py", line 44, in button
    bot.delete_message(chat_id = update.effective_message.chat_id,message_id = message_id -i)
  File "C:\Users\Administrator\AppData\Local\Programs\Python\Python37-32\lib\site-packages\telegram\bot.py", line 65, in decorator
    result = func(self, *args, **kwargs)
  File "C:\Users\Administrator\AppData\Local\Programs\Python\Python37-32\lib\site-packages\telegram\bot.py", line 296, in delete_message
    result = self._request.post(url, data, timeout=timeout)
  File "C:\Users\Administrator\AppData\Local\Programs\Python\Python37-32\lib\site-packages\telegram\utils\request.py", line 309, in post
    headers={'Content-Type': 'application/json'})
  File "C:\Users\Administrator\AppData\Local\Programs\Python\Python37-32\lib\site-packages\telegram\utils\request.py", line 223, in _request_wrapper
    raise BadRequest(message)
telegram.error.BadRequest: Message to delete not found
2019-04-14 05:18:20,908 - telegram.ext.updater - INFO - Received signal 2 (SIGINT), stopping...
2019-04-14 05:20:12,051 - telegram.ext.updater - INFO - Received signal 2 (SIGINT), stopping...
2019-04-14 05:21:38,179 - telegram.ext.updater - INFO - Received signal 2 (SIGINT), stopping...
2019-04-14 05:23:15,763 - telegram.ext.updater - INFO - Received signal 2 (SIGINT), stopping...
2019-04-14 05:24:52,539 - telegram.ext.updater - INFO - Received signal 2 (SIGINT), stopping...
2019-04-14 05:25:38,686 - telegram.ext.dispatcher - WARNING - A TelegramError was raised while processing the Update
2019-04-14 05:25:38,686 - telegram.ext.dispatcher - ERROR - No error handlers are registered, logging exception.
Traceback (most recent call last):
  File "C:\Users\Administrator\AppData\Local\Programs\Python\Python37-32\lib\site-packages\telegram\ext\dispatcher.py", line 279, in process_update
    handler.handle_update(update, self)
  File "C:\Users\Administrator\AppData\Local\Programs\Python\Python37-32\lib\site-packages\telegram\ext\callbackqueryhandler.py", line 143, in handle_update
    return self.callback(dispatcher.bot, update, **optional_args)
  File "telegrambot.py", line 45, in button
    bot.delete_message(chat_id = update.effective_message.chat_id,message_id = update.effective_message.message_id)
  File "C:\Users\Administrator\AppData\Local\Programs\Python\Python37-32\lib\site-packages\telegram\bot.py", line 65, in decorator
    result = func(self, *args, **kwargs)
  File "C:\Users\Administrator\AppData\Local\Programs\Python\Python37-32\lib\site-packages\telegram\bot.py", line 296, in delete_message
    result = self._request.post(url, data, timeout=timeout)
  File "C:\Users\Administrator\AppData\Local\Programs\Python\Python37-32\lib\site-packages\telegram\utils\request.py", line 309, in post
    headers={'Content-Type': 'application/json'})
  File "C:\Users\Administrator\AppData\Local\Programs\Python\Python37-32\lib\site-packages\telegram\utils\request.py", line 223, in _request_wrapper
    raise BadRequest(message)
telegram.error.BadRequest: Message to delete not found
2019-04-14 05:25:42,602 - telegram.ext.dispatcher - WARNING - A TelegramError was raised while processing the Update
2019-04-14 05:25:42,602 - telegram.ext.dispatcher - ERROR - No error handlers are registered, logging exception.
Traceback (most recent call last):
  File "C:\Users\Administrator\AppData\Local\Programs\Python\Python37-32\lib\site-packages\telegram\ext\dispatcher.py", line 279, in process_update
    handler.handle_update(update, self)
  File "C:\Users\Administrator\AppData\Local\Programs\Python\Python37-32\lib\site-packages\telegram\ext\callbackqueryhandler.py", line 143, in handle_update
    return self.callback(dispatcher.bot, update, **optional_args)
  File "telegrambot.py", line 45, in button
    bot.delete_message(chat_id = update.effective_message.chat_id,message_id = update.effective_message.message_id)
  File "C:\Users\Administrator\AppData\Local\Programs\Python\Python37-32\lib\site-packages\telegram\bot.py", line 65, in decorator
    result = func(self, *args, **kwargs)
  File "C:\Users\Administrator\AppData\Local\Programs\Python\Python37-32\lib\site-packages\telegram\bot.py", line 296, in delete_message
    result = self._request.post(url, data, timeout=timeout)
  File "C:\Users\Administrator\AppData\Local\Programs\Python\Python37-32\lib\site-packages\telegram\utils\request.py", line 309, in post
    headers={'Content-Type': 'application/json'})
  File "C:\Users\Administrator\AppData\Local\Programs\Python\Python37-32\lib\site-packages\telegram\utils\request.py", line 223, in _request_wrapper
    raise BadRequest(message)
telegram.error.BadRequest: Message to delete not found
2019-04-14 05:25:45,022 - telegram.ext.dispatcher - WARNING - A TelegramError was raised while processing the Update
2019-04-14 05:25:45,022 - telegram.ext.dispatcher - ERROR - No error handlers are registered, logging exception.
Traceback (most recent call last):
  File "C:\Users\Administrator\AppData\Local\Programs\Python\Python37-32\lib\site-packages\telegram\ext\dispatcher.py", line 279, in process_update
    handler.handle_update(update, self)
  File "C:\Users\Administrator\AppData\Local\Programs\Python\Python37-32\lib\site-packages\telegram\ext\callbackqueryhandler.py", line 143, in handle_update
    return self.callback(dispatcher.bot, update, **optional_args)
  File "telegrambot.py", line 45, in button
    bot.delete_message(chat_id = update.effective_message.chat_id,message_id = update.effective_message.message_id)
  File "C:\Users\Administrator\AppData\Local\Programs\Python\Python37-32\lib\site-packages\telegram\bot.py", line 65, in decorator
    result = func(self, *args, **kwargs)
  File "C:\Users\Administrator\AppData\Local\Programs\Python\Python37-32\lib\site-packages\telegram\bot.py", line 296, in delete_message
    result = self._request.post(url, data, timeout=timeout)
  File "C:\Users\Administrator\AppData\Local\Programs\Python\Python37-32\lib\site-packages\telegram\utils\request.py", line 309, in post
    headers={'Content-Type': 'application/json'})
  File "C:\Users\Administrator\AppData\Local\Programs\Python\Python37-32\lib\site-packages\telegram\utils\request.py", line 223, in _request_wrapper
    raise BadRequest(message)
telegram.error.BadRequest: Message to delete not found
2019-04-14 05:25:47,396 - telegram.ext.dispatcher - WARNING - A TelegramError was raised while processing the Update
2019-04-14 05:25:47,396 - telegram.ext.dispatcher - ERROR - No error handlers are registered, logging exception.
Traceback (most recent call last):
  File "C:\Users\Administrator\AppData\Local\Programs\Python\Python37-32\lib\site-packages\telegram\ext\dispatcher.py", line 279, in process_update
    handler.handle_update(update, self)
  File "C:\Users\Administrator\AppData\Local\Programs\Python\Python37-32\lib\site-packages\telegram\ext\callbackqueryhandler.py", line 143, in handle_update
    return self.callback(dispatcher.bot, update, **optional_args)
  File "telegrambot.py", line 45, in button
    bot.delete_message(chat_id = update.effective_message.chat_id,message_id = update.effective_message.message_id)
  File "C:\Users\Administrator\AppData\Local\Programs\Python\Python37-32\lib\site-packages\telegram\bot.py", line 65, in decorator
    result = func(self, *args, **kwargs)
  File "C:\Users\Administrator\AppData\Local\Programs\Python\Python37-32\lib\site-packages\telegram\bot.py", line 296, in delete_message
    result = self._request.post(url, data, timeout=timeout)
  File "C:\Users\Administrator\AppData\Local\Programs\Python\Python37-32\lib\site-packages\telegram\utils\request.py", line 309, in post
    headers={'Content-Type': 'application/json'})
  File "C:\Users\Administrator\AppData\Local\Programs\Python\Python37-32\lib\site-packages\telegram\utils\request.py", line 223, in _request_wrapper
    raise BadRequest(message)
telegram.error.BadRequest: Message to delete not found
2019-04-14 05:25:48,646 - telegram.ext.dispatcher - WARNING - A TelegramError was raised while processing the Update
2019-04-14 05:25:48,646 - telegram.ext.dispatcher - ERROR - No error handlers are registered, logging exception.
Traceback (most recent call last):
  File "C:\Users\Administrator\AppData\Local\Programs\Python\Python37-32\lib\site-packages\telegram\ext\dispatcher.py", line 279, in process_update
    handler.handle_update(update, self)
  File "C:\Users\Administrator\AppData\Local\Programs\Python\Python37-32\lib\site-packages\telegram\ext\callbackqueryhandler.py", line 143, in handle_update
    return self.callback(dispatcher.bot, update, **optional_args)
  File "telegrambot.py", line 45, in button
    bot.delete_message(chat_id = update.effective_message.chat_id,message_id = update.effective_message.message_id)
  File "C:\Users\Administrator\AppData\Local\Programs\Python\Python37-32\lib\site-packages\telegram\bot.py", line 65, in decorator
    result = func(self, *args, **kwargs)
  File "C:\Users\Administrator\AppData\Local\Programs\Python\Python37-32\lib\site-packages\telegram\bot.py", line 296, in delete_message
    result = self._request.post(url, data, timeout=timeout)
  File "C:\Users\Administrator\AppData\Local\Programs\Python\Python37-32\lib\site-packages\telegram\utils\request.py", line 309, in post
    headers={'Content-Type': 'application/json'})
  File "C:\Users\Administrator\AppData\Local\Programs\Python\Python37-32\lib\site-packages\telegram\utils\request.py", line 223, in _request_wrapper
    raise BadRequest(message)
telegram.error.BadRequest: Message to delete not found
2019-04-14 05:25:49,914 - telegram.ext.dispatcher - WARNING - A TelegramError was raised while processing the Update
2019-04-14 05:25:49,914 - telegram.ext.dispatcher - ERROR - No error handlers are registered, logging exception.
Traceback (most recent call last):
  File "C:\Users\Administrator\AppData\Local\Programs\Python\Python37-32\lib\site-packages\telegram\ext\dispatcher.py", line 279, in process_update
    handler.handle_update(update, self)
  File "C:\Users\Administrator\AppData\Local\Programs\Python\Python37-32\lib\site-packages\telegram\ext\callbackqueryhandler.py", line 143, in handle_update
    return self.callback(dispatcher.bot, update, **optional_args)
  File "telegrambot.py", line 45, in button
    bot.delete_message(chat_id = update.effective_message.chat_id,message_id = update.effective_message.message_id)
  File "C:\Users\Administrator\AppData\Local\Programs\Python\Python37-32\lib\site-packages\telegram\bot.py", line 65, in decorator
    result = func(self, *args, **kwargs)
  File "C:\Users\Administrator\AppData\Local\Programs\Python\Python37-32\lib\site-packages\telegram\bot.py", line 296, in delete_message
    result = self._request.post(url, data, timeout=timeout)
  File "C:\Users\Administrator\AppData\Local\Programs\Python\Python37-32\lib\site-packages\telegram\utils\request.py", line 309, in post
    headers={'Content-Type': 'application/json'})
  File "C:\Users\Administrator\AppData\Local\Programs\Python\Python37-32\lib\site-packages\telegram\utils\request.py", line 223, in _request_wrapper
    raise BadRequest(message)
telegram.error.BadRequest: Message to delete not found
2019-04-14 05:25:51,274 - telegram.ext.dispatcher - WARNING - A TelegramError was raised while processing the Update
2019-04-14 05:25:51,274 - telegram.ext.dispatcher - ERROR - No error handlers are registered, logging exception.
Traceback (most recent call last):
  File "C:\Users\Administrator\AppData\Local\Programs\Python\Python37-32\lib\site-packages\telegram\ext\dispatcher.py", line 279, in process_update
    handler.handle_update(update, self)
  File "C:\Users\Administrator\AppData\Local\Programs\Python\Python37-32\lib\site-packages\telegram\ext\callbackqueryhandler.py", line 143, in handle_update
    return self.callback(dispatcher.bot, update, **optional_args)
  File "telegrambot.py", line 45, in button
    bot.delete_message(chat_id = update.effective_message.chat_id,message_id = update.effective_message.message_id)
  File "C:\Users\Administrator\AppData\Local\Programs\Python\Python37-32\lib\site-packages\telegram\bot.py", line 65, in decorator
    result = func(self, *args, **kwargs)
  File "C:\Users\Administrator\AppData\Local\Programs\Python\Python37-32\lib\site-packages\telegram\bot.py", line 296, in delete_message
    result = self._request.post(url, data, timeout=timeout)
  File "C:\Users\Administrator\AppData\Local\Programs\Python\Python37-32\lib\site-packages\telegram\utils\request.py", line 309, in post
    headers={'Content-Type': 'application/json'})
  File "C:\Users\Administrator\AppData\Local\Programs\Python\Python37-32\lib\site-packages\telegram\utils\request.py", line 223, in _request_wrapper
    raise BadRequest(message)
telegram.error.BadRequest: Message to delete not found
2019-04-14 05:25:52,666 - telegram.ext.dispatcher - WARNING - A TelegramError was raised while processing the Update
2019-04-14 05:25:52,666 - telegram.ext.dispatcher - ERROR - No error handlers are registered, logging exception.
Traceback (most recent call last):
  File "C:\Users\Administrator\AppData\Local\Programs\Python\Python37-32\lib\site-packages\telegram\ext\dispatcher.py", line 279, in process_update
    handler.handle_update(update, self)
  File "C:\Users\Administrator\AppData\Local\Programs\Python\Python37-32\lib\site-packages\telegram\ext\callbackqueryhandler.py", line 143, in handle_update
    return self.callback(dispatcher.bot, update, **optional_args)
  File "telegrambot.py", line 45, in button
    bot.delete_message(chat_id = update.effective_message.chat_id,message_id = update.effective_message.message_id)
  File "C:\Users\Administrator\AppData\Local\Programs\Python\Python37-32\lib\site-packages\telegram\bot.py", line 65, in decorator
    result = func(self, *args, **kwargs)
  File "C:\Users\Administrator\AppData\Local\Programs\Python\Python37-32\lib\site-packages\telegram\bot.py", line 296, in delete_message
    result = self._request.post(url, data, timeout=timeout)
  File "C:\Users\Administrator\AppData\Local\Programs\Python\Python37-32\lib\site-packages\telegram\utils\request.py", line 309, in post
    headers={'Content-Type': 'application/json'})
  File "C:\Users\Administrator\AppData\Local\Programs\Python\Python37-32\lib\site-packages\telegram\utils\request.py", line 223, in _request_wrapper
    raise BadRequest(message)
telegram.error.BadRequest: Message to delete not found
2019-04-14 05:25:53,583 - telegram.ext.dispatcher - WARNING - A TelegramError was raised while processing the Update
2019-04-14 05:25:53,583 - telegram.ext.dispatcher - ERROR - No error handlers are registered, logging exception.
Traceback (most recent call last):
  File "C:\Users\Administrator\AppData\Local\Programs\Python\Python37-32\lib\site-packages\telegram\ext\dispatcher.py", line 279, in process_update
    handler.handle_update(update, self)
  File "C:\Users\Administrator\AppData\Local\Programs\Python\Python37-32\lib\site-packages\telegram\ext\callbackqueryhandler.py", line 143, in handle_update
    return self.callback(dispatcher.bot, update, **optional_args)
  File "telegrambot.py", line 45, in button
    bot.delete_message(chat_id = update.effective_message.chat_id,message_id = update.effective_message.message_id)
  File "C:\Users\Administrator\AppData\Local\Programs\Python\Python37-32\lib\site-packages\telegram\bot.py", line 65, in decorator
    result = func(self, *args, **kwargs)
  File "C:\Users\Administrator\AppData\Local\Programs\Python\Python37-32\lib\site-packages\telegram\bot.py", line 296, in delete_message
    result = self._request.post(url, data, timeout=timeout)
  File "C:\Users\Administrator\AppData\Local\Programs\Python\Python37-32\lib\site-packages\telegram\utils\request.py", line 309, in post
    headers={'Content-Type': 'application/json'})
  File "C:\Users\Administrator\AppData\Local\Programs\Python\Python37-32\lib\site-packages\telegram\utils\request.py", line 223, in _request_wrapper
    raise BadRequest(message)
telegram.error.BadRequest: Message to delete not found
2019-04-14 05:25:54,835 - telegram.ext.dispatcher - WARNING - A TelegramError was raised while processing the Update
2019-04-14 05:25:54,835 - telegram.ext.dispatcher - ERROR - No error handlers are registered, logging exception.
Traceback (most recent call last):
  File "C:\Users\Administrator\AppData\Local\Programs\Python\Python37-32\lib\site-packages\telegram\ext\dispatcher.py", line 279, in process_update
    handler.handle_update(update, self)
  File "C:\Users\Administrator\AppData\Local\Programs\Python\Python37-32\lib\site-packages\telegram\ext\callbackqueryhandler.py", line 143, in handle_update
    return self.callback(dispatcher.bot, update, **optional_args)
  File "telegrambot.py", line 45, in button
    bot.delete_message(chat_id = update.effective_message.chat_id,message_id = update.effective_message.message_id)
  File "C:\Users\Administrator\AppData\Local\Programs\Python\Python37-32\lib\site-packages\telegram\bot.py", line 65, in decorator
    result = func(self, *args, **kwargs)
  File "C:\Users\Administrator\AppData\Local\Programs\Python\Python37-32\lib\site-packages\telegram\bot.py", line 296, in delete_message
    result = self._request.post(url, data, timeout=timeout)
  File "C:\Users\Administrator\AppData\Local\Programs\Python\Python37-32\lib\site-packages\telegram\utils\request.py", line 309, in post
    headers={'Content-Type': 'application/json'})
  File "C:\Users\Administrator\AppData\Local\Programs\Python\Python37-32\lib\site-packages\telegram\utils\request.py", line 223, in _request_wrapper
    raise BadRequest(message)
telegram.error.BadRequest: Message to delete not found
2019-04-14 05:25:55,825 - telegram.ext.dispatcher - WARNING - A TelegramError was raised while processing the Update
2019-04-14 05:25:55,825 - telegram.ext.dispatcher - ERROR - No error handlers are registered, logging exception.
Traceback (most recent call last):
  File "C:\Users\Administrator\AppData\Local\Programs\Python\Python37-32\lib\site-packages\telegram\ext\dispatcher.py", line 279, in process_update
    handler.handle_update(update, self)
  File "C:\Users\Administrator\AppData\Local\Programs\Python\Python37-32\lib\site-packages\telegram\ext\callbackqueryhandler.py", line 143, in handle_update
    return self.callback(dispatcher.bot, update, **optional_args)
  File "telegrambot.py", line 45, in button
    bot.delete_message(chat_id = update.effective_message.chat_id,message_id = update.effective_message.message_id)
  File "C:\Users\Administrator\AppData\Local\Programs\Python\Python37-32\lib\site-packages\telegram\bot.py", line 65, in decorator
    result = func(self, *args, **kwargs)
  File "C:\Users\Administrator\AppData\Local\Programs\Python\Python37-32\lib\site-packages\telegram\bot.py", line 296, in delete_message
    result = self._request.post(url, data, timeout=timeout)
  File "C:\Users\Administrator\AppData\Local\Programs\Python\Python37-32\lib\site-packages\telegram\utils\request.py", line 309, in post
    headers={'Content-Type': 'application/json'})
  File "C:\Users\Administrator\AppData\Local\Programs\Python\Python37-32\lib\site-packages\telegram\utils\request.py", line 223, in _request_wrapper
    raise BadRequest(message)
telegram.error.BadRequest: Message to delete not found
2019-04-14 05:25:56,839 - telegram.ext.dispatcher - WARNING - A TelegramError was raised while processing the Update
2019-04-14 05:25:56,839 - telegram.ext.dispatcher - ERROR - No error handlers are registered, logging exception.
Traceback (most recent call last):
  File "C:\Users\Administrator\AppData\Local\Programs\Python\Python37-32\lib\site-packages\telegram\ext\dispatcher.py", line 279, in process_update
    handler.handle_update(update, self)
  File "C:\Users\Administrator\AppData\Local\Programs\Python\Python37-32\lib\site-packages\telegram\ext\callbackqueryhandler.py", line 143, in handle_update
    return self.callback(dispatcher.bot, update, **optional_args)
  File "telegrambot.py", line 45, in button
    bot.delete_message(chat_id = update.effective_message.chat_id,message_id = update.effective_message.message_id)
  File "C:\Users\Administrator\AppData\Local\Programs\Python\Python37-32\lib\site-packages\telegram\bot.py", line 65, in decorator
    result = func(self, *args, **kwargs)
  File "C:\Users\Administrator\AppData\Local\Programs\Python\Python37-32\lib\site-packages\telegram\bot.py", line 296, in delete_message
    result = self._request.post(url, data, timeout=timeout)
  File "C:\Users\Administrator\AppData\Local\Programs\Python\Python37-32\lib\site-packages\telegram\utils\request.py", line 309, in post
    headers={'Content-Type': 'application/json'})
  File "C:\Users\Administrator\AppData\Local\Programs\Python\Python37-32\lib\site-packages\telegram\utils\request.py", line 223, in _request_wrapper
    raise BadRequest(message)
telegram.error.BadRequest: Message to delete not found
2019-04-14 05:35:47,639 - telegram.ext.dispatcher - ERROR - An uncaught error was raised while processing the update
Traceback (most recent call last):
  File "C:\Users\Administrator\AppData\Local\Programs\Python\Python37-32\lib\site-packages\telegram\ext\dispatcher.py", line 279, in process_update
    handler.handle_update(update, self)
  File "C:\Users\Administrator\AppData\Local\Programs\Python\Python37-32\lib\site-packages\telegram\ext\callbackqueryhandler.py", line 143, in handle_update
    return self.callback(dispatcher.bot, update, **optional_args)
  File "telegrambot.py", line 45, in button
    bot.delete(chat_id = update.effective_message.chat_id,message_id = update.effective_message.message_id)
AttributeError: 'Bot' object has no attribute 'delete'
2019-04-14 05:35:52,542 - telegram.ext.dispatcher - ERROR - An uncaught error was raised while processing the update
Traceback (most recent call last):
  File "C:\Users\Administrator\AppData\Local\Programs\Python\Python37-32\lib\site-packages\telegram\ext\dispatcher.py", line 279, in process_update
    handler.handle_update(update, self)
  File "C:\Users\Administrator\AppData\Local\Programs\Python\Python37-32\lib\site-packages\telegram\ext\callbackqueryhandler.py", line 143, in handle_update
    return self.callback(dispatcher.bot, update, **optional_args)
  File "telegrambot.py", line 45, in button
    bot.delete(chat_id = update.effective_message.chat_id,message_id = update.effective_message.message_id)
AttributeError: 'Bot' object has no attribute 'delete'
2019-04-14 05:35:57,138 - telegram.ext.dispatcher - ERROR - An uncaught error was raised while processing the update
Traceback (most recent call last):
  File "C:\Users\Administrator\AppData\Local\Programs\Python\Python37-32\lib\site-packages\telegram\ext\dispatcher.py", line 279, in process_update
    handler.handle_update(update, self)
  File "C:\Users\Administrator\AppData\Local\Programs\Python\Python37-32\lib\site-packages\telegram\ext\callbackqueryhandler.py", line 143, in handle_update
    return self.callback(dispatcher.bot, update, **optional_args)
  File "telegrambot.py", line 45, in button
    bot.delete(chat_id = update.effective_message.chat_id,message_id = update.effective_message.message_id)
AttributeError: 'Bot' object has no attribute 'delete'
2019-04-14 07:54:22,420 - telegram.ext.updater - ERROR - Error while getting Updates: Internal server error: restart (500)
2019-04-14 07:54:22,420 - telegram.ext.dispatcher - ERROR - No error handlers are registered, logging exception.
Traceback (most recent call last):
  File "C:\Users\Administrator\AppData\Local\Programs\Python\Python37-32\lib\site-packages\telegram\ext\updater.py", line 319, in _network_loop_retry
    if not action_cb():
  File "C:\Users\Administrator\AppData\Local\Programs\Python\Python37-32\lib\site-packages\telegram\ext\updater.py", line 280, in polling_action_cb
    allowed_updates=allowed_updates)
  File "C:\Users\Administrator\AppData\Local\Programs\Python\Python37-32\lib\site-packages\telegram\bot.py", line 65, in decorator
    result = func(self, *args, **kwargs)
  File "C:\Users\Administrator\AppData\Local\Programs\Python\Python37-32\lib\site-packages\telegram\bot.py", line 1975, in get_updates
    result = self._request.post(url, data, timeout=float(read_latency) + float(timeout))
  File "C:\Users\Administrator\AppData\Local\Programs\Python\Python37-32\lib\site-packages\telegram\utils\request.py", line 309, in post
    headers={'Content-Type': 'application/json'})
  File "C:\Users\Administrator\AppData\Local\Programs\Python\Python37-32\lib\site-packages\telegram\utils\request.py", line 233, in _request_wrapper
    raise NetworkError('{0} ({1})'.format(message, resp.status))
telegram.error.NetworkError: Internal server error: restart (500)
2019-04-14 07:54:25,388 - telegram.ext.updater - INFO - Flood control exceeded. Retry in 5 seconds
2019-04-15 10:57:19,440 - telegram.ext.updater - INFO - Received signal 2 (SIGINT), stopping...
2019-04-15 10:58:12,162 - telegram.ext.dispatcher - ERROR - An uncaught error was raised while processing the update
Traceback (most recent call last):
  File "C:\Users\Administrator\AppData\Local\Programs\Python\Python37-32\lib\site-packages\telegram\ext\dispatcher.py", line 279, in process_update
    handler.handle_update(update, self)
  File "C:\Users\Administrator\AppData\Local\Programs\Python\Python37-32\lib\site-packages\telegram\ext\callbackqueryhandler.py", line 143, in handle_update
    return self.callback(dispatcher.bot, update, **optional_args)
  File "telegrambot.py", line 45, in button
    bot.edit_message_text(chat_id = update.effective_message.chat_id,message_id = update.effective_message.message_id)
  File "C:\Users\Administrator\AppData\Local\Programs\Python\Python37-32\lib\site-packages\telegram\bot.py", line 65, in decorator
    result = func(self, *args, **kwargs)
  File "C:\Users\Administrator\AppData\Local\Programs\Python\Python37-32\lib\site-packages\telegram\bot.py", line 76, in decorator
    url, data = func(self, *args, **kwargs)
TypeError: edit_message_text() missing 1 required positional argument: 'text'
2019-04-15 10:58:55,959 - telegram.ext.updater - INFO - Received signal 2 (SIGINT), stopping...
2019-04-15 10:59:41,273 - telegram.ext.dispatcher - WARNING - A TelegramError was raised while processing the Update
2019-04-15 10:59:41,273 - telegram.ext.dispatcher - ERROR - No error handlers are registered, logging exception.
Traceback (most recent call last):
  File "C:\Users\Administrator\AppData\Local\Programs\Python\Python37-32\lib\site-packages\telegram\vendor\ptb_urllib3\urllib3\connectionpool.py", line 402, in _make_request
    six.raise_from(e, None)
  File "<string>", line 2, in raise_from
  File "C:\Users\Administrator\AppData\Local\Programs\Python\Python37-32\lib\site-packages\telegram\vendor\ptb_urllib3\urllib3\connectionpool.py", line 398, in _make_request
    httplib_response = conn.getresponse()
  File "C:\Users\Administrator\AppData\Local\Programs\Python\Python37-32\lib\http\client.py", line 1321, in getresponse
    response.begin()
  File "C:\Users\Administrator\AppData\Local\Programs\Python\Python37-32\lib\http\client.py", line 296, in begin
    version, status, reason = self._read_status()
  File "C:\Users\Administrator\AppData\Local\Programs\Python\Python37-32\lib\http\client.py", line 257, in _read_status
    line = str(self.fp.readline(_MAXLINE + 1), "iso-8859-1")
  File "C:\Users\Administrator\AppData\Local\Programs\Python\Python37-32\lib\socket.py", line 589, in readinto
    return self._sock.recv_into(b)
  File "C:\Users\Administrator\AppData\Local\Programs\Python\Python37-32\lib\ssl.py", line 1052, in recv_into
    return self.read(nbytes, buffer)
  File "C:\Users\Administrator\AppData\Local\Programs\Python\Python37-32\lib\ssl.py", line 911, in read
    return self._sslobj.read(len, buffer)
socket.timeout: The read operation timed out

During handling of the above exception, another exception occurred:

Traceback (most recent call last):
  File "C:\Users\Administrator\AppData\Local\Programs\Python\Python37-32\lib\site-packages\telegram\utils\request.py", line 203, in _request_wrapper
    resp = self._con_pool.request(*args, **kwargs)
  File "C:\Users\Administrator\AppData\Local\Programs\Python\Python37-32\lib\site-packages\telegram\vendor\ptb_urllib3\urllib3\request.py", line 70, in request
    **urlopen_kw)
  File "C:\Users\Administrator\AppData\Local\Programs\Python\Python37-32\lib\site-packages\telegram\vendor\ptb_urllib3\urllib3\request.py", line 148, in request_encode_body
    return self.urlopen(method, url, **extra_kw)
  File "C:\Users\Administrator\AppData\Local\Programs\Python\Python37-32\lib\site-packages\telegram\vendor\ptb_urllib3\urllib3\poolmanager.py", line 244, in urlopen
    response = conn.urlopen(method, u.request_uri, **kw)
  File "C:\Users\Administrator\AppData\Local\Programs\Python\Python37-32\lib\site-packages\telegram\vendor\ptb_urllib3\urllib3\connectionpool.py", line 666, in urlopen
    _stacktrace=sys.exc_info()[2])
  File "C:\Users\Administrator\AppData\Local\Programs\Python\Python37-32\lib\site-packages\telegram\vendor\ptb_urllib3\urllib3\util\retry.py", line 347, in increment
    raise six.reraise(type(error), error, _stacktrace)
  File "C:\Users\Administrator\AppData\Local\Programs\Python\Python37-32\lib\site-packages\telegram\vendor\ptb_urllib3\urllib3\packages\six.py", line 686, in reraise
    raise value
  File "C:\Users\Administrator\AppData\Local\Programs\Python\Python37-32\lib\site-packages\telegram\vendor\ptb_urllib3\urllib3\connectionpool.py", line 617, in urlopen
    chunked=chunked)
  File "C:\Users\Administrator\AppData\Local\Programs\Python\Python37-32\lib\site-packages\telegram\vendor\ptb_urllib3\urllib3\connectionpool.py", line 405, in _make_request
    exc_cls=ReadTimeoutError)
  File "C:\Users\Administrator\AppData\Local\Programs\Python\Python37-32\lib\site-packages\telegram\vendor\ptb_urllib3\urllib3\connectionpool.py", line 321, in _raise_timeout
    raise exc_cls(*args)
telegram.vendor.ptb_urllib3.urllib3.exceptions.ReadTimeoutError: HTTPSConnectionPool(host='api.telegram.org', port=443): Read timed out. (read timeout=5.0)

During handling of the above exception, another exception occurred:

Traceback (most recent call last):
  File "C:\Users\Administrator\AppData\Local\Programs\Python\Python37-32\lib\site-packages\telegram\ext\dispatcher.py", line 279, in process_update
    handler.handle_update(update, self)
  File "C:\Users\Administrator\AppData\Local\Programs\Python\Python37-32\lib\site-packages\telegram\ext\callbackqueryhandler.py", line 143, in handle_update
    return self.callback(dispatcher.bot, update, **optional_args)
  File "telegrambot.py", line 45, in button
    bot.edit_message_text(chat_id = update.effective_message.chat_id,message_id = update.effective_message.message_id,text = str(NewsFeed.entries[i].title) + '\n---------------------\nLink : ' + str(NewsFeed.entries[i].link) +'\n---------------------\n' + str(NewsFeed.entries[i].summary) + '\n---------------------\nPublished on :' + str(NewsFeed.entries[i].published))
  File "C:\Users\Administrator\AppData\Local\Programs\Python\Python37-32\lib\site-packages\telegram\bot.py", line 65, in decorator
    result = func(self, *args, **kwargs)
  File "C:\Users\Administrator\AppData\Local\Programs\Python\Python37-32\lib\site-packages\telegram\bot.py", line 90, in decorator
    result = self._request.post(url, data, timeout=kwargs.get('timeout'))
  File "C:\Users\Administrator\AppData\Local\Programs\Python\Python37-32\lib\site-packages\telegram\utils\request.py", line 309, in post
    headers={'Content-Type': 'application/json'})
  File "C:\Users\Administrator\AppData\Local\Programs\Python\Python37-32\lib\site-packages\telegram\utils\request.py", line 205, in _request_wrapper
    raise TimedOut()
telegram.error.TimedOut: Timed out
2019-04-15 10:59:48,262 - telegram.ext.dispatcher - WARNING - A TelegramError was raised while processing the Update
2019-04-15 10:59:48,262 - telegram.ext.dispatcher - ERROR - No error handlers are registered, logging exception.
Traceback (most recent call last):
  File "C:\Users\Administrator\AppData\Local\Programs\Python\Python37-32\lib\site-packages\telegram\vendor\ptb_urllib3\urllib3\connectionpool.py", line 402, in _make_request
    six.raise_from(e, None)
  File "<string>", line 2, in raise_from
  File "C:\Users\Administrator\AppData\Local\Programs\Python\Python37-32\lib\site-packages\telegram\vendor\ptb_urllib3\urllib3\connectionpool.py", line 398, in _make_request
    httplib_response = conn.getresponse()
  File "C:\Users\Administrator\AppData\Local\Programs\Python\Python37-32\lib\http\client.py", line 1321, in getresponse
    response.begin()
  File "C:\Users\Administrator\AppData\Local\Programs\Python\Python37-32\lib\http\client.py", line 296, in begin
    version, status, reason = self._read_status()
  File "C:\Users\Administrator\AppData\Local\Programs\Python\Python37-32\lib\http\client.py", line 257, in _read_status
    line = str(self.fp.readline(_MAXLINE + 1), "iso-8859-1")
  File "C:\Users\Administrator\AppData\Local\Programs\Python\Python37-32\lib\socket.py", line 589, in readinto
    return self._sock.recv_into(b)
  File "C:\Users\Administrator\AppData\Local\Programs\Python\Python37-32\lib\ssl.py", line 1052, in recv_into
    return self.read(nbytes, buffer)
  File "C:\Users\Administrator\AppData\Local\Programs\Python\Python37-32\lib\ssl.py", line 911, in read
    return self._sslobj.read(len, buffer)
socket.timeout: The read operation timed out

During handling of the above exception, another exception occurred:

Traceback (most recent call last):
  File "C:\Users\Administrator\AppData\Local\Programs\Python\Python37-32\lib\site-packages\telegram\utils\request.py", line 203, in _request_wrapper
    resp = self._con_pool.request(*args, **kwargs)
  File "C:\Users\Administrator\AppData\Local\Programs\Python\Python37-32\lib\site-packages\telegram\vendor\ptb_urllib3\urllib3\request.py", line 70, in request
    **urlopen_kw)
  File "C:\Users\Administrator\AppData\Local\Programs\Python\Python37-32\lib\site-packages\telegram\vendor\ptb_urllib3\urllib3\request.py", line 148, in request_encode_body
    return self.urlopen(method, url, **extra_kw)
  File "C:\Users\Administrator\AppData\Local\Programs\Python\Python37-32\lib\site-packages\telegram\vendor\ptb_urllib3\urllib3\poolmanager.py", line 244, in urlopen
    response = conn.urlopen(method, u.request_uri, **kw)
  File "C:\Users\Administrator\AppData\Local\Programs\Python\Python37-32\lib\site-packages\telegram\vendor\ptb_urllib3\urllib3\connectionpool.py", line 666, in urlopen
    _stacktrace=sys.exc_info()[2])
  File "C:\Users\Administrator\AppData\Local\Programs\Python\Python37-32\lib\site-packages\telegram\vendor\ptb_urllib3\urllib3\util\retry.py", line 347, in increment
    raise six.reraise(type(error), error, _stacktrace)
  File "C:\Users\Administrator\AppData\Local\Programs\Python\Python37-32\lib\site-packages\telegram\vendor\ptb_urllib3\urllib3\packages\six.py", line 686, in reraise
    raise value
  File "C:\Users\Administrator\AppData\Local\Programs\Python\Python37-32\lib\site-packages\telegram\vendor\ptb_urllib3\urllib3\connectionpool.py", line 617, in urlopen
    chunked=chunked)
  File "C:\Users\Administrator\AppData\Local\Programs\Python\Python37-32\lib\site-packages\telegram\vendor\ptb_urllib3\urllib3\connectionpool.py", line 405, in _make_request
    exc_cls=ReadTimeoutError)
  File "C:\Users\Administrator\AppData\Local\Programs\Python\Python37-32\lib\site-packages\telegram\vendor\ptb_urllib3\urllib3\connectionpool.py", line 321, in _raise_timeout
    raise exc_cls(*args)
telegram.vendor.ptb_urllib3.urllib3.exceptions.ReadTimeoutError: HTTPSConnectionPool(host='api.telegram.org', port=443): Read timed out. (read timeout=5.0)

During handling of the above exception, another exception occurred:

Traceback (most recent call last):
  File "C:\Users\Administrator\AppData\Local\Programs\Python\Python37-32\lib\site-packages\telegram\ext\dispatcher.py", line 279, in process_update
    handler.handle_update(update, self)
  File "C:\Users\Administrator\AppData\Local\Programs\Python\Python37-32\lib\site-packages\telegram\ext\callbackqueryhandler.py", line 143, in handle_update
    return self.callback(dispatcher.bot, update, **optional_args)
  File "telegrambot.py", line 45, in button
    bot.edit_message_text(chat_id = update.effective_message.chat_id,message_id = update.effective_message.message_id,text = str(NewsFeed.entries[i].title) + '\n---------------------\nLink : ' + str(NewsFeed.entries[i].link) +'\n---------------------\n' + str(NewsFeed.entries[i].summary) + '\n---------------------\nPublished on :' + str(NewsFeed.entries[i].published))
  File "C:\Users\Administrator\AppData\Local\Programs\Python\Python37-32\lib\site-packages\telegram\bot.py", line 65, in decorator
    result = func(self, *args, **kwargs)
  File "C:\Users\Administrator\AppData\Local\Programs\Python\Python37-32\lib\site-packages\telegram\bot.py", line 90, in decorator
    result = self._request.post(url, data, timeout=kwargs.get('timeout'))
  File "C:\Users\Administrator\AppData\Local\Programs\Python\Python37-32\lib\site-packages\telegram\utils\request.py", line 309, in post
    headers={'Content-Type': 'application/json'})
  File "C:\Users\Administrator\AppData\Local\Programs\Python\Python37-32\lib\site-packages\telegram\utils\request.py", line 205, in _request_wrapper
    raise TimedOut()
telegram.error.TimedOut: Timed out
2019-04-15 11:00:18,293 - telegram.ext.dispatcher - WARNING - A TelegramError was raised while processing the Update
2019-04-15 11:00:18,293 - telegram.ext.dispatcher - ERROR - No error handlers are registered, logging exception.
Traceback (most recent call last):
  File "C:\Users\Administrator\AppData\Local\Programs\Python\Python37-32\lib\site-packages\telegram\vendor\ptb_urllib3\urllib3\connectionpool.py", line 402, in _make_request
    six.raise_from(e, None)
  File "<string>", line 2, in raise_from
  File "C:\Users\Administrator\AppData\Local\Programs\Python\Python37-32\lib\site-packages\telegram\vendor\ptb_urllib3\urllib3\connectionpool.py", line 398, in _make_request
    httplib_response = conn.getresponse()
  File "C:\Users\Administrator\AppData\Local\Programs\Python\Python37-32\lib\http\client.py", line 1321, in getresponse
    response.begin()
  File "C:\Users\Administrator\AppData\Local\Programs\Python\Python37-32\lib\http\client.py", line 296, in begin
    version, status, reason = self._read_status()
  File "C:\Users\Administrator\AppData\Local\Programs\Python\Python37-32\lib\http\client.py", line 257, in _read_status
    line = str(self.fp.readline(_MAXLINE + 1), "iso-8859-1")
  File "C:\Users\Administrator\AppData\Local\Programs\Python\Python37-32\lib\socket.py", line 589, in readinto
    return self._sock.recv_into(b)
  File "C:\Users\Administrator\AppData\Local\Programs\Python\Python37-32\lib\ssl.py", line 1052, in recv_into
    return self.read(nbytes, buffer)
  File "C:\Users\Administrator\AppData\Local\Programs\Python\Python37-32\lib\ssl.py", line 911, in read
    return self._sslobj.read(len, buffer)
socket.timeout: The read operation timed out

During handling of the above exception, another exception occurred:

Traceback (most recent call last):
  File "C:\Users\Administrator\AppData\Local\Programs\Python\Python37-32\lib\site-packages\telegram\utils\request.py", line 203, in _request_wrapper
    resp = self._con_pool.request(*args, **kwargs)
  File "C:\Users\Administrator\AppData\Local\Programs\Python\Python37-32\lib\site-packages\telegram\vendor\ptb_urllib3\urllib3\request.py", line 70, in request
    **urlopen_kw)
  File "C:\Users\Administrator\AppData\Local\Programs\Python\Python37-32\lib\site-packages\telegram\vendor\ptb_urllib3\urllib3\request.py", line 148, in request_encode_body
    return self.urlopen(method, url, **extra_kw)
  File "C:\Users\Administrator\AppData\Local\Programs\Python\Python37-32\lib\site-packages\telegram\vendor\ptb_urllib3\urllib3\poolmanager.py", line 244, in urlopen
    response = conn.urlopen(method, u.request_uri, **kw)
  File "C:\Users\Administrator\AppData\Local\Programs\Python\Python37-32\lib\site-packages\telegram\vendor\ptb_urllib3\urllib3\connectionpool.py", line 666, in urlopen
    _stacktrace=sys.exc_info()[2])
  File "C:\Users\Administrator\AppData\Local\Programs\Python\Python37-32\lib\site-packages\telegram\vendor\ptb_urllib3\urllib3\util\retry.py", line 347, in increment
    raise six.reraise(type(error), error, _stacktrace)
  File "C:\Users\Administrator\AppData\Local\Programs\Python\Python37-32\lib\site-packages\telegram\vendor\ptb_urllib3\urllib3\packages\six.py", line 686, in reraise
    raise value
  File "C:\Users\Administrator\AppData\Local\Programs\Python\Python37-32\lib\site-packages\telegram\vendor\ptb_urllib3\urllib3\connectionpool.py", line 617, in urlopen
    chunked=chunked)
  File "C:\Users\Administrator\AppData\Local\Programs\Python\Python37-32\lib\site-packages\telegram\vendor\ptb_urllib3\urllib3\connectionpool.py", line 405, in _make_request
    exc_cls=ReadTimeoutError)
  File "C:\Users\Administrator\AppData\Local\Programs\Python\Python37-32\lib\site-packages\telegram\vendor\ptb_urllib3\urllib3\connectionpool.py", line 321, in _raise_timeout
    raise exc_cls(*args)
telegram.vendor.ptb_urllib3.urllib3.exceptions.ReadTimeoutError: HTTPSConnectionPool(host='api.telegram.org', port=443): Read timed out. (read timeout=5.0)

During handling of the above exception, another exception occurred:

Traceback (most recent call last):
  File "C:\Users\Administrator\AppData\Local\Programs\Python\Python37-32\lib\site-packages\telegram\ext\dispatcher.py", line 279, in process_update
    handler.handle_update(update, self)
  File "C:\Users\Administrator\AppData\Local\Programs\Python\Python37-32\lib\site-packages\telegram\ext\callbackqueryhandler.py", line 143, in handle_update
    return self.callback(dispatcher.bot, update, **optional_args)
  File "telegrambot.py", line 45, in button
    bot.edit_message_text(chat_id = update.effective_message.chat_id,message_id = update.effective_message.message_id,text = str(NewsFeed.entries[i].title) + '\n---------------------\nLink : ' + str(NewsFeed.entries[i].link) +'\n---------------------\n' + str(NewsFeed.entries[i].summary) + '\n---------------------\nPublished on :' + str(NewsFeed.entries[i].published))
  File "C:\Users\Administrator\AppData\Local\Programs\Python\Python37-32\lib\site-packages\telegram\bot.py", line 65, in decorator
    result = func(self, *args, **kwargs)
  File "C:\Users\Administrator\AppData\Local\Programs\Python\Python37-32\lib\site-packages\telegram\bot.py", line 90, in decorator
    result = self._request.post(url, data, timeout=kwargs.get('timeout'))
  File "C:\Users\Administrator\AppData\Local\Programs\Python\Python37-32\lib\site-packages\telegram\utils\request.py", line 309, in post
    headers={'Content-Type': 'application/json'})
  File "C:\Users\Administrator\AppData\Local\Programs\Python\Python37-32\lib\site-packages\telegram\utils\request.py", line 205, in _request_wrapper
    raise TimedOut()
telegram.error.TimedOut: Timed out
2019-04-15 11:01:27,812 - telegram.ext.dispatcher - WARNING - A TelegramError was raised while processing the Update
2019-04-15 11:01:27,812 - telegram.ext.dispatcher - ERROR - No error handlers are registered, logging exception.
Traceback (most recent call last):
  File "C:\Users\Administrator\AppData\Local\Programs\Python\Python37-32\lib\site-packages\telegram\vendor\ptb_urllib3\urllib3\connectionpool.py", line 402, in _make_request
    six.raise_from(e, None)
  File "<string>", line 2, in raise_from
  File "C:\Users\Administrator\AppData\Local\Programs\Python\Python37-32\lib\site-packages\telegram\vendor\ptb_urllib3\urllib3\connectionpool.py", line 398, in _make_request
    httplib_response = conn.getresponse()
  File "C:\Users\Administrator\AppData\Local\Programs\Python\Python37-32\lib\http\client.py", line 1321, in getresponse
    response.begin()
  File "C:\Users\Administrator\AppData\Local\Programs\Python\Python37-32\lib\http\client.py", line 296, in begin
    version, status, reason = self._read_status()
  File "C:\Users\Administrator\AppData\Local\Programs\Python\Python37-32\lib\http\client.py", line 257, in _read_status
    line = str(self.fp.readline(_MAXLINE + 1), "iso-8859-1")
  File "C:\Users\Administrator\AppData\Local\Programs\Python\Python37-32\lib\socket.py", line 589, in readinto
    return self._sock.recv_into(b)
  File "C:\Users\Administrator\AppData\Local\Programs\Python\Python37-32\lib\ssl.py", line 1052, in recv_into
    return self.read(nbytes, buffer)
  File "C:\Users\Administrator\AppData\Local\Programs\Python\Python37-32\lib\ssl.py", line 911, in read
    return self._sslobj.read(len, buffer)
socket.timeout: The read operation timed out

During handling of the above exception, another exception occurred:

Traceback (most recent call last):
  File "C:\Users\Administrator\AppData\Local\Programs\Python\Python37-32\lib\site-packages\telegram\utils\request.py", line 203, in _request_wrapper
    resp = self._con_pool.request(*args, **kwargs)
  File "C:\Users\Administrator\AppData\Local\Programs\Python\Python37-32\lib\site-packages\telegram\vendor\ptb_urllib3\urllib3\request.py", line 70, in request
    **urlopen_kw)
  File "C:\Users\Administrator\AppData\Local\Programs\Python\Python37-32\lib\site-packages\telegram\vendor\ptb_urllib3\urllib3\request.py", line 148, in request_encode_body
    return self.urlopen(method, url, **extra_kw)
  File "C:\Users\Administrator\AppData\Local\Programs\Python\Python37-32\lib\site-packages\telegram\vendor\ptb_urllib3\urllib3\poolmanager.py", line 244, in urlopen
    response = conn.urlopen(method, u.request_uri, **kw)
  File "C:\Users\Administrator\AppData\Local\Programs\Python\Python37-32\lib\site-packages\telegram\vendor\ptb_urllib3\urllib3\connectionpool.py", line 666, in urlopen
    _stacktrace=sys.exc_info()[2])
  File "C:\Users\Administrator\AppData\Local\Programs\Python\Python37-32\lib\site-packages\telegram\vendor\ptb_urllib3\urllib3\util\retry.py", line 347, in increment
    raise six.reraise(type(error), error, _stacktrace)
  File "C:\Users\Administrator\AppData\Local\Programs\Python\Python37-32\lib\site-packages\telegram\vendor\ptb_urllib3\urllib3\packages\six.py", line 686, in reraise
    raise value
  File "C:\Users\Administrator\AppData\Local\Programs\Python\Python37-32\lib\site-packages\telegram\vendor\ptb_urllib3\urllib3\connectionpool.py", line 617, in urlopen
    chunked=chunked)
  File "C:\Users\Administrator\AppData\Local\Programs\Python\Python37-32\lib\site-packages\telegram\vendor\ptb_urllib3\urllib3\connectionpool.py", line 405, in _make_request
    exc_cls=ReadTimeoutError)
  File "C:\Users\Administrator\AppData\Local\Programs\Python\Python37-32\lib\site-packages\telegram\vendor\ptb_urllib3\urllib3\connectionpool.py", line 321, in _raise_timeout
    raise exc_cls(*args)
telegram.vendor.ptb_urllib3.urllib3.exceptions.ReadTimeoutError: HTTPSConnectionPool(host='api.telegram.org', port=443): Read timed out. (read timeout=5.0)

During handling of the above exception, another exception occurred:

Traceback (most recent call last):
  File "C:\Users\Administrator\AppData\Local\Programs\Python\Python37-32\lib\site-packages\telegram\ext\dispatcher.py", line 279, in process_update
    handler.handle_update(update, self)
  File "C:\Users\Administrator\AppData\Local\Programs\Python\Python37-32\lib\site-packages\telegram\ext\callbackqueryhandler.py", line 143, in handle_update
    return self.callback(dispatcher.bot, update, **optional_args)
  File "telegrambot.py", line 45, in button
    bot.edit_message_text(chat_id = update.effective_message.chat_id,message_id = update.effective_message.message_id,text = str(NewsFeed.entries[i].title) + '\n---------------------\nLink : ' + str(NewsFeed.entries[i].link) +'\n---------------------\n' + str(NewsFeed.entries[i].summary) + '\n---------------------\nPublished on :' + str(NewsFeed.entries[i].published))
  File "C:\Users\Administrator\AppData\Local\Programs\Python\Python37-32\lib\site-packages\telegram\bot.py", line 65, in decorator
    result = func(self, *args, **kwargs)
  File "C:\Users\Administrator\AppData\Local\Programs\Python\Python37-32\lib\site-packages\telegram\bot.py", line 90, in decorator
    result = self._request.post(url, data, timeout=kwargs.get('timeout'))
  File "C:\Users\Administrator\AppData\Local\Programs\Python\Python37-32\lib\site-packages\telegram\utils\request.py", line 309, in post
    headers={'Content-Type': 'application/json'})
  File "C:\Users\Administrator\AppData\Local\Programs\Python\Python37-32\lib\site-packages\telegram\utils\request.py", line 205, in _request_wrapper
    raise TimedOut()
telegram.error.TimedOut: Timed out
2019-04-15 11:06:02,256 - telegram.ext.updater - INFO - Received signal 2 (SIGINT), stopping...
2019-04-15 11:19:32,712 - telegram.ext.dispatcher - WARNING - A TelegramError was raised while processing the Update
2019-04-15 11:19:32,712 - telegram.ext.dispatcher - ERROR - No error handlers are registered, logging exception.
Traceback (most recent call last):
  File "C:\Users\Administrator\AppData\Local\Programs\Python\Python37-32\lib\site-packages\telegram\vendor\ptb_urllib3\urllib3\connectionpool.py", line 402, in _make_request
    six.raise_from(e, None)
  File "<string>", line 2, in raise_from
  File "C:\Users\Administrator\AppData\Local\Programs\Python\Python37-32\lib\site-packages\telegram\vendor\ptb_urllib3\urllib3\connectionpool.py", line 398, in _make_request
    httplib_response = conn.getresponse()
  File "C:\Users\Administrator\AppData\Local\Programs\Python\Python37-32\lib\http\client.py", line 1321, in getresponse
    response.begin()
  File "C:\Users\Administrator\AppData\Local\Programs\Python\Python37-32\lib\http\client.py", line 296, in begin
    version, status, reason = self._read_status()
  File "C:\Users\Administrator\AppData\Local\Programs\Python\Python37-32\lib\http\client.py", line 257, in _read_status
    line = str(self.fp.readline(_MAXLINE + 1), "iso-8859-1")
  File "C:\Users\Administrator\AppData\Local\Programs\Python\Python37-32\lib\socket.py", line 589, in readinto
    return self._sock.recv_into(b)
  File "C:\Users\Administrator\AppData\Local\Programs\Python\Python37-32\lib\ssl.py", line 1052, in recv_into
    return self.read(nbytes, buffer)
  File "C:\Users\Administrator\AppData\Local\Programs\Python\Python37-32\lib\ssl.py", line 911, in read
    return self._sslobj.read(len, buffer)
socket.timeout: The read operation timed out

During handling of the above exception, another exception occurred:

Traceback (most recent call last):
  File "C:\Users\Administrator\AppData\Local\Programs\Python\Python37-32\lib\site-packages\telegram\utils\request.py", line 203, in _request_wrapper
    resp = self._con_pool.request(*args, **kwargs)
  File "C:\Users\Administrator\AppData\Local\Programs\Python\Python37-32\lib\site-packages\telegram\vendor\ptb_urllib3\urllib3\request.py", line 70, in request
    **urlopen_kw)
  File "C:\Users\Administrator\AppData\Local\Programs\Python\Python37-32\lib\site-packages\telegram\vendor\ptb_urllib3\urllib3\request.py", line 148, in request_encode_body
    return self.urlopen(method, url, **extra_kw)
  File "C:\Users\Administrator\AppData\Local\Programs\Python\Python37-32\lib\site-packages\telegram\vendor\ptb_urllib3\urllib3\poolmanager.py", line 244, in urlopen
    response = conn.urlopen(method, u.request_uri, **kw)
  File "C:\Users\Administrator\AppData\Local\Programs\Python\Python37-32\lib\site-packages\telegram\vendor\ptb_urllib3\urllib3\connectionpool.py", line 666, in urlopen
    _stacktrace=sys.exc_info()[2])
  File "C:\Users\Administrator\AppData\Local\Programs\Python\Python37-32\lib\site-packages\telegram\vendor\ptb_urllib3\urllib3\util\retry.py", line 347, in increment
    raise six.reraise(type(error), error, _stacktrace)
  File "C:\Users\Administrator\AppData\Local\Programs\Python\Python37-32\lib\site-packages\telegram\vendor\ptb_urllib3\urllib3\packages\six.py", line 686, in reraise
    raise value
  File "C:\Users\Administrator\AppData\Local\Programs\Python\Python37-32\lib\site-packages\telegram\vendor\ptb_urllib3\urllib3\connectionpool.py", line 617, in urlopen
    chunked=chunked)
  File "C:\Users\Administrator\AppData\Local\Programs\Python\Python37-32\lib\site-packages\telegram\vendor\ptb_urllib3\urllib3\connectionpool.py", line 405, in _make_request
    exc_cls=ReadTimeoutError)
  File "C:\Users\Administrator\AppData\Local\Programs\Python\Python37-32\lib\site-packages\telegram\vendor\ptb_urllib3\urllib3\connectionpool.py", line 321, in _raise_timeout
    raise exc_cls(*args)
telegram.vendor.ptb_urllib3.urllib3.exceptions.ReadTimeoutError: HTTPSConnectionPool(host='api.telegram.org', port=443): Read timed out. (read timeout=5.0)

During handling of the above exception, another exception occurred:

Traceback (most recent call last):
  File "C:\Users\Administrator\AppData\Local\Programs\Python\Python37-32\lib\site-packages\telegram\ext\dispatcher.py", line 279, in process_update
    handler.handle_update(update, self)
  File "C:\Users\Administrator\AppData\Local\Programs\Python\Python37-32\lib\site-packages\telegram\ext\callbackqueryhandler.py", line 143, in handle_update
    return self.callback(dispatcher.bot, update, **optional_args)
  File "telegrambot.py", line 45, in button
    bot.edit_message_text(chat_id = update.effective_message.chat_id,message_id = update.effective_message.message_id,text = str(NewsFeed.entries[i].title) + '\n---------------------\nLink : ' + str(NewsFeed.entries[i].link) +'\n---------------------\n' + str(NewsFeed.entries[i].summary) + '\n---------------------\nPublished on :' + str(NewsFeed.entries[i].published))
  File "C:\Users\Administrator\AppData\Local\Programs\Python\Python37-32\lib\site-packages\telegram\bot.py", line 65, in decorator
    result = func(self, *args, **kwargs)
  File "C:\Users\Administrator\AppData\Local\Programs\Python\Python37-32\lib\site-packages\telegram\bot.py", line 90, in decorator
    result = self._request.post(url, data, timeout=kwargs.get('timeout'))
  File "C:\Users\Administrator\AppData\Local\Programs\Python\Python37-32\lib\site-packages\telegram\utils\request.py", line 309, in post
    headers={'Content-Type': 'application/json'})
  File "C:\Users\Administrator\AppData\Local\Programs\Python\Python37-32\lib\site-packages\telegram\utils\request.py", line 205, in _request_wrapper
    raise TimedOut()
telegram.error.TimedOut: Timed out
2019-04-15 11:19:39,587 - telegram.ext.dispatcher - WARNING - A TelegramError was raised while processing the Update
2019-04-15 11:19:39,587 - telegram.ext.dispatcher - ERROR - No error handlers are registered, logging exception.
Traceback (most recent call last):
  File "C:\Users\Administrator\AppData\Local\Programs\Python\Python37-32\lib\site-packages\telegram\vendor\ptb_urllib3\urllib3\connectionpool.py", line 402, in _make_request
    six.raise_from(e, None)
  File "<string>", line 2, in raise_from
  File "C:\Users\Administrator\AppData\Local\Programs\Python\Python37-32\lib\site-packages\telegram\vendor\ptb_urllib3\urllib3\connectionpool.py", line 398, in _make_request
    httplib_response = conn.getresponse()
  File "C:\Users\Administrator\AppData\Local\Programs\Python\Python37-32\lib\http\client.py", line 1321, in getresponse
    response.begin()
  File "C:\Users\Administrator\AppData\Local\Programs\Python\Python37-32\lib\http\client.py", line 296, in begin
    version, status, reason = self._read_status()
  File "C:\Users\Administrator\AppData\Local\Programs\Python\Python37-32\lib\http\client.py", line 257, in _read_status
    line = str(self.fp.readline(_MAXLINE + 1), "iso-8859-1")
  File "C:\Users\Administrator\AppData\Local\Programs\Python\Python37-32\lib\socket.py", line 589, in readinto
    return self._sock.recv_into(b)
  File "C:\Users\Administrator\AppData\Local\Programs\Python\Python37-32\lib\ssl.py", line 1052, in recv_into
    return self.read(nbytes, buffer)
  File "C:\Users\Administrator\AppData\Local\Programs\Python\Python37-32\lib\ssl.py", line 911, in read
    return self._sslobj.read(len, buffer)
socket.timeout: The read operation timed out

During handling of the above exception, another exception occurred:

Traceback (most recent call last):
  File "C:\Users\Administrator\AppData\Local\Programs\Python\Python37-32\lib\site-packages\telegram\utils\request.py", line 203, in _request_wrapper
    resp = self._con_pool.request(*args, **kwargs)
  File "C:\Users\Administrator\AppData\Local\Programs\Python\Python37-32\lib\site-packages\telegram\vendor\ptb_urllib3\urllib3\request.py", line 70, in request
    **urlopen_kw)
  File "C:\Users\Administrator\AppData\Local\Programs\Python\Python37-32\lib\site-packages\telegram\vendor\ptb_urllib3\urllib3\request.py", line 148, in request_encode_body
    return self.urlopen(method, url, **extra_kw)
  File "C:\Users\Administrator\AppData\Local\Programs\Python\Python37-32\lib\site-packages\telegram\vendor\ptb_urllib3\urllib3\poolmanager.py", line 244, in urlopen
    response = conn.urlopen(method, u.request_uri, **kw)
  File "C:\Users\Administrator\AppData\Local\Programs\Python\Python37-32\lib\site-packages\telegram\vendor\ptb_urllib3\urllib3\connectionpool.py", line 666, in urlopen
    _stacktrace=sys.exc_info()[2])
  File "C:\Users\Administrator\AppData\Local\Programs\Python\Python37-32\lib\site-packages\telegram\vendor\ptb_urllib3\urllib3\util\retry.py", line 347, in increment
    raise six.reraise(type(error), error, _stacktrace)
  File "C:\Users\Administrator\AppData\Local\Programs\Python\Python37-32\lib\site-packages\telegram\vendor\ptb_urllib3\urllib3\packages\six.py", line 686, in reraise
    raise value
  File "C:\Users\Administrator\AppData\Local\Programs\Python\Python37-32\lib\site-packages\telegram\vendor\ptb_urllib3\urllib3\connectionpool.py", line 617, in urlopen
    chunked=chunked)
  File "C:\Users\Administrator\AppData\Local\Programs\Python\Python37-32\lib\site-packages\telegram\vendor\ptb_urllib3\urllib3\connectionpool.py", line 405, in _make_request
    exc_cls=ReadTimeoutError)
  File "C:\Users\Administrator\AppData\Local\Programs\Python\Python37-32\lib\site-packages\telegram\vendor\ptb_urllib3\urllib3\connectionpool.py", line 321, in _raise_timeout
    raise exc_cls(*args)
telegram.vendor.ptb_urllib3.urllib3.exceptions.ReadTimeoutError: HTTPSConnectionPool(host='api.telegram.org', port=443): Read timed out. (read timeout=5.0)

During handling of the above exception, another exception occurred:

Traceback (most recent call last):
  File "C:\Users\Administrator\AppData\Local\Programs\Python\Python37-32\lib\site-packages\telegram\ext\dispatcher.py", line 279, in process_update
    handler.handle_update(update, self)
  File "C:\Users\Administrator\AppData\Local\Programs\Python\Python37-32\lib\site-packages\telegram\ext\callbackqueryhandler.py", line 143, in handle_update
    return self.callback(dispatcher.bot, update, **optional_args)
  File "telegrambot.py", line 45, in button
    bot.edit_message_text(chat_id = update.effective_message.chat_id,message_id = update.effective_message.message_id,text = str(NewsFeed.entries[i].title) + '\n---------------------\nLink : ' + str(NewsFeed.entries[i].link) +'\n---------------------\n' + str(NewsFeed.entries[i].summary) + '\n---------------------\nPublished on :' + str(NewsFeed.entries[i].published))
  File "C:\Users\Administrator\AppData\Local\Programs\Python\Python37-32\lib\site-packages\telegram\bot.py", line 65, in decorator
    result = func(self, *args, **kwargs)
  File "C:\Users\Administrator\AppData\Local\Programs\Python\Python37-32\lib\site-packages\telegram\bot.py", line 90, in decorator
    result = self._request.post(url, data, timeout=kwargs.get('timeout'))
  File "C:\Users\Administrator\AppData\Local\Programs\Python\Python37-32\lib\site-packages\telegram\utils\request.py", line 309, in post
    headers={'Content-Type': 'application/json'})
  File "C:\Users\Administrator\AppData\Local\Programs\Python\Python37-32\lib\site-packages\telegram\utils\request.py", line 205, in _request_wrapper
    raise TimedOut()
telegram.error.TimedOut: Timed out
2019-04-15 11:19:56,919 - telegram.ext.dispatcher - WARNING - A TelegramError was raised while processing the Update
2019-04-15 11:19:56,919 - telegram.ext.dispatcher - ERROR - No error handlers are registered, logging exception.
Traceback (most recent call last):
  File "C:\Users\Administrator\AppData\Local\Programs\Python\Python37-32\lib\site-packages\telegram\vendor\ptb_urllib3\urllib3\connectionpool.py", line 402, in _make_request
    six.raise_from(e, None)
  File "<string>", line 2, in raise_from
  File "C:\Users\Administrator\AppData\Local\Programs\Python\Python37-32\lib\site-packages\telegram\vendor\ptb_urllib3\urllib3\connectionpool.py", line 398, in _make_request
    httplib_response = conn.getresponse()
  File "C:\Users\Administrator\AppData\Local\Programs\Python\Python37-32\lib\http\client.py", line 1321, in getresponse
    response.begin()
  File "C:\Users\Administrator\AppData\Local\Programs\Python\Python37-32\lib\http\client.py", line 296, in begin
    version, status, reason = self._read_status()
  File "C:\Users\Administrator\AppData\Local\Programs\Python\Python37-32\lib\http\client.py", line 257, in _read_status
    line = str(self.fp.readline(_MAXLINE + 1), "iso-8859-1")
  File "C:\Users\Administrator\AppData\Local\Programs\Python\Python37-32\lib\socket.py", line 589, in readinto
    return self._sock.recv_into(b)
  File "C:\Users\Administrator\AppData\Local\Programs\Python\Python37-32\lib\ssl.py", line 1052, in recv_into
    return self.read(nbytes, buffer)
  File "C:\Users\Administrator\AppData\Local\Programs\Python\Python37-32\lib\ssl.py", line 911, in read
    return self._sslobj.read(len, buffer)
socket.timeout: The read operation timed out

During handling of the above exception, another exception occurred:

Traceback (most recent call last):
  File "C:\Users\Administrator\AppData\Local\Programs\Python\Python37-32\lib\site-packages\telegram\utils\request.py", line 203, in _request_wrapper
    resp = self._con_pool.request(*args, **kwargs)
  File "C:\Users\Administrator\AppData\Local\Programs\Python\Python37-32\lib\site-packages\telegram\vendor\ptb_urllib3\urllib3\request.py", line 70, in request
    **urlopen_kw)
  File "C:\Users\Administrator\AppData\Local\Programs\Python\Python37-32\lib\site-packages\telegram\vendor\ptb_urllib3\urllib3\request.py", line 148, in request_encode_body
    return self.urlopen(method, url, **extra_kw)
  File "C:\Users\Administrator\AppData\Local\Programs\Python\Python37-32\lib\site-packages\telegram\vendor\ptb_urllib3\urllib3\poolmanager.py", line 244, in urlopen
    response = conn.urlopen(method, u.request_uri, **kw)
  File "C:\Users\Administrator\AppData\Local\Programs\Python\Python37-32\lib\site-packages\telegram\vendor\ptb_urllib3\urllib3\connectionpool.py", line 666, in urlopen
    _stacktrace=sys.exc_info()[2])
  File "C:\Users\Administrator\AppData\Local\Programs\Python\Python37-32\lib\site-packages\telegram\vendor\ptb_urllib3\urllib3\util\retry.py", line 347, in increment
    raise six.reraise(type(error), error, _stacktrace)
  File "C:\Users\Administrator\AppData\Local\Programs\Python\Python37-32\lib\site-packages\telegram\vendor\ptb_urllib3\urllib3\packages\six.py", line 686, in reraise
    raise value
  File "C:\Users\Administrator\AppData\Local\Programs\Python\Python37-32\lib\site-packages\telegram\vendor\ptb_urllib3\urllib3\connectionpool.py", line 617, in urlopen
    chunked=chunked)
  File "C:\Users\Administrator\AppData\Local\Programs\Python\Python37-32\lib\site-packages\telegram\vendor\ptb_urllib3\urllib3\connectionpool.py", line 405, in _make_request
    exc_cls=ReadTimeoutError)
  File "C:\Users\Administrator\AppData\Local\Programs\Python\Python37-32\lib\site-packages\telegram\vendor\ptb_urllib3\urllib3\connectionpool.py", line 321, in _raise_timeout
    raise exc_cls(*args)
telegram.vendor.ptb_urllib3.urllib3.exceptions.ReadTimeoutError: HTTPSConnectionPool(host='api.telegram.org', port=443): Read timed out. (read timeout=5.0)

During handling of the above exception, another exception occurred:

Traceback (most recent call last):
  File "C:\Users\Administrator\AppData\Local\Programs\Python\Python37-32\lib\site-packages\telegram\ext\dispatcher.py", line 279, in process_update
    handler.handle_update(update, self)
  File "C:\Users\Administrator\AppData\Local\Programs\Python\Python37-32\lib\site-packages\telegram\ext\callbackqueryhandler.py", line 143, in handle_update
    return self.callback(dispatcher.bot, update, **optional_args)
  File "telegrambot.py", line 45, in button
    bot.edit_message_text(chat_id = update.effective_message.chat_id,message_id = update.effective_message.message_id,text = str(NewsFeed.entries[i].title) + '\n---------------------\nLink : ' + str(NewsFeed.entries[i].link) +'\n---------------------\n' + str(NewsFeed.entries[i].summary) + '\n---------------------\nPublished on :' + str(NewsFeed.entries[i].published))
  File "C:\Users\Administrator\AppData\Local\Programs\Python\Python37-32\lib\site-packages\telegram\bot.py", line 65, in decorator
    result = func(self, *args, **kwargs)
  File "C:\Users\Administrator\AppData\Local\Programs\Python\Python37-32\lib\site-packages\telegram\bot.py", line 90, in decorator
    result = self._request.post(url, data, timeout=kwargs.get('timeout'))
  File "C:\Users\Administrator\AppData\Local\Programs\Python\Python37-32\lib\site-packages\telegram\utils\request.py", line 309, in post
    headers={'Content-Type': 'application/json'})
  File "C:\Users\Administrator\AppData\Local\Programs\Python\Python37-32\lib\site-packages\telegram\utils\request.py", line 205, in _request_wrapper
    raise TimedOut()
telegram.error.TimedOut: Timed out
2019-04-15 11:20:02,508 - telegram.ext.dispatcher - WARNING - A TelegramError was raised while processing the Update
2019-04-15 11:20:02,508 - telegram.ext.dispatcher - ERROR - No error handlers are registered, logging exception.
Traceback (most recent call last):
  File "C:\Users\Administrator\AppData\Local\Programs\Python\Python37-32\lib\site-packages\telegram\vendor\ptb_urllib3\urllib3\connectionpool.py", line 402, in _make_request
    six.raise_from(e, None)
  File "<string>", line 2, in raise_from
  File "C:\Users\Administrator\AppData\Local\Programs\Python\Python37-32\lib\site-packages\telegram\vendor\ptb_urllib3\urllib3\connectionpool.py", line 398, in _make_request
    httplib_response = conn.getresponse()
  File "C:\Users\Administrator\AppData\Local\Programs\Python\Python37-32\lib\http\client.py", line 1321, in getresponse
    response.begin()
  File "C:\Users\Administrator\AppData\Local\Programs\Python\Python37-32\lib\http\client.py", line 296, in begin
    version, status, reason = self._read_status()
  File "C:\Users\Administrator\AppData\Local\Programs\Python\Python37-32\lib\http\client.py", line 257, in _read_status
    line = str(self.fp.readline(_MAXLINE + 1), "iso-8859-1")
  File "C:\Users\Administrator\AppData\Local\Programs\Python\Python37-32\lib\socket.py", line 589, in readinto
    return self._sock.recv_into(b)
  File "C:\Users\Administrator\AppData\Local\Programs\Python\Python37-32\lib\ssl.py", line 1052, in recv_into
    return self.read(nbytes, buffer)
  File "C:\Users\Administrator\AppData\Local\Programs\Python\Python37-32\lib\ssl.py", line 911, in read
    return self._sslobj.read(len, buffer)
socket.timeout: The read operation timed out

During handling of the above exception, another exception occurred:

Traceback (most recent call last):
  File "C:\Users\Administrator\AppData\Local\Programs\Python\Python37-32\lib\site-packages\telegram\utils\request.py", line 203, in _request_wrapper
    resp = self._con_pool.request(*args, **kwargs)
  File "C:\Users\Administrator\AppData\Local\Programs\Python\Python37-32\lib\site-packages\telegram\vendor\ptb_urllib3\urllib3\request.py", line 70, in request
    **urlopen_kw)
  File "C:\Users\Administrator\AppData\Local\Programs\Python\Python37-32\lib\site-packages\telegram\vendor\ptb_urllib3\urllib3\request.py", line 148, in request_encode_body
    return self.urlopen(method, url, **extra_kw)
  File "C:\Users\Administrator\AppData\Local\Programs\Python\Python37-32\lib\site-packages\telegram\vendor\ptb_urllib3\urllib3\poolmanager.py", line 244, in urlopen
    response = conn.urlopen(method, u.request_uri, **kw)
  File "C:\Users\Administrator\AppData\Local\Programs\Python\Python37-32\lib\site-packages\telegram\vendor\ptb_urllib3\urllib3\connectionpool.py", line 666, in urlopen
    _stacktrace=sys.exc_info()[2])
  File "C:\Users\Administrator\AppData\Local\Programs\Python\Python37-32\lib\site-packages\telegram\vendor\ptb_urllib3\urllib3\util\retry.py", line 347, in increment
    raise six.reraise(type(error), error, _stacktrace)
  File "C:\Users\Administrator\AppData\Local\Programs\Python\Python37-32\lib\site-packages\telegram\vendor\ptb_urllib3\urllib3\packages\six.py", line 686, in reraise
    raise value
  File "C:\Users\Administrator\AppData\Local\Programs\Python\Python37-32\lib\site-packages\telegram\vendor\ptb_urllib3\urllib3\connectionpool.py", line 617, in urlopen
    chunked=chunked)
  File "C:\Users\Administrator\AppData\Local\Programs\Python\Python37-32\lib\site-packages\telegram\vendor\ptb_urllib3\urllib3\connectionpool.py", line 405, in _make_request
    exc_cls=ReadTimeoutError)
  File "C:\Users\Administrator\AppData\Local\Programs\Python\Python37-32\lib\site-packages\telegram\vendor\ptb_urllib3\urllib3\connectionpool.py", line 321, in _raise_timeout
    raise exc_cls(*args)
telegram.vendor.ptb_urllib3.urllib3.exceptions.ReadTimeoutError: HTTPSConnectionPool(host='api.telegram.org', port=443): Read timed out. (read timeout=5.0)

During handling of the above exception, another exception occurred:

Traceback (most recent call last):
  File "C:\Users\Administrator\AppData\Local\Programs\Python\Python37-32\lib\site-packages\telegram\ext\dispatcher.py", line 279, in process_update
    handler.handle_update(update, self)
  File "C:\Users\Administrator\AppData\Local\Programs\Python\Python37-32\lib\site-packages\telegram\ext\regexhandler.py", line 173, in handle_update
    return self.callback(dispatcher.bot, update, **optional_args)
  File "telegrambot.py", line 197, in status
    update.message.reply_text('Normal')
  File "C:\Users\Administrator\AppData\Local\Programs\Python\Python37-32\lib\site-packages\telegram\message.py", line 455, in reply_text
    return self.bot.send_message(self.chat_id, *args, **kwargs)
  File "C:\Users\Administrator\AppData\Local\Programs\Python\Python37-32\lib\site-packages\telegram\bot.py", line 65, in decorator
    result = func(self, *args, **kwargs)
  File "C:\Users\Administrator\AppData\Local\Programs\Python\Python37-32\lib\site-packages\telegram\bot.py", line 90, in decorator
    result = self._request.post(url, data, timeout=kwargs.get('timeout'))
  File "C:\Users\Administrator\AppData\Local\Programs\Python\Python37-32\lib\site-packages\telegram\utils\request.py", line 309, in post
    headers={'Content-Type': 'application/json'})
  File "C:\Users\Administrator\AppData\Local\Programs\Python\Python37-32\lib\site-packages\telegram\utils\request.py", line 205, in _request_wrapper
    raise TimedOut()
telegram.error.TimedOut: Timed out
2019-04-15 11:20:36,726 - telegram.ext.dispatcher - WARNING - A TelegramError was raised while processing the Update
2019-04-15 11:20:36,726 - telegram.ext.dispatcher - ERROR - No error handlers are registered, logging exception.
Traceback (most recent call last):
  File "C:\Users\Administrator\AppData\Local\Programs\Python\Python37-32\lib\site-packages\telegram\vendor\ptb_urllib3\urllib3\connectionpool.py", line 402, in _make_request
    six.raise_from(e, None)
  File "<string>", line 2, in raise_from
  File "C:\Users\Administrator\AppData\Local\Programs\Python\Python37-32\lib\site-packages\telegram\vendor\ptb_urllib3\urllib3\connectionpool.py", line 398, in _make_request
    httplib_response = conn.getresponse()
  File "C:\Users\Administrator\AppData\Local\Programs\Python\Python37-32\lib\http\client.py", line 1321, in getresponse
    response.begin()
  File "C:\Users\Administrator\AppData\Local\Programs\Python\Python37-32\lib\http\client.py", line 296, in begin
    version, status, reason = self._read_status()
  File "C:\Users\Administrator\AppData\Local\Programs\Python\Python37-32\lib\http\client.py", line 257, in _read_status
    line = str(self.fp.readline(_MAXLINE + 1), "iso-8859-1")
  File "C:\Users\Administrator\AppData\Local\Programs\Python\Python37-32\lib\socket.py", line 589, in readinto
    return self._sock.recv_into(b)
  File "C:\Users\Administrator\AppData\Local\Programs\Python\Python37-32\lib\ssl.py", line 1052, in recv_into
    return self.read(nbytes, buffer)
  File "C:\Users\Administrator\AppData\Local\Programs\Python\Python37-32\lib\ssl.py", line 911, in read
    return self._sslobj.read(len, buffer)
socket.timeout: The read operation timed out

During handling of the above exception, another exception occurred:

Traceback (most recent call last):
  File "C:\Users\Administrator\AppData\Local\Programs\Python\Python37-32\lib\site-packages\telegram\utils\request.py", line 203, in _request_wrapper
    resp = self._con_pool.request(*args, **kwargs)
  File "C:\Users\Administrator\AppData\Local\Programs\Python\Python37-32\lib\site-packages\telegram\vendor\ptb_urllib3\urllib3\request.py", line 70, in request
    **urlopen_kw)
  File "C:\Users\Administrator\AppData\Local\Programs\Python\Python37-32\lib\site-packages\telegram\vendor\ptb_urllib3\urllib3\request.py", line 148, in request_encode_body
    return self.urlopen(method, url, **extra_kw)
  File "C:\Users\Administrator\AppData\Local\Programs\Python\Python37-32\lib\site-packages\telegram\vendor\ptb_urllib3\urllib3\poolmanager.py", line 244, in urlopen
    response = conn.urlopen(method, u.request_uri, **kw)
  File "C:\Users\Administrator\AppData\Local\Programs\Python\Python37-32\lib\site-packages\telegram\vendor\ptb_urllib3\urllib3\connectionpool.py", line 666, in urlopen
    _stacktrace=sys.exc_info()[2])
  File "C:\Users\Administrator\AppData\Local\Programs\Python\Python37-32\lib\site-packages\telegram\vendor\ptb_urllib3\urllib3\util\retry.py", line 347, in increment
    raise six.reraise(type(error), error, _stacktrace)
  File "C:\Users\Administrator\AppData\Local\Programs\Python\Python37-32\lib\site-packages\telegram\vendor\ptb_urllib3\urllib3\packages\six.py", line 686, in reraise
    raise value
  File "C:\Users\Administrator\AppData\Local\Programs\Python\Python37-32\lib\site-packages\telegram\vendor\ptb_urllib3\urllib3\connectionpool.py", line 617, in urlopen
    chunked=chunked)
  File "C:\Users\Administrator\AppData\Local\Programs\Python\Python37-32\lib\site-packages\telegram\vendor\ptb_urllib3\urllib3\connectionpool.py", line 405, in _make_request
    exc_cls=ReadTimeoutError)
  File "C:\Users\Administrator\AppData\Local\Programs\Python\Python37-32\lib\site-packages\telegram\vendor\ptb_urllib3\urllib3\connectionpool.py", line 321, in _raise_timeout
    raise exc_cls(*args)
telegram.vendor.ptb_urllib3.urllib3.exceptions.ReadTimeoutError: HTTPSConnectionPool(host='api.telegram.org', port=443): Read timed out. (read timeout=5.0)

During handling of the above exception, another exception occurred:

Traceback (most recent call last):
  File "C:\Users\Administrator\AppData\Local\Programs\Python\Python37-32\lib\site-packages\telegram\ext\dispatcher.py", line 279, in process_update
    handler.handle_update(update, self)
  File "C:\Users\Administrator\AppData\Local\Programs\Python\Python37-32\lib\site-packages\telegram\ext\callbackqueryhandler.py", line 143, in handle_update
    return self.callback(dispatcher.bot, update, **optional_args)
  File "telegrambot.py", line 45, in button
    bot.edit_message_text(chat_id = update.effective_message.chat_id,message_id = update.effective_message.message_id,text = str(NewsFeed.entries[i].title) + '\n---------------------\nLink : ' + str(NewsFeed.entries[i].link) +'\n---------------------\n' + str(NewsFeed.entries[i].summary) + '\n---------------------\nPublished on :' + str(NewsFeed.entries[i].published))
  File "C:\Users\Administrator\AppData\Local\Programs\Python\Python37-32\lib\site-packages\telegram\bot.py", line 65, in decorator
    result = func(self, *args, **kwargs)
  File "C:\Users\Administrator\AppData\Local\Programs\Python\Python37-32\lib\site-packages\telegram\bot.py", line 90, in decorator
    result = self._request.post(url, data, timeout=kwargs.get('timeout'))
  File "C:\Users\Administrator\AppData\Local\Programs\Python\Python37-32\lib\site-packages\telegram\utils\request.py", line 309, in post
    headers={'Content-Type': 'application/json'})
  File "C:\Users\Administrator\AppData\Local\Programs\Python\Python37-32\lib\site-packages\telegram\utils\request.py", line 205, in _request_wrapper
    raise TimedOut()
telegram.error.TimedOut: Timed out
2019-04-15 11:20:49,041 - telegram.ext.dispatcher - WARNING - A TelegramError was raised while processing the Update
2019-04-15 11:20:49,041 - telegram.ext.dispatcher - ERROR - No error handlers are registered, logging exception.
Traceback (most recent call last):
  File "C:\Users\Administrator\AppData\Local\Programs\Python\Python37-32\lib\site-packages\telegram\vendor\ptb_urllib3\urllib3\connectionpool.py", line 402, in _make_request
    six.raise_from(e, None)
  File "<string>", line 2, in raise_from
  File "C:\Users\Administrator\AppData\Local\Programs\Python\Python37-32\lib\site-packages\telegram\vendor\ptb_urllib3\urllib3\connectionpool.py", line 398, in _make_request
    httplib_response = conn.getresponse()
  File "C:\Users\Administrator\AppData\Local\Programs\Python\Python37-32\lib\http\client.py", line 1321, in getresponse
    response.begin()
  File "C:\Users\Administrator\AppData\Local\Programs\Python\Python37-32\lib\http\client.py", line 296, in begin
    version, status, reason = self._read_status()
  File "C:\Users\Administrator\AppData\Local\Programs\Python\Python37-32\lib\http\client.py", line 257, in _read_status
    line = str(self.fp.readline(_MAXLINE + 1), "iso-8859-1")
  File "C:\Users\Administrator\AppData\Local\Programs\Python\Python37-32\lib\socket.py", line 589, in readinto
    return self._sock.recv_into(b)
  File "C:\Users\Administrator\AppData\Local\Programs\Python\Python37-32\lib\ssl.py", line 1052, in recv_into
    return self.read(nbytes, buffer)
  File "C:\Users\Administrator\AppData\Local\Programs\Python\Python37-32\lib\ssl.py", line 911, in read
    return self._sslobj.read(len, buffer)
socket.timeout: The read operation timed out

During handling of the above exception, another exception occurred:

Traceback (most recent call last):
  File "C:\Users\Administrator\AppData\Local\Programs\Python\Python37-32\lib\site-packages\telegram\utils\request.py", line 203, in _request_wrapper
    resp = self._con_pool.request(*args, **kwargs)
  File "C:\Users\Administrator\AppData\Local\Programs\Python\Python37-32\lib\site-packages\telegram\vendor\ptb_urllib3\urllib3\request.py", line 70, in request
    **urlopen_kw)
  File "C:\Users\Administrator\AppData\Local\Programs\Python\Python37-32\lib\site-packages\telegram\vendor\ptb_urllib3\urllib3\request.py", line 148, in request_encode_body
    return self.urlopen(method, url, **extra_kw)
  File "C:\Users\Administrator\AppData\Local\Programs\Python\Python37-32\lib\site-packages\telegram\vendor\ptb_urllib3\urllib3\poolmanager.py", line 244, in urlopen
    response = conn.urlopen(method, u.request_uri, **kw)
  File "C:\Users\Administrator\AppData\Local\Programs\Python\Python37-32\lib\site-packages\telegram\vendor\ptb_urllib3\urllib3\connectionpool.py", line 666, in urlopen
    _stacktrace=sys.exc_info()[2])
  File "C:\Users\Administrator\AppData\Local\Programs\Python\Python37-32\lib\site-packages\telegram\vendor\ptb_urllib3\urllib3\util\retry.py", line 347, in increment
    raise six.reraise(type(error), error, _stacktrace)
  File "C:\Users\Administrator\AppData\Local\Programs\Python\Python37-32\lib\site-packages\telegram\vendor\ptb_urllib3\urllib3\packages\six.py", line 686, in reraise
    raise value
  File "C:\Users\Administrator\AppData\Local\Programs\Python\Python37-32\lib\site-packages\telegram\vendor\ptb_urllib3\urllib3\connectionpool.py", line 617, in urlopen
    chunked=chunked)
  File "C:\Users\Administrator\AppData\Local\Programs\Python\Python37-32\lib\site-packages\telegram\vendor\ptb_urllib3\urllib3\connectionpool.py", line 405, in _make_request
    exc_cls=ReadTimeoutError)
  File "C:\Users\Administrator\AppData\Local\Programs\Python\Python37-32\lib\site-packages\telegram\vendor\ptb_urllib3\urllib3\connectionpool.py", line 321, in _raise_timeout
    raise exc_cls(*args)
telegram.vendor.ptb_urllib3.urllib3.exceptions.ReadTimeoutError: HTTPSConnectionPool(host='api.telegram.org', port=443): Read timed out. (read timeout=5.0)

During handling of the above exception, another exception occurred:

Traceback (most recent call last):
  File "C:\Users\Administrator\AppData\Local\Programs\Python\Python37-32\lib\site-packages\telegram\ext\dispatcher.py", line 279, in process_update
    handler.handle_update(update, self)
  File "C:\Users\Administrator\AppData\Local\Programs\Python\Python37-32\lib\site-packages\telegram\ext\callbackqueryhandler.py", line 143, in handle_update
    return self.callback(dispatcher.bot, update, **optional_args)
  File "telegrambot.py", line 45, in button
    bot.edit_message_text(chat_id = update.effective_message.chat_id,message_id = update.effective_message.message_id,text = str(NewsFeed.entries[i].title) + '\n---------------------\nLink : ' + str(NewsFeed.entries[i].link) +'\n---------------------\n' + str(NewsFeed.entries[i].summary) + '\n---------------------\nPublished on :' + str(NewsFeed.entries[i].published))
  File "C:\Users\Administrator\AppData\Local\Programs\Python\Python37-32\lib\site-packages\telegram\bot.py", line 65, in decorator
    result = func(self, *args, **kwargs)
  File "C:\Users\Administrator\AppData\Local\Programs\Python\Python37-32\lib\site-packages\telegram\bot.py", line 90, in decorator
    result = self._request.post(url, data, timeout=kwargs.get('timeout'))
  File "C:\Users\Administrator\AppData\Local\Programs\Python\Python37-32\lib\site-packages\telegram\utils\request.py", line 309, in post
    headers={'Content-Type': 'application/json'})
  File "C:\Users\Administrator\AppData\Local\Programs\Python\Python37-32\lib\site-packages\telegram\utils\request.py", line 205, in _request_wrapper
    raise TimedOut()
telegram.error.TimedOut: Timed out
2019-04-15 11:20:55,270 - telegram.ext.dispatcher - WARNING - A TelegramError was raised while processing the Update
2019-04-15 11:20:55,270 - telegram.ext.dispatcher - ERROR - No error handlers are registered, logging exception.
Traceback (most recent call last):
  File "C:\Users\Administrator\AppData\Local\Programs\Python\Python37-32\lib\site-packages\telegram\vendor\ptb_urllib3\urllib3\connectionpool.py", line 402, in _make_request
    six.raise_from(e, None)
  File "<string>", line 2, in raise_from
  File "C:\Users\Administrator\AppData\Local\Programs\Python\Python37-32\lib\site-packages\telegram\vendor\ptb_urllib3\urllib3\connectionpool.py", line 398, in _make_request
    httplib_response = conn.getresponse()
  File "C:\Users\Administrator\AppData\Local\Programs\Python\Python37-32\lib\http\client.py", line 1321, in getresponse
    response.begin()
  File "C:\Users\Administrator\AppData\Local\Programs\Python\Python37-32\lib\http\client.py", line 296, in begin
    version, status, reason = self._read_status()
  File "C:\Users\Administrator\AppData\Local\Programs\Python\Python37-32\lib\http\client.py", line 257, in _read_status
    line = str(self.fp.readline(_MAXLINE + 1), "iso-8859-1")
  File "C:\Users\Administrator\AppData\Local\Programs\Python\Python37-32\lib\socket.py", line 589, in readinto
    return self._sock.recv_into(b)
  File "C:\Users\Administrator\AppData\Local\Programs\Python\Python37-32\lib\ssl.py", line 1052, in recv_into
    return self.read(nbytes, buffer)
  File "C:\Users\Administrator\AppData\Local\Programs\Python\Python37-32\lib\ssl.py", line 911, in read
    return self._sslobj.read(len, buffer)
socket.timeout: The read operation timed out

During handling of the above exception, another exception occurred:

Traceback (most recent call last):
  File "C:\Users\Administrator\AppData\Local\Programs\Python\Python37-32\lib\site-packages\telegram\utils\request.py", line 203, in _request_wrapper
    resp = self._con_pool.request(*args, **kwargs)
  File "C:\Users\Administrator\AppData\Local\Programs\Python\Python37-32\lib\site-packages\telegram\vendor\ptb_urllib3\urllib3\request.py", line 70, in request
    **urlopen_kw)
  File "C:\Users\Administrator\AppData\Local\Programs\Python\Python37-32\lib\site-packages\telegram\vendor\ptb_urllib3\urllib3\request.py", line 148, in request_encode_body
    return self.urlopen(method, url, **extra_kw)
  File "C:\Users\Administrator\AppData\Local\Programs\Python\Python37-32\lib\site-packages\telegram\vendor\ptb_urllib3\urllib3\poolmanager.py", line 244, in urlopen
    response = conn.urlopen(method, u.request_uri, **kw)
  File "C:\Users\Administrator\AppData\Local\Programs\Python\Python37-32\lib\site-packages\telegram\vendor\ptb_urllib3\urllib3\connectionpool.py", line 666, in urlopen
    _stacktrace=sys.exc_info()[2])
  File "C:\Users\Administrator\AppData\Local\Programs\Python\Python37-32\lib\site-packages\telegram\vendor\ptb_urllib3\urllib3\util\retry.py", line 347, in increment
    raise six.reraise(type(error), error, _stacktrace)
  File "C:\Users\Administrator\AppData\Local\Programs\Python\Python37-32\lib\site-packages\telegram\vendor\ptb_urllib3\urllib3\packages\six.py", line 686, in reraise
    raise value
  File "C:\Users\Administrator\AppData\Local\Programs\Python\Python37-32\lib\site-packages\telegram\vendor\ptb_urllib3\urllib3\connectionpool.py", line 617, in urlopen
    chunked=chunked)
  File "C:\Users\Administrator\AppData\Local\Programs\Python\Python37-32\lib\site-packages\telegram\vendor\ptb_urllib3\urllib3\connectionpool.py", line 405, in _make_request
    exc_cls=ReadTimeoutError)
  File "C:\Users\Administrator\AppData\Local\Programs\Python\Python37-32\lib\site-packages\telegram\vendor\ptb_urllib3\urllib3\connectionpool.py", line 321, in _raise_timeout
    raise exc_cls(*args)
telegram.vendor.ptb_urllib3.urllib3.exceptions.ReadTimeoutError: HTTPSConnectionPool(host='api.telegram.org', port=443): Read timed out. (read timeout=5.0)

During handling of the above exception, another exception occurred:

Traceback (most recent call last):
  File "C:\Users\Administrator\AppData\Local\Programs\Python\Python37-32\lib\site-packages\telegram\ext\dispatcher.py", line 279, in process_update
    handler.handle_update(update, self)
  File "C:\Users\Administrator\AppData\Local\Programs\Python\Python37-32\lib\site-packages\telegram\ext\regexhandler.py", line 173, in handle_update
    return self.callback(dispatcher.bot, update, **optional_args)
  File "telegrambot.py", line 197, in status
    update.message.reply_text('Normal')
  File "C:\Users\Administrator\AppData\Local\Programs\Python\Python37-32\lib\site-packages\telegram\message.py", line 455, in reply_text
    return self.bot.send_message(self.chat_id, *args, **kwargs)
  File "C:\Users\Administrator\AppData\Local\Programs\Python\Python37-32\lib\site-packages\telegram\bot.py", line 65, in decorator
    result = func(self, *args, **kwargs)
  File "C:\Users\Administrator\AppData\Local\Programs\Python\Python37-32\lib\site-packages\telegram\bot.py", line 90, in decorator
    result = self._request.post(url, data, timeout=kwargs.get('timeout'))
  File "C:\Users\Administrator\AppData\Local\Programs\Python\Python37-32\lib\site-packages\telegram\utils\request.py", line 309, in post
    headers={'Content-Type': 'application/json'})
  File "C:\Users\Administrator\AppData\Local\Programs\Python\Python37-32\lib\site-packages\telegram\utils\request.py", line 205, in _request_wrapper
    raise TimedOut()
telegram.error.TimedOut: Timed out
2019-04-15 11:21:47,707 - telegram.ext.dispatcher - WARNING - A TelegramError was raised while processing the Update
2019-04-15 11:21:47,708 - telegram.ext.dispatcher - ERROR - No error handlers are registered, logging exception.
Traceback (most recent call last):
  File "C:\Users\Administrator\AppData\Local\Programs\Python\Python37-32\lib\site-packages\telegram\ext\dispatcher.py", line 279, in process_update
    handler.handle_update(update, self)
  File "C:\Users\Administrator\AppData\Local\Programs\Python\Python37-32\lib\site-packages\telegram\ext\callbackqueryhandler.py", line 143, in handle_update
    return self.callback(dispatcher.bot, update, **optional_args)
  File "telegrambot.py", line 45, in button
    bot.edit_message_text(chat_id = update.effective_message.chat_id,message_id = update.effective_message.message_id,text = str(NewsFeed.entries[i].title) + '\n---------------------\nLink : ' + str(NewsFeed.entries[i].link) +'\n---------------------\n' + str(NewsFeed.entries[i].summary) + '\n---------------------\nPublished on :' + str(NewsFeed.entries[i].published))
  File "C:\Users\Administrator\AppData\Local\Programs\Python\Python37-32\lib\site-packages\telegram\bot.py", line 65, in decorator
    result = func(self, *args, **kwargs)
  File "C:\Users\Administrator\AppData\Local\Programs\Python\Python37-32\lib\site-packages\telegram\bot.py", line 90, in decorator
    result = self._request.post(url, data, timeout=kwargs.get('timeout'))
  File "C:\Users\Administrator\AppData\Local\Programs\Python\Python37-32\lib\site-packages\telegram\utils\request.py", line 309, in post
    headers={'Content-Type': 'application/json'})
  File "C:\Users\Administrator\AppData\Local\Programs\Python\Python37-32\lib\site-packages\telegram\utils\request.py", line 216, in _request_wrapper
    message = self._parse(resp.data)
  File "C:\Users\Administrator\AppData\Local\Programs\Python\Python37-32\lib\site-packages\telegram\utils\request.py", line 174, in _parse
    raise RetryAfter(retry_after)
telegram.error.RetryAfter: Flood control exceeded. Retry in 458 seconds
2019-04-15 11:21:53,659 - telegram.ext.dispatcher - WARNING - A TelegramError was raised while processing the Update
2019-04-15 11:21:53,660 - telegram.ext.dispatcher - ERROR - No error handlers are registered, logging exception.
Traceback (most recent call last):
  File "C:\Users\Administrator\AppData\Local\Programs\Python\Python37-32\lib\site-packages\telegram\ext\dispatcher.py", line 279, in process_update
    handler.handle_update(update, self)
  File "C:\Users\Administrator\AppData\Local\Programs\Python\Python37-32\lib\site-packages\telegram\ext\callbackqueryhandler.py", line 143, in handle_update
    return self.callback(dispatcher.bot, update, **optional_args)
  File "telegrambot.py", line 45, in button
    bot.edit_message_text(chat_id = update.effective_message.chat_id,message_id = update.effective_message.message_id,text = str(NewsFeed.entries[i].title) + '\n---------------------\nLink : ' + str(NewsFeed.entries[i].link) +'\n---------------------\n' + str(NewsFeed.entries[i].summary) + '\n---------------------\nPublished on :' + str(NewsFeed.entries[i].published))
  File "C:\Users\Administrator\AppData\Local\Programs\Python\Python37-32\lib\site-packages\telegram\bot.py", line 65, in decorator
    result = func(self, *args, **kwargs)
  File "C:\Users\Administrator\AppData\Local\Programs\Python\Python37-32\lib\site-packages\telegram\bot.py", line 90, in decorator
    result = self._request.post(url, data, timeout=kwargs.get('timeout'))
  File "C:\Users\Administrator\AppData\Local\Programs\Python\Python37-32\lib\site-packages\telegram\utils\request.py", line 309, in post
    headers={'Content-Type': 'application/json'})
  File "C:\Users\Administrator\AppData\Local\Programs\Python\Python37-32\lib\site-packages\telegram\utils\request.py", line 216, in _request_wrapper
    message = self._parse(resp.data)
  File "C:\Users\Administrator\AppData\Local\Programs\Python\Python37-32\lib\site-packages\telegram\utils\request.py", line 174, in _parse
    raise RetryAfter(retry_after)
telegram.error.RetryAfter: Flood control exceeded. Retry in 452 seconds
2019-04-15 11:22:10,116 - telegram.ext.dispatcher - WARNING - A TelegramError was raised while processing the Update
2019-04-15 11:22:10,116 - telegram.ext.dispatcher - ERROR - No error handlers are registered, logging exception.
Traceback (most recent call last):
  File "C:\Users\Administrator\AppData\Local\Programs\Python\Python37-32\lib\site-packages\telegram\ext\dispatcher.py", line 279, in process_update
    handler.handle_update(update, self)
  File "C:\Users\Administrator\AppData\Local\Programs\Python\Python37-32\lib\site-packages\telegram\ext\callbackqueryhandler.py", line 143, in handle_update
    return self.callback(dispatcher.bot, update, **optional_args)
  File "telegrambot.py", line 45, in button
    bot.edit_message_text(chat_id = update.effective_message.chat_id,message_id = update.effective_message.message_id,text = str(NewsFeed.entries[i].title) + '\n---------------------\nLink : ' + str(NewsFeed.entries[i].link) +'\n---------------------\n' + str(NewsFeed.entries[i].summary) + '\n---------------------\nPublished on :' + str(NewsFeed.entries[i].published))
  File "C:\Users\Administrator\AppData\Local\Programs\Python\Python37-32\lib\site-packages\telegram\bot.py", line 65, in decorator
    result = func(self, *args, **kwargs)
  File "C:\Users\Administrator\AppData\Local\Programs\Python\Python37-32\lib\site-packages\telegram\bot.py", line 90, in decorator
    result = self._request.post(url, data, timeout=kwargs.get('timeout'))
  File "C:\Users\Administrator\AppData\Local\Programs\Python\Python37-32\lib\site-packages\telegram\utils\request.py", line 309, in post
    headers={'Content-Type': 'application/json'})
  File "C:\Users\Administrator\AppData\Local\Programs\Python\Python37-32\lib\site-packages\telegram\utils\request.py", line 216, in _request_wrapper
    message = self._parse(resp.data)
  File "C:\Users\Administrator\AppData\Local\Programs\Python\Python37-32\lib\site-packages\telegram\utils\request.py", line 174, in _parse
    raise RetryAfter(retry_after)
telegram.error.RetryAfter: Flood control exceeded. Retry in 436 seconds
2019-04-15 11:22:10,556 - telegram.ext.dispatcher - WARNING - A TelegramError was raised while processing the Update
2019-04-15 11:22:10,556 - telegram.ext.dispatcher - ERROR - No error handlers are registered, logging exception.
Traceback (most recent call last):
  File "C:\Users\Administrator\AppData\Local\Programs\Python\Python37-32\lib\site-packages\telegram\ext\dispatcher.py", line 279, in process_update
    handler.handle_update(update, self)
  File "C:\Users\Administrator\AppData\Local\Programs\Python\Python37-32\lib\site-packages\telegram\ext\callbackqueryhandler.py", line 143, in handle_update
    return self.callback(dispatcher.bot, update, **optional_args)
  File "telegrambot.py", line 45, in button
    bot.edit_message_text(chat_id = update.effective_message.chat_id,message_id = update.effective_message.message_id,text = str(NewsFeed.entries[i].title) + '\n---------------------\nLink : ' + str(NewsFeed.entries[i].link) +'\n---------------------\n' + str(NewsFeed.entries[i].summary) + '\n---------------------\nPublished on :' + str(NewsFeed.entries[i].published))
  File "C:\Users\Administrator\AppData\Local\Programs\Python\Python37-32\lib\site-packages\telegram\bot.py", line 65, in decorator
    result = func(self, *args, **kwargs)
  File "C:\Users\Administrator\AppData\Local\Programs\Python\Python37-32\lib\site-packages\telegram\bot.py", line 90, in decorator
    result = self._request.post(url, data, timeout=kwargs.get('timeout'))
  File "C:\Users\Administrator\AppData\Local\Programs\Python\Python37-32\lib\site-packages\telegram\utils\request.py", line 309, in post
    headers={'Content-Type': 'application/json'})
  File "C:\Users\Administrator\AppData\Local\Programs\Python\Python37-32\lib\site-packages\telegram\utils\request.py", line 223, in _request_wrapper
    raise BadRequest(message)
telegram.error.BadRequest: Message is not modified: specified new message content and reply markup are exactly the same as a current content and reply_markup of the message
2019-04-15 11:22:14,271 - telegram.ext.dispatcher - WARNING - A TelegramError was raised while processing the Update
2019-04-15 11:22:14,272 - telegram.ext.dispatcher - ERROR - No error handlers are registered, logging exception.
Traceback (most recent call last):
  File "C:\Users\Administrator\AppData\Local\Programs\Python\Python37-32\lib\site-packages\telegram\ext\dispatcher.py", line 279, in process_update
    handler.handle_update(update, self)
  File "C:\Users\Administrator\AppData\Local\Programs\Python\Python37-32\lib\site-packages\telegram\ext\callbackqueryhandler.py", line 143, in handle_update
    return self.callback(dispatcher.bot, update, **optional_args)
  File "telegrambot.py", line 45, in button
    bot.edit_message_text(chat_id = update.effective_message.chat_id,message_id = update.effective_message.message_id,text = str(NewsFeed.entries[i].title) + '\n---------------------\nLink : ' + str(NewsFeed.entries[i].link) +'\n---------------------\n' + str(NewsFeed.entries[i].summary) + '\n---------------------\nPublished on :' + str(NewsFeed.entries[i].published))
  File "C:\Users\Administrator\AppData\Local\Programs\Python\Python37-32\lib\site-packages\telegram\bot.py", line 65, in decorator
    result = func(self, *args, **kwargs)
  File "C:\Users\Administrator\AppData\Local\Programs\Python\Python37-32\lib\site-packages\telegram\bot.py", line 90, in decorator
    result = self._request.post(url, data, timeout=kwargs.get('timeout'))
  File "C:\Users\Administrator\AppData\Local\Programs\Python\Python37-32\lib\site-packages\telegram\utils\request.py", line 309, in post
    headers={'Content-Type': 'application/json'})
  File "C:\Users\Administrator\AppData\Local\Programs\Python\Python37-32\lib\site-packages\telegram\utils\request.py", line 223, in _request_wrapper
    raise BadRequest(message)
telegram.error.BadRequest: Message is not modified: specified new message content and reply markup are exactly the same as a current content and reply_markup of the message
2019-04-15 11:22:16,671 - telegram.ext.dispatcher - WARNING - A TelegramError was raised while processing the Update
2019-04-15 11:22:16,671 - telegram.ext.dispatcher - ERROR - No error handlers are registered, logging exception.
Traceback (most recent call last):
  File "C:\Users\Administrator\AppData\Local\Programs\Python\Python37-32\lib\site-packages\telegram\ext\dispatcher.py", line 279, in process_update
    handler.handle_update(update, self)
  File "C:\Users\Administrator\AppData\Local\Programs\Python\Python37-32\lib\site-packages\telegram\ext\callbackqueryhandler.py", line 143, in handle_update
    return self.callback(dispatcher.bot, update, **optional_args)
  File "telegrambot.py", line 45, in button
    bot.edit_message_text(chat_id = update.effective_message.chat_id,message_id = update.effective_message.message_id,text = str(NewsFeed.entries[i].title) + '\n---------------------\nLink : ' + str(NewsFeed.entries[i].link) +'\n---------------------\n' + str(NewsFeed.entries[i].summary) + '\n---------------------\nPublished on :' + str(NewsFeed.entries[i].published))
  File "C:\Users\Administrator\AppData\Local\Programs\Python\Python37-32\lib\site-packages\telegram\bot.py", line 65, in decorator
    result = func(self, *args, **kwargs)
  File "C:\Users\Administrator\AppData\Local\Programs\Python\Python37-32\lib\site-packages\telegram\bot.py", line 90, in decorator
    result = self._request.post(url, data, timeout=kwargs.get('timeout'))
  File "C:\Users\Administrator\AppData\Local\Programs\Python\Python37-32\lib\site-packages\telegram\utils\request.py", line 309, in post
    headers={'Content-Type': 'application/json'})
  File "C:\Users\Administrator\AppData\Local\Programs\Python\Python37-32\lib\site-packages\telegram\utils\request.py", line 223, in _request_wrapper
    raise BadRequest(message)
telegram.error.BadRequest: Message is not modified: specified new message content and reply markup are exactly the same as a current content and reply_markup of the message
2019-04-15 11:22:20,628 - telegram.ext.dispatcher - WARNING - A TelegramError was raised while processing the Update
2019-04-15 11:22:20,628 - telegram.ext.dispatcher - ERROR - No error handlers are registered, logging exception.
Traceback (most recent call last):
  File "C:\Users\Administrator\AppData\Local\Programs\Python\Python37-32\lib\site-packages\telegram\ext\dispatcher.py", line 279, in process_update
    handler.handle_update(update, self)
  File "C:\Users\Administrator\AppData\Local\Programs\Python\Python37-32\lib\site-packages\telegram\ext\callbackqueryhandler.py", line 143, in handle_update
    return self.callback(dispatcher.bot, update, **optional_args)
  File "telegrambot.py", line 45, in button
    bot.edit_message_text(chat_id = update.effective_message.chat_id,message_id = update.effective_message.message_id,text = str(NewsFeed.entries[i].title) + '\n---------------------\nLink : ' + str(NewsFeed.entries[i].link) +'\n---------------------\n' + str(NewsFeed.entries[i].summary) + '\n---------------------\nPublished on :' + str(NewsFeed.entries[i].published))
  File "C:\Users\Administrator\AppData\Local\Programs\Python\Python37-32\lib\site-packages\telegram\bot.py", line 65, in decorator
    result = func(self, *args, **kwargs)
  File "C:\Users\Administrator\AppData\Local\Programs\Python\Python37-32\lib\site-packages\telegram\bot.py", line 90, in decorator
    result = self._request.post(url, data, timeout=kwargs.get('timeout'))
  File "C:\Users\Administrator\AppData\Local\Programs\Python\Python37-32\lib\site-packages\telegram\utils\request.py", line 309, in post
    headers={'Content-Type': 'application/json'})
  File "C:\Users\Administrator\AppData\Local\Programs\Python\Python37-32\lib\site-packages\telegram\utils\request.py", line 223, in _request_wrapper
    raise BadRequest(message)
telegram.error.BadRequest: Message is not modified: specified new message content and reply markup are exactly the same as a current content and reply_markup of the message
2019-04-15 11:22:21,349 - telegram.ext.dispatcher - WARNING - A TelegramError was raised while processing the Update
2019-04-15 11:22:21,349 - telegram.ext.dispatcher - ERROR - No error handlers are registered, logging exception.
Traceback (most recent call last):
  File "C:\Users\Administrator\AppData\Local\Programs\Python\Python37-32\lib\site-packages\telegram\ext\dispatcher.py", line 279, in process_update
    handler.handle_update(update, self)
  File "C:\Users\Administrator\AppData\Local\Programs\Python\Python37-32\lib\site-packages\telegram\ext\callbackqueryhandler.py", line 143, in handle_update
    return self.callback(dispatcher.bot, update, **optional_args)
  File "telegrambot.py", line 45, in button
    bot.edit_message_text(chat_id = update.effective_message.chat_id,message_id = update.effective_message.message_id,text = str(NewsFeed.entries[i].title) + '\n---------------------\nLink : ' + str(NewsFeed.entries[i].link) +'\n---------------------\n' + str(NewsFeed.entries[i].summary) + '\n---------------------\nPublished on :' + str(NewsFeed.entries[i].published))
  File "C:\Users\Administrator\AppData\Local\Programs\Python\Python37-32\lib\site-packages\telegram\bot.py", line 65, in decorator
    result = func(self, *args, **kwargs)
  File "C:\Users\Administrator\AppData\Local\Programs\Python\Python37-32\lib\site-packages\telegram\bot.py", line 90, in decorator
    result = self._request.post(url, data, timeout=kwargs.get('timeout'))
  File "C:\Users\Administrator\AppData\Local\Programs\Python\Python37-32\lib\site-packages\telegram\utils\request.py", line 309, in post
    headers={'Content-Type': 'application/json'})
  File "C:\Users\Administrator\AppData\Local\Programs\Python\Python37-32\lib\site-packages\telegram\utils\request.py", line 223, in _request_wrapper
    raise BadRequest(message)
telegram.error.BadRequest: Message is not modified: specified new message content and reply markup are exactly the same as a current content and reply_markup of the message
2019-04-15 11:22:21,720 - telegram.ext.dispatcher - WARNING - A TelegramError was raised while processing the Update
2019-04-15 11:22:21,720 - telegram.ext.dispatcher - ERROR - No error handlers are registered, logging exception.
Traceback (most recent call last):
  File "C:\Users\Administrator\AppData\Local\Programs\Python\Python37-32\lib\site-packages\telegram\ext\dispatcher.py", line 279, in process_update
    handler.handle_update(update, self)
  File "C:\Users\Administrator\AppData\Local\Programs\Python\Python37-32\lib\site-packages\telegram\ext\callbackqueryhandler.py", line 143, in handle_update
    return self.callback(dispatcher.bot, update, **optional_args)
  File "telegrambot.py", line 45, in button
    bot.edit_message_text(chat_id = update.effective_message.chat_id,message_id = update.effective_message.message_id,text = str(NewsFeed.entries[i].title) + '\n---------------------\nLink : ' + str(NewsFeed.entries[i].link) +'\n---------------------\n' + str(NewsFeed.entries[i].summary) + '\n---------------------\nPublished on :' + str(NewsFeed.entries[i].published))
  File "C:\Users\Administrator\AppData\Local\Programs\Python\Python37-32\lib\site-packages\telegram\bot.py", line 65, in decorator
    result = func(self, *args, **kwargs)
  File "C:\Users\Administrator\AppData\Local\Programs\Python\Python37-32\lib\site-packages\telegram\bot.py", line 90, in decorator
    result = self._request.post(url, data, timeout=kwargs.get('timeout'))
  File "C:\Users\Administrator\AppData\Local\Programs\Python\Python37-32\lib\site-packages\telegram\utils\request.py", line 309, in post
    headers={'Content-Type': 'application/json'})
  File "C:\Users\Administrator\AppData\Local\Programs\Python\Python37-32\lib\site-packages\telegram\utils\request.py", line 223, in _request_wrapper
    raise BadRequest(message)
telegram.error.BadRequest: Message is not modified: specified new message content and reply markup are exactly the same as a current content and reply_markup of the message
2019-04-15 11:22:22,075 - telegram.ext.dispatcher - WARNING - A TelegramError was raised while processing the Update
2019-04-15 11:22:22,076 - telegram.ext.dispatcher - ERROR - No error handlers are registered, logging exception.
Traceback (most recent call last):
  File "C:\Users\Administrator\AppData\Local\Programs\Python\Python37-32\lib\site-packages\telegram\ext\dispatcher.py", line 279, in process_update
    handler.handle_update(update, self)
  File "C:\Users\Administrator\AppData\Local\Programs\Python\Python37-32\lib\site-packages\telegram\ext\callbackqueryhandler.py", line 143, in handle_update
    return self.callback(dispatcher.bot, update, **optional_args)
  File "telegrambot.py", line 45, in button
    bot.edit_message_text(chat_id = update.effective_message.chat_id,message_id = update.effective_message.message_id,text = str(NewsFeed.entries[i].title) + '\n---------------------\nLink : ' + str(NewsFeed.entries[i].link) +'\n---------------------\n' + str(NewsFeed.entries[i].summary) + '\n---------------------\nPublished on :' + str(NewsFeed.entries[i].published))
  File "C:\Users\Administrator\AppData\Local\Programs\Python\Python37-32\lib\site-packages\telegram\bot.py", line 65, in decorator
    result = func(self, *args, **kwargs)
  File "C:\Users\Administrator\AppData\Local\Programs\Python\Python37-32\lib\site-packages\telegram\bot.py", line 90, in decorator
    result = self._request.post(url, data, timeout=kwargs.get('timeout'))
  File "C:\Users\Administrator\AppData\Local\Programs\Python\Python37-32\lib\site-packages\telegram\utils\request.py", line 309, in post
    headers={'Content-Type': 'application/json'})
  File "C:\Users\Administrator\AppData\Local\Programs\Python\Python37-32\lib\site-packages\telegram\utils\request.py", line 223, in _request_wrapper
    raise BadRequest(message)
telegram.error.BadRequest: Message is not modified: specified new message content and reply markup are exactly the same as a current content and reply_markup of the message
2019-04-15 11:22:22,432 - telegram.ext.dispatcher - WARNING - A TelegramError was raised while processing the Update
2019-04-15 11:22:22,432 - telegram.ext.dispatcher - ERROR - No error handlers are registered, logging exception.
Traceback (most recent call last):
  File "C:\Users\Administrator\AppData\Local\Programs\Python\Python37-32\lib\site-packages\telegram\ext\dispatcher.py", line 279, in process_update
    handler.handle_update(update, self)
  File "C:\Users\Administrator\AppData\Local\Programs\Python\Python37-32\lib\site-packages\telegram\ext\callbackqueryhandler.py", line 143, in handle_update
    return self.callback(dispatcher.bot, update, **optional_args)
  File "telegrambot.py", line 45, in button
    bot.edit_message_text(chat_id = update.effective_message.chat_id,message_id = update.effective_message.message_id,text = str(NewsFeed.entries[i].title) + '\n---------------------\nLink : ' + str(NewsFeed.entries[i].link) +'\n---------------------\n' + str(NewsFeed.entries[i].summary) + '\n---------------------\nPublished on :' + str(NewsFeed.entries[i].published))
  File "C:\Users\Administrator\AppData\Local\Programs\Python\Python37-32\lib\site-packages\telegram\bot.py", line 65, in decorator
    result = func(self, *args, **kwargs)
  File "C:\Users\Administrator\AppData\Local\Programs\Python\Python37-32\lib\site-packages\telegram\bot.py", line 90, in decorator
    result = self._request.post(url, data, timeout=kwargs.get('timeout'))
  File "C:\Users\Administrator\AppData\Local\Programs\Python\Python37-32\lib\site-packages\telegram\utils\request.py", line 309, in post
    headers={'Content-Type': 'application/json'})
  File "C:\Users\Administrator\AppData\Local\Programs\Python\Python37-32\lib\site-packages\telegram\utils\request.py", line 223, in _request_wrapper
    raise BadRequest(message)
telegram.error.BadRequest: Message is not modified: specified new message content and reply markup are exactly the same as a current content and reply_markup of the message
2019-04-15 11:22:26,600 - telegram.ext.dispatcher - WARNING - A TelegramError was raised while processing the Update
2019-04-15 11:22:26,600 - telegram.ext.dispatcher - ERROR - No error handlers are registered, logging exception.
Traceback (most recent call last):
  File "C:\Users\Administrator\AppData\Local\Programs\Python\Python37-32\lib\site-packages\telegram\ext\dispatcher.py", line 279, in process_update
    handler.handle_update(update, self)
  File "C:\Users\Administrator\AppData\Local\Programs\Python\Python37-32\lib\site-packages\telegram\ext\callbackqueryhandler.py", line 143, in handle_update
    return self.callback(dispatcher.bot, update, **optional_args)
  File "telegrambot.py", line 45, in button
    bot.edit_message_text(chat_id = update.effective_message.chat_id,message_id = update.effective_message.message_id,text = str(NewsFeed.entries[i].title) + '\n---------------------\nLink : ' + str(NewsFeed.entries[i].link) +'\n---------------------\n' + str(NewsFeed.entries[i].summary) + '\n---------------------\nPublished on :' + str(NewsFeed.entries[i].published))
  File "C:\Users\Administrator\AppData\Local\Programs\Python\Python37-32\lib\site-packages\telegram\bot.py", line 65, in decorator
    result = func(self, *args, **kwargs)
  File "C:\Users\Administrator\AppData\Local\Programs\Python\Python37-32\lib\site-packages\telegram\bot.py", line 90, in decorator
    result = self._request.post(url, data, timeout=kwargs.get('timeout'))
  File "C:\Users\Administrator\AppData\Local\Programs\Python\Python37-32\lib\site-packages\telegram\utils\request.py", line 309, in post
    headers={'Content-Type': 'application/json'})
  File "C:\Users\Administrator\AppData\Local\Programs\Python\Python37-32\lib\site-packages\telegram\utils\request.py", line 223, in _request_wrapper
    raise BadRequest(message)
telegram.error.BadRequest: Message is not modified: specified new message content and reply markup are exactly the same as a current content and reply_markup of the message
2019-04-15 19:05:50,560 - telegram.vendor.ptb_urllib3.urllib3.connectionpool - WARNING - Retrying (Retry(total=2, connect=None, read=None, redirect=None)) after connection broken by 'NewConnectionError('<telegram.vendor.ptb_urllib3.urllib3.connection.VerifiedHTTPSConnection object at 0x240C37B0>: Failed to establish a new connection: [Errno 11004] getaddrinfo failed')': /bot886726378:AAF9gwzWZzr0pfw-Wh5_bnnQHUybcOI6Z6g/getUpdates
2019-04-16 22:55:12,222 - telegram.vendor.ptb_urllib3.urllib3.connectionpool - WARNING - Retrying (Retry(total=2, connect=None, read=None, redirect=None)) after connection broken by 'ConnectTimeoutError(<telegram.vendor.ptb_urllib3.urllib3.connectionpool.HTTPSConnectionPool object at 0x240C31B0>, 'Connect timed out. (connect timeout=5.0)')': /bot886726378:AAF9gwzWZzr0pfw-Wh5_bnnQHUybcOI6Z6g/getUpdates
2019-04-16 22:55:28,857 - telegram.vendor.ptb_urllib3.urllib3.connectionpool - WARNING - Retrying (Retry(total=2, connect=None, read=None, redirect=None)) after connection broken by 'ConnectTimeoutError(<telegram.vendor.ptb_urllib3.urllib3.connectionpool.HTTPSConnectionPool object at 0x240C31B0>, 'Connect timed out. (connect timeout=5.0)')': /bot886726378:AAF9gwzWZzr0pfw-Wh5_bnnQHUybcOI6Z6g/getUpdates
2019-04-16 23:28:56,627 - telegram.vendor.ptb_urllib3.urllib3.connectionpool - WARNING - Retrying (Retry(total=2, connect=None, read=None, redirect=None)) after connection broken by 'ConnectTimeoutError(<telegram.vendor.ptb_urllib3.urllib3.connectionpool.HTTPSConnectionPool object at 0x240C31B0>, 'Connect timed out. (connect timeout=5.0)')': /bot886726378:AAF9gwzWZzr0pfw-Wh5_bnnQHUybcOI6Z6g/getUpdates
2019-04-16 23:29:03,097 - telegram.vendor.ptb_urllib3.urllib3.connectionpool - WARNING - Retrying (Retry(total=1, connect=None, read=None, redirect=None)) after connection broken by 'ConnectTimeoutError(<telegram.vendor.ptb_urllib3.urllib3.connectionpool.HTTPSConnectionPool object at 0x240C31B0>, 'Connect timed out. (connect timeout=5.0)')': /bot886726378:AAF9gwzWZzr0pfw-Wh5_bnnQHUybcOI6Z6g/getUpdates
2019-04-16 23:29:08,415 - telegram.vendor.ptb_urllib3.urllib3.connectionpool - WARNING - Retrying (Retry(total=0, connect=None, read=None, redirect=None)) after connection broken by 'ConnectTimeoutError(<telegram.vendor.ptb_urllib3.urllib3.connectionpool.HTTPSConnectionPool object at 0x240C31B0>, 'Connect timed out. (connect timeout=5.0)')': /bot886726378:AAF9gwzWZzr0pfw-Wh5_bnnQHUybcOI6Z6g/getUpdates
2019-04-17 17:42:53,993 - telegram.ext.updater - INFO - Received signal 2 (SIGINT), stopping...
2019-04-17 17:50:49,119 - telegram.ext.dispatcher - ERROR - An uncaught error was raised while processing the update
Traceback (most recent call last):
  File "C:\Users\Administrator\AppData\Local\Programs\Python\Python37-32\lib\site-packages\telegram\ext\dispatcher.py", line 279, in process_update
    handler.handle_update(update, self)
  File "C:\Users\Administrator\AppData\Local\Programs\Python\Python37-32\lib\site-packages\telegram\ext\commandhandler.py", line 173, in handle_update
    return self.callback(dispatcher.bot, update, **optional_args)
  File "telegrambot.py", line 366, in gg
    if search == row['tag'] :
KeyError: 'tag'
2019-04-17 17:52:11,233 - telegram.ext.updater - INFO - Received signal 2 (SIGINT), stopping...
2019-04-17 17:52:54,015 - telegram.ext.dispatcher - ERROR - An uncaught error was raised while processing the update
Traceback (most recent call last):
  File "C:\Users\Administrator\AppData\Local\Programs\Python\Python37-32\lib\site-packages\telegram\ext\dispatcher.py", line 279, in process_update
    handler.handle_update(update, self)
  File "C:\Users\Administrator\AppData\Local\Programs\Python\Python37-32\lib\site-packages\telegram\ext\commandhandler.py", line 173, in handle_update
    return self.callback(dispatcher.bot, update, **optional_args)
  File "telegrambot.py", line 371, in gg
    write.writerow([search, datetime.datetime.now().time(), type_list,type_sub_list])
io.UnsupportedOperation: not writable
2019-04-17 17:53:41,098 - telegram.ext.updater - INFO - Received signal 2 (SIGINT), stopping...
2019-04-17 17:55:07,097 - telegram.ext.updater - INFO - Received signal 2 (SIGINT), stopping...
2019-04-17 17:55:44,968 - telegram.ext.dispatcher - ERROR - An uncaught error was raised while processing the update
Traceback (most recent call last):
  File "C:\Users\Administrator\AppData\Local\Programs\Python\Python37-32\lib\site-packages\telegram\ext\dispatcher.py", line 279, in process_update
    handler.handle_update(update, self)
  File "C:\Users\Administrator\AppData\Local\Programs\Python\Python37-32\lib\site-packages\telegram\ext\commandhandler.py", line 173, in handle_update
    return self.callback(dispatcher.bot, update, **optional_args)
  File "telegrambot.py", line 372, in gg
    update.message.reply_text('Try searching for : ' + str(ran[randint(0,len(ran)-1)]))
  File "C:\Users\Administrator\AppData\Local\Programs\Python\Python37-32\lib\random.py", line 222, in randint
    return self.randrange(a, b+1)
  File "C:\Users\Administrator\AppData\Local\Programs\Python\Python37-32\lib\random.py", line 200, in randrange
    raise ValueError("empty range for randrange() (%d,%d, %d)" % (istart, istop, width))
ValueError: empty range for randrange() (0,0, 0)
2019-04-17 17:58:31,321 - telegram.ext.updater - INFO - Received signal 2 (SIGINT), stopping...
2019-04-17 18:04:24,403 - telegram.ext.dispatcher - ERROR - An uncaught error was raised while processing the update
Traceback (most recent call last):
  File "C:\Users\Administrator\AppData\Local\Programs\Python\Python37-32\lib\site-packages\telegram\ext\dispatcher.py", line 279, in process_update
    handler.handle_update(update, self)
  File "C:\Users\Administrator\AppData\Local\Programs\Python\Python37-32\lib\site-packages\telegram\ext\commandhandler.py", line 173, in handle_update
    return self.callback(dispatcher.bot, update, **optional_args)
  File "telegrambot.py", line 375, in gg
    update.message.reply_text('Try searching for : ' + str(random.choice(ran)))
  File "C:\Users\Administrator\AppData\Local\Programs\Python\Python37-32\lib\random.py", line 261, in choice
    raise IndexError('Cannot choose from an empty sequence') from None
IndexError: Cannot choose from an empty sequence
2019-04-17 18:07:42,402 - telegram.ext.updater - INFO - Received signal 2 (SIGINT), stopping...
2019-04-17 18:08:45,274 - telegram.ext.updater - INFO - Received signal 2 (SIGINT), stopping...
2019-04-17 18:09:41,683 - telegram.ext.updater - INFO - Received signal 2 (SIGINT), stopping...
2019-04-17 18:17:10,890 - telegram.ext.updater - INFO - Received signal 2 (SIGINT), stopping...
2019-04-17 18:20:46,611 - telegram.ext.updater - INFO - Received signal 2 (SIGINT), stopping...
2019-04-17 18:25:58,946 - telegram.ext.updater - INFO - Received signal 2 (SIGINT), stopping...
2019-04-17 18:30:38,075 - telegram.ext.updater - INFO - Received signal 2 (SIGINT), stopping...
2019-04-17 18:36:15,948 - telegram.ext.updater - INFO - Received signal 2 (SIGINT), stopping...
2019-04-17 18:36:49,846 - telegram.ext.updater - INFO - Received signal 2 (SIGINT), stopping...
2019-04-17 18:43:10,596 - telegram.ext.updater - INFO - Received signal 2 (SIGINT), stopping...
2019-04-17 18:47:40,268 - telegram.ext.updater - INFO - Received signal 2 (SIGINT), stopping...
2019-04-17 18:52:38,133 - telegram.ext.updater - INFO - Received signal 2 (SIGINT), stopping...
2019-04-17 21:04:19,109 - telegram.ext.dispatcher - WARNING - A TelegramError was raised while processing the Update
2019-04-17 21:04:19,109 - telegram.ext.dispatcher - ERROR - No error handlers are registered, logging exception.
Traceback (most recent call last):
  File "C:\Users\Administrator\AppData\Local\Programs\Python\Python37-32\lib\site-packages\telegram\vendor\ptb_urllib3\urllib3\connectionpool.py", line 402, in _make_request
    six.raise_from(e, None)
  File "<string>", line 2, in raise_from
  File "C:\Users\Administrator\AppData\Local\Programs\Python\Python37-32\lib\site-packages\telegram\vendor\ptb_urllib3\urllib3\connectionpool.py", line 398, in _make_request
    httplib_response = conn.getresponse()
  File "C:\Users\Administrator\AppData\Local\Programs\Python\Python37-32\lib\http\client.py", line 1321, in getresponse
    response.begin()
  File "C:\Users\Administrator\AppData\Local\Programs\Python\Python37-32\lib\http\client.py", line 296, in begin
    version, status, reason = self._read_status()
  File "C:\Users\Administrator\AppData\Local\Programs\Python\Python37-32\lib\http\client.py", line 257, in _read_status
    line = str(self.fp.readline(_MAXLINE + 1), "iso-8859-1")
  File "C:\Users\Administrator\AppData\Local\Programs\Python\Python37-32\lib\socket.py", line 589, in readinto
    return self._sock.recv_into(b)
  File "C:\Users\Administrator\AppData\Local\Programs\Python\Python37-32\lib\ssl.py", line 1052, in recv_into
    return self.read(nbytes, buffer)
  File "C:\Users\Administrator\AppData\Local\Programs\Python\Python37-32\lib\ssl.py", line 911, in read
    return self._sslobj.read(len, buffer)
socket.timeout: The read operation timed out

During handling of the above exception, another exception occurred:

Traceback (most recent call last):
  File "C:\Users\Administrator\AppData\Local\Programs\Python\Python37-32\lib\site-packages\telegram\utils\request.py", line 203, in _request_wrapper
    resp = self._con_pool.request(*args, **kwargs)
  File "C:\Users\Administrator\AppData\Local\Programs\Python\Python37-32\lib\site-packages\telegram\vendor\ptb_urllib3\urllib3\request.py", line 70, in request
    **urlopen_kw)
  File "C:\Users\Administrator\AppData\Local\Programs\Python\Python37-32\lib\site-packages\telegram\vendor\ptb_urllib3\urllib3\request.py", line 148, in request_encode_body
    return self.urlopen(method, url, **extra_kw)
  File "C:\Users\Administrator\AppData\Local\Programs\Python\Python37-32\lib\site-packages\telegram\vendor\ptb_urllib3\urllib3\poolmanager.py", line 244, in urlopen
    response = conn.urlopen(method, u.request_uri, **kw)
  File "C:\Users\Administrator\AppData\Local\Programs\Python\Python37-32\lib\site-packages\telegram\vendor\ptb_urllib3\urllib3\connectionpool.py", line 666, in urlopen
    _stacktrace=sys.exc_info()[2])
  File "C:\Users\Administrator\AppData\Local\Programs\Python\Python37-32\lib\site-packages\telegram\vendor\ptb_urllib3\urllib3\util\retry.py", line 347, in increment
    raise six.reraise(type(error), error, _stacktrace)
  File "C:\Users\Administrator\AppData\Local\Programs\Python\Python37-32\lib\site-packages\telegram\vendor\ptb_urllib3\urllib3\packages\six.py", line 686, in reraise
    raise value
  File "C:\Users\Administrator\AppData\Local\Programs\Python\Python37-32\lib\site-packages\telegram\vendor\ptb_urllib3\urllib3\connectionpool.py", line 617, in urlopen
    chunked=chunked)
  File "C:\Users\Administrator\AppData\Local\Programs\Python\Python37-32\lib\site-packages\telegram\vendor\ptb_urllib3\urllib3\connectionpool.py", line 405, in _make_request
    exc_cls=ReadTimeoutError)
  File "C:\Users\Administrator\AppData\Local\Programs\Python\Python37-32\lib\site-packages\telegram\vendor\ptb_urllib3\urllib3\connectionpool.py", line 321, in _raise_timeout
    raise exc_cls(*args)
telegram.vendor.ptb_urllib3.urllib3.exceptions.ReadTimeoutError: HTTPSConnectionPool(host='api.telegram.org', port=443): Read timed out. (read timeout=5.0)

During handling of the above exception, another exception occurred:

Traceback (most recent call last):
  File "C:\Users\Administrator\AppData\Local\Programs\Python\Python37-32\lib\site-packages\telegram\ext\dispatcher.py", line 279, in process_update
    handler.handle_update(update, self)
  File "C:\Users\Administrator\AppData\Local\Programs\Python\Python37-32\lib\site-packages\telegram\ext\callbackqueryhandler.py", line 143, in handle_update
    return self.callback(dispatcher.bot, update, **optional_args)
  File "telegrambot.py", line 46, in button
    bot.edit_message_text(chat_id = update.effective_message.chat_id,message_id = update.effective_message.message_id,text = str(NewsFeed.entries[i].title) + '\n---------------------\nLink : ' + str(NewsFeed.entries[i].link) +'\n---------------------\n' + str(NewsFeed.entries[i].summary) + '\n---------------------\nPublished on :' + str(NewsFeed.entries[i].published))
  File "C:\Users\Administrator\AppData\Local\Programs\Python\Python37-32\lib\site-packages\telegram\bot.py", line 65, in decorator
    result = func(self, *args, **kwargs)
  File "C:\Users\Administrator\AppData\Local\Programs\Python\Python37-32\lib\site-packages\telegram\bot.py", line 90, in decorator
    result = self._request.post(url, data, timeout=kwargs.get('timeout'))
  File "C:\Users\Administrator\AppData\Local\Programs\Python\Python37-32\lib\site-packages\telegram\utils\request.py", line 309, in post
    headers={'Content-Type': 'application/json'})
  File "C:\Users\Administrator\AppData\Local\Programs\Python\Python37-32\lib\site-packages\telegram\utils\request.py", line 205, in _request_wrapper
    raise TimedOut()
telegram.error.TimedOut: Timed out
2019-04-17 23:18:00,501 - telegram.vendor.ptb_urllib3.urllib3.connectionpool - WARNING - Retrying (Retry(total=2, connect=None, read=None, redirect=None)) after connection broken by 'ConnectTimeoutError(<telegram.vendor.ptb_urllib3.urllib3.connectionpool.HTTPSConnectionPool object at 0x25DAC530>, 'Connect timed out. (connect timeout=5.0)')': /bot886726378:AAF9gwzWZzr0pfw-Wh5_bnnQHUybcOI6Z6g/getUpdates
2019-04-18 01:16:13,482 - telegram.vendor.ptb_urllib3.urllib3.connectionpool - WARNING - Retrying (Retry(total=2, connect=None, read=None, redirect=None)) after connection broken by 'ConnectTimeoutError(<telegram.vendor.ptb_urllib3.urllib3.connectionpool.HTTPSConnectionPool object at 0x25DAC530>, 'Connect timed out. (connect timeout=5.0)')': /bot886726378:AAF9gwzWZzr0pfw-Wh5_bnnQHUybcOI6Z6g/getUpdates
2019-04-18 02:33:20,214 - telegram.ext.updater - INFO - Received signal 2 (SIGINT), stopping...
2019-04-18 02:43:16,347 - telegram.ext.updater - INFO - Received signal 2 (SIGINT), stopping...
2019-04-18 02:50:41,404 - telegram.ext.updater - INFO - Received signal 2 (SIGINT), stopping...
2019-04-18 02:51:53,912 - telegram.ext.dispatcher - ERROR - An uncaught error was raised while processing the update
Traceback (most recent call last):
  File "C:\Users\Administrator\AppData\Local\Programs\Python\Python37-32\lib\site-packages\telegram\ext\dispatcher.py", line 279, in process_update
    handler.handle_update(update, self)
  File "C:\Users\Administrator\AppData\Local\Programs\Python\Python37-32\lib\site-packages\telegram\ext\commandhandler.py", line 173, in handle_update
    return self.callback(dispatcher.bot, update, **optional_args)
  File "telegrambot.py", line 374, in gg
    for row in table:
  File "C:\Users\Administrator\AppData\Local\Programs\Python\Python37-32\lib\csv.py", line 112, in __next__
    row = next(self.reader)
ValueError: I/O operation on closed file.
2019-04-18 02:52:31,387 - telegram.ext.updater - INFO - Received signal 2 (SIGINT), stopping...
2019-04-18 02:53:51,959 - telegram.ext.dispatcher - ERROR - An uncaught error was raised while processing the update
Traceback (most recent call last):
  File "C:\Users\Administrator\AppData\Local\Programs\Python\Python37-32\lib\site-packages\telegram\ext\dispatcher.py", line 279, in process_update
    handler.handle_update(update, self)
  File "C:\Users\Administrator\AppData\Local\Programs\Python\Python37-32\lib\site-packages\telegram\ext\commandhandler.py", line 173, in handle_update
    return self.callback(dispatcher.bot, update, **optional_args)
  File "telegrambot.py", line 374, in gg
    for row in write:
TypeError: '_csv.writer' object is not iterable
2019-04-18 02:55:04,499 - telegram.ext.updater - INFO - Received signal 2 (SIGINT), stopping...
2019-04-18 03:08:12,028 - telegram.ext.updater - INFO - Received signal 2 (SIGINT), stopping...
2019-04-18 03:19:54,604 - telegram.ext.updater - INFO - Received signal 2 (SIGINT), stopping...
2019-04-18 03:21:58,237 - telegram.ext.updater - INFO - Received signal 2 (SIGINT), stopping...
2019-04-18 03:22:34,247 - telegram.ext.dispatcher - ERROR - An uncaught error was raised while processing the update
Traceback (most recent call last):
  File "C:\Users\Administrator\AppData\Local\Programs\Python\Python37-32\lib\site-packages\telegram\ext\dispatcher.py", line 279, in process_update
    handler.handle_update(update, self)
  File "C:\Users\Administrator\AppData\Local\Programs\Python\Python37-32\lib\site-packages\telegram\ext\commandhandler.py", line 173, in handle_update
    return self.callback(dispatcher.bot, update, **optional_args)
  File "telegrambot.py", line 363, in gg
    short = s.short(long_url)
  File "C:\Users\Administrator\AppData\Local\Programs\Python\Python37-32\lib\site-packages\pyshorteners\shorteners\__init__.py", line 115, in short
    self.shorten = self._class(**self.kwargs).short(url)
TypeError: 'module' object is not callable
2019-04-18 03:24:17,666 - telegram.ext.updater - INFO - Received signal 2 (SIGINT), stopping...
2019-04-19 14:26:03,470 - telegram.ext.dispatcher - ERROR - An uncaught error was raised while processing the update
Traceback (most recent call last):
  File "C:\Users\Administrator\AppData\Local\Programs\Python\Python37-32\lib\site-packages\telegram\ext\dispatcher.py", line 279, in process_update
    handler.handle_update(update, self)
  File "C:\Users\Administrator\AppData\Local\Programs\Python\Python37-32\lib\site-packages\telegram\ext\inlinequeryhandler.py", line 144, in handle_update
    return self.callback(dispatcher.bot, update, **optional_args)
TypeError: inline() got an unexpected keyword argument 'user_data'
2019-04-19 14:26:36,904 - telegram.ext.updater - INFO - Received signal 2 (SIGINT), stopping...
2019-04-19 14:27:03,944 - telegram.ext.dispatcher - ERROR - An uncaught error was raised while processing the update
Traceback (most recent call last):
  File "C:\Users\Administrator\AppData\Local\Programs\Python\Python37-32\lib\site-packages\telegram\ext\dispatcher.py", line 279, in process_update
    handler.handle_update(update, self)
  File "C:\Users\Administrator\AppData\Local\Programs\Python\Python37-32\lib\site-packages\telegram\ext\inlinequeryhandler.py", line 144, in handle_update
    return self.callback(dispatcher.bot, update, **optional_args)
TypeError: inline() got an unexpected keyword argument 'user_data'
2019-04-19 14:27:35,007 - telegram.ext.updater - INFO - Received signal 2 (SIGINT), stopping...
2019-04-19 14:28:03,364 - telegram.ext.dispatcher - ERROR - An uncaught error was raised while processing the update
Traceback (most recent call last):
  File "C:\Users\Administrator\AppData\Local\Programs\Python\Python37-32\lib\site-packages\telegram\ext\dispatcher.py", line 279, in process_update
    handler.handle_update(update, self)
  File "C:\Users\Administrator\AppData\Local\Programs\Python\Python37-32\lib\site-packages\telegram\ext\inlinequeryhandler.py", line 144, in handle_update
    return self.callback(dispatcher.bot, update, **optional_args)
TypeError: inline() got an unexpected keyword argument 'user_data'
2019-04-19 14:28:03,365 - telegram.ext.dispatcher - ERROR - An uncaught error was raised while processing the update
Traceback (most recent call last):
  File "C:\Users\Administrator\AppData\Local\Programs\Python\Python37-32\lib\site-packages\telegram\ext\dispatcher.py", line 279, in process_update
    handler.handle_update(update, self)
  File "C:\Users\Administrator\AppData\Local\Programs\Python\Python37-32\lib\site-packages\telegram\ext\inlinequeryhandler.py", line 144, in handle_update
    return self.callback(dispatcher.bot, update, **optional_args)
TypeError: inline() got an unexpected keyword argument 'user_data'
2019-04-19 14:28:03,366 - telegram.ext.dispatcher - ERROR - An uncaught error was raised while processing the update
Traceback (most recent call last):
  File "C:\Users\Administrator\AppData\Local\Programs\Python\Python37-32\lib\site-packages\telegram\ext\dispatcher.py", line 279, in process_update
    handler.handle_update(update, self)
  File "C:\Users\Administrator\AppData\Local\Programs\Python\Python37-32\lib\site-packages\telegram\ext\inlinequeryhandler.py", line 144, in handle_update
    return self.callback(dispatcher.bot, update, **optional_args)
TypeError: inline() got an unexpected keyword argument 'user_data'
2019-04-19 14:28:03,366 - telegram.ext.dispatcher - ERROR - An uncaught error was raised while processing the update
Traceback (most recent call last):
  File "C:\Users\Administrator\AppData\Local\Programs\Python\Python37-32\lib\site-packages\telegram\ext\dispatcher.py", line 279, in process_update
    handler.handle_update(update, self)
  File "C:\Users\Administrator\AppData\Local\Programs\Python\Python37-32\lib\site-packages\telegram\ext\inlinequeryhandler.py", line 144, in handle_update
    return self.callback(dispatcher.bot, update, **optional_args)
TypeError: inline() got an unexpected keyword argument 'user_data'
2019-04-19 14:28:03,366 - telegram.ext.dispatcher - ERROR - An uncaught error was raised while processing the update
Traceback (most recent call last):
  File "C:\Users\Administrator\AppData\Local\Programs\Python\Python37-32\lib\site-packages\telegram\ext\dispatcher.py", line 279, in process_update
    handler.handle_update(update, self)
  File "C:\Users\Administrator\AppData\Local\Programs\Python\Python37-32\lib\site-packages\telegram\ext\inlinequeryhandler.py", line 144, in handle_update
    return self.callback(dispatcher.bot, update, **optional_args)
TypeError: inline() got an unexpected keyword argument 'user_data'
2019-04-19 14:28:03,367 - telegram.ext.dispatcher - ERROR - An uncaught error was raised while processing the update
Traceback (most recent call last):
  File "C:\Users\Administrator\AppData\Local\Programs\Python\Python37-32\lib\site-packages\telegram\ext\dispatcher.py", line 279, in process_update
    handler.handle_update(update, self)
  File "C:\Users\Administrator\AppData\Local\Programs\Python\Python37-32\lib\site-packages\telegram\ext\inlinequeryhandler.py", line 144, in handle_update
    return self.callback(dispatcher.bot, update, **optional_args)
TypeError: inline() got an unexpected keyword argument 'user_data'
2019-04-19 14:28:04,050 - telegram.ext.dispatcher - ERROR - An uncaught error was raised while processing the update
Traceback (most recent call last):
  File "C:\Users\Administrator\AppData\Local\Programs\Python\Python37-32\lib\site-packages\telegram\ext\dispatcher.py", line 279, in process_update
    handler.handle_update(update, self)
  File "C:\Users\Administrator\AppData\Local\Programs\Python\Python37-32\lib\site-packages\telegram\ext\inlinequeryhandler.py", line 144, in handle_update
    return self.callback(dispatcher.bot, update, **optional_args)
TypeError: inline() got an unexpected keyword argument 'user_data'
2019-04-19 14:28:04,595 - telegram.ext.dispatcher - ERROR - An uncaught error was raised while processing the update
Traceback (most recent call last):
  File "C:\Users\Administrator\AppData\Local\Programs\Python\Python37-32\lib\site-packages\telegram\ext\dispatcher.py", line 279, in process_update
    handler.handle_update(update, self)
  File "C:\Users\Administrator\AppData\Local\Programs\Python\Python37-32\lib\site-packages\telegram\ext\inlinequeryhandler.py", line 144, in handle_update
    return self.callback(dispatcher.bot, update, **optional_args)
TypeError: inline() got an unexpected keyword argument 'user_data'
2019-04-19 14:28:05,602 - telegram.ext.dispatcher - ERROR - An uncaught error was raised while processing the update
Traceback (most recent call last):
  File "C:\Users\Administrator\AppData\Local\Programs\Python\Python37-32\lib\site-packages\telegram\ext\dispatcher.py", line 279, in process_update
    handler.handle_update(update, self)
  File "C:\Users\Administrator\AppData\Local\Programs\Python\Python37-32\lib\site-packages\telegram\ext\inlinequeryhandler.py", line 144, in handle_update
    return self.callback(dispatcher.bot, update, **optional_args)
TypeError: inline() got an unexpected keyword argument 'user_data'
2019-04-19 14:28:09,519 - telegram.ext.dispatcher - ERROR - An uncaught error was raised while processing the update
Traceback (most recent call last):
  File "C:\Users\Administrator\AppData\Local\Programs\Python\Python37-32\lib\site-packages\telegram\ext\dispatcher.py", line 279, in process_update
    handler.handle_update(update, self)
  File "C:\Users\Administrator\AppData\Local\Programs\Python\Python37-32\lib\site-packages\telegram\ext\inlinequeryhandler.py", line 144, in handle_update
    return self.callback(dispatcher.bot, update, **optional_args)
TypeError: inline() got an unexpected keyword argument 'user_data'
2019-04-19 14:28:13,501 - telegram.ext.dispatcher - ERROR - An uncaught error was raised while processing the update
Traceback (most recent call last):
  File "C:\Users\Administrator\AppData\Local\Programs\Python\Python37-32\lib\site-packages\telegram\ext\dispatcher.py", line 279, in process_update
    handler.handle_update(update, self)
  File "C:\Users\Administrator\AppData\Local\Programs\Python\Python37-32\lib\site-packages\telegram\ext\inlinequeryhandler.py", line 144, in handle_update
    return self.callback(dispatcher.bot, update, **optional_args)
TypeError: inline() got an unexpected keyword argument 'user_data'
2019-04-19 14:28:33,219 - telegram.ext.dispatcher - ERROR - An uncaught error was raised while processing the update
Traceback (most recent call last):
  File "C:\Users\Administrator\AppData\Local\Programs\Python\Python37-32\lib\site-packages\telegram\ext\dispatcher.py", line 279, in process_update
    handler.handle_update(update, self)
  File "C:\Users\Administrator\AppData\Local\Programs\Python\Python37-32\lib\site-packages\telegram\ext\inlinequeryhandler.py", line 144, in handle_update
    return self.callback(dispatcher.bot, update, **optional_args)
TypeError: inline() got an unexpected keyword argument 'user_data'
2019-04-19 14:28:39,030 - telegram.ext.dispatcher - ERROR - An uncaught error was raised while processing the update
Traceback (most recent call last):
  File "C:\Users\Administrator\AppData\Local\Programs\Python\Python37-32\lib\site-packages\telegram\ext\dispatcher.py", line 279, in process_update
    handler.handle_update(update, self)
  File "C:\Users\Administrator\AppData\Local\Programs\Python\Python37-32\lib\site-packages\telegram\ext\inlinequeryhandler.py", line 144, in handle_update
    return self.callback(dispatcher.bot, update, **optional_args)
TypeError: inline() got an unexpected keyword argument 'user_data'
2019-04-19 14:28:39,229 - telegram.ext.dispatcher - ERROR - An uncaught error was raised while processing the update
Traceback (most recent call last):
  File "C:\Users\Administrator\AppData\Local\Programs\Python\Python37-32\lib\site-packages\telegram\ext\dispatcher.py", line 279, in process_update
    handler.handle_update(update, self)
  File "C:\Users\Administrator\AppData\Local\Programs\Python\Python37-32\lib\site-packages\telegram\ext\inlinequeryhandler.py", line 144, in handle_update
    return self.callback(dispatcher.bot, update, **optional_args)
TypeError: inline() got an unexpected keyword argument 'user_data'
2019-04-19 14:28:46,274 - telegram.ext.dispatcher - ERROR - An uncaught error was raised while processing the update
Traceback (most recent call last):
  File "C:\Users\Administrator\AppData\Local\Programs\Python\Python37-32\lib\site-packages\telegram\ext\dispatcher.py", line 279, in process_update
    handler.handle_update(update, self)
  File "C:\Users\Administrator\AppData\Local\Programs\Python\Python37-32\lib\site-packages\telegram\ext\commandhandler.py", line 173, in handle_update
    return self.callback(dispatcher.bot, update, **optional_args)
  File "telegrambot.py", line 392, in gg
    write.writerow([search, datetime.datetime.now().time(), type_list,type_sub_list])
NameError: name 'search' is not defined
2019-04-19 14:34:06,671 - telegram.ext.updater - INFO - Received signal 2 (SIGINT), stopping...
2019-04-19 14:46:36,131 - telegram.ext.dispatcher - ERROR - An uncaught error was raised while processing the update
Traceback (most recent call last):
  File "C:\Users\Administrator\AppData\Local\Programs\Python\Python37-32\lib\site-packages\telegram\ext\dispatcher.py", line 279, in process_update
    handler.handle_update(update, self)
  File "C:\Users\Administrator\AppData\Local\Programs\Python\Python37-32\lib\site-packages\telegram\ext\inlinequeryhandler.py", line 144, in handle_update
    return self.callback(dispatcher.bot, update, **optional_args)
TypeError: inline() got an unexpected keyword argument 'user_data'
2019-04-19 14:46:38,258 - telegram.ext.dispatcher - ERROR - An uncaught error was raised while processing the update
Traceback (most recent call last):
  File "C:\Users\Administrator\AppData\Local\Programs\Python\Python37-32\lib\site-packages\telegram\ext\dispatcher.py", line 279, in process_update
    handler.handle_update(update, self)
  File "C:\Users\Administrator\AppData\Local\Programs\Python\Python37-32\lib\site-packages\telegram\ext\inlinequeryhandler.py", line 144, in handle_update
    return self.callback(dispatcher.bot, update, **optional_args)
TypeError: inline() got an unexpected keyword argument 'user_data'
2019-04-19 14:46:39,878 - telegram.ext.dispatcher - ERROR - An uncaught error was raised while processing the update
Traceback (most recent call last):
  File "C:\Users\Administrator\AppData\Local\Programs\Python\Python37-32\lib\site-packages\telegram\ext\dispatcher.py", line 279, in process_update
    handler.handle_update(update, self)
  File "C:\Users\Administrator\AppData\Local\Programs\Python\Python37-32\lib\site-packages\telegram\ext\inlinequeryhandler.py", line 144, in handle_update
    return self.callback(dispatcher.bot, update, **optional_args)
TypeError: inline() got an unexpected keyword argument 'user_data'
2019-04-19 14:46:41,306 - telegram.ext.dispatcher - ERROR - An uncaught error was raised while processing the update
Traceback (most recent call last):
  File "C:\Users\Administrator\AppData\Local\Programs\Python\Python37-32\lib\site-packages\telegram\ext\dispatcher.py", line 279, in process_update
    handler.handle_update(update, self)
  File "C:\Users\Administrator\AppData\Local\Programs\Python\Python37-32\lib\site-packages\telegram\ext\inlinequeryhandler.py", line 144, in handle_update
    return self.callback(dispatcher.bot, update, **optional_args)
TypeError: inline() got an unexpected keyword argument 'user_data'
2019-04-19 14:46:41,714 - telegram.ext.dispatcher - ERROR - An uncaught error was raised while processing the update
Traceback (most recent call last):
  File "C:\Users\Administrator\AppData\Local\Programs\Python\Python37-32\lib\site-packages\telegram\ext\dispatcher.py", line 279, in process_update
    handler.handle_update(update, self)
  File "C:\Users\Administrator\AppData\Local\Programs\Python\Python37-32\lib\site-packages\telegram\ext\inlinequeryhandler.py", line 144, in handle_update
    return self.callback(dispatcher.bot, update, **optional_args)
TypeError: inline() got an unexpected keyword argument 'user_data'
2019-04-19 14:46:41,914 - telegram.ext.dispatcher - ERROR - An uncaught error was raised while processing the update
Traceback (most recent call last):
  File "C:\Users\Administrator\AppData\Local\Programs\Python\Python37-32\lib\site-packages\telegram\ext\dispatcher.py", line 279, in process_update
    handler.handle_update(update, self)
  File "C:\Users\Administrator\AppData\Local\Programs\Python\Python37-32\lib\site-packages\telegram\ext\inlinequeryhandler.py", line 144, in handle_update
    return self.callback(dispatcher.bot, update, **optional_args)
TypeError: inline() got an unexpected keyword argument 'user_data'
2019-04-19 15:45:49,546 - telegram.vendor.ptb_urllib3.urllib3.connectionpool - WARNING - Retrying (Retry(total=2, connect=None, read=None, redirect=None)) after connection broken by 'ConnectTimeoutError(<telegram.vendor.ptb_urllib3.urllib3.connectionpool.HTTPSConnectionPool object at 0x26244650>, 'Connect timed out. (connect timeout=5.0)')': /bot886726378:AAF9gwzWZzr0pfw-Wh5_bnnQHUybcOI6Z6g/getUpdates
2019-04-19 15:46:06,326 - telegram.vendor.ptb_urllib3.urllib3.connectionpool - WARNING - Retrying (Retry(total=2, connect=None, read=None, redirect=None)) after connection broken by 'ConnectTimeoutError(<telegram.vendor.ptb_urllib3.urllib3.connectionpool.HTTPSConnectionPool object at 0x26244650>, 'Connect timed out. (connect timeout=5.0)')': /bot886726378:AAF9gwzWZzr0pfw-Wh5_bnnQHUybcOI6Z6g/getUpdates
2019-04-19 15:47:13,733 - telegram.vendor.ptb_urllib3.urllib3.connectionpool - WARNING - Retrying (Retry(total=2, connect=None, read=None, redirect=None)) after connection broken by 'ConnectTimeoutError(<telegram.vendor.ptb_urllib3.urllib3.connectionpool.HTTPSConnectionPool object at 0x26244650>, 'Connect timed out. (connect timeout=5.0)')': /bot886726378:AAF9gwzWZzr0pfw-Wh5_bnnQHUybcOI6Z6g/getUpdates
2019-04-19 15:48:40,809 - telegram.vendor.ptb_urllib3.urllib3.connectionpool - WARNING - Retrying (Retry(total=2, connect=None, read=None, redirect=None)) after connection broken by 'ConnectTimeoutError(<telegram.vendor.ptb_urllib3.urllib3.connectionpool.HTTPSConnectionPool object at 0x26244650>, 'Connect timed out. (connect timeout=5.0)')': /bot886726378:AAF9gwzWZzr0pfw-Wh5_bnnQHUybcOI6Z6g/getUpdates
2019-04-19 15:49:00,422 - telegram.vendor.ptb_urllib3.urllib3.connectionpool - WARNING - Retrying (Retry(total=2, connect=None, read=None, redirect=None)) after connection broken by 'ConnectTimeoutError(<telegram.vendor.ptb_urllib3.urllib3.connectionpool.HTTPSConnectionPool object at 0x26244650>, 'Connect timed out. (connect timeout=5.0)')': /bot886726378:AAF9gwzWZzr0pfw-Wh5_bnnQHUybcOI6Z6g/getUpdates
2019-04-19 17:20:19,538 - telegram.ext.updater - INFO - Received signal 2 (SIGINT), stopping...
2019-04-19 17:21:17,232 - telegram.ext.dispatcher - ERROR - An uncaught error was raised while processing the update
Traceback (most recent call last):
  File "C:\Users\Administrator\AppData\Local\Programs\Python\Python37-32\lib\site-packages\urllib3\connectionpool.py", line 384, in _make_request
    six.raise_from(e, None)
  File "<string>", line 2, in raise_from
  File "C:\Users\Administrator\AppData\Local\Programs\Python\Python37-32\lib\site-packages\urllib3\connectionpool.py", line 380, in _make_request
    httplib_response = conn.getresponse()
  File "C:\Users\Administrator\AppData\Local\Programs\Python\Python37-32\lib\http\client.py", line 1321, in getresponse
    response.begin()
  File "C:\Users\Administrator\AppData\Local\Programs\Python\Python37-32\lib\http\client.py", line 296, in begin
    version, status, reason = self._read_status()
  File "C:\Users\Administrator\AppData\Local\Programs\Python\Python37-32\lib\http\client.py", line 257, in _read_status
    line = str(self.fp.readline(_MAXLINE + 1), "iso-8859-1")
  File "C:\Users\Administrator\AppData\Local\Programs\Python\Python37-32\lib\socket.py", line 589, in readinto
    return self._sock.recv_into(b)
socket.timeout: timed out

During handling of the above exception, another exception occurred:

Traceback (most recent call last):
  File "C:\Users\Administrator\AppData\Local\Programs\Python\Python37-32\lib\site-packages\requests\adapters.py", line 449, in send
    timeout=timeout
  File "C:\Users\Administrator\AppData\Local\Programs\Python\Python37-32\lib\site-packages\urllib3\connectionpool.py", line 638, in urlopen
    _stacktrace=sys.exc_info()[2])
  File "C:\Users\Administrator\AppData\Local\Programs\Python\Python37-32\lib\site-packages\urllib3\util\retry.py", line 367, in increment
    raise six.reraise(type(error), error, _stacktrace)
  File "C:\Users\Administrator\AppData\Local\Programs\Python\Python37-32\lib\site-packages\urllib3\packages\six.py", line 686, in reraise
    raise value
  File "C:\Users\Administrator\AppData\Local\Programs\Python\Python37-32\lib\site-packages\urllib3\connectionpool.py", line 600, in urlopen
    chunked=chunked)
  File "C:\Users\Administrator\AppData\Local\Programs\Python\Python37-32\lib\site-packages\urllib3\connectionpool.py", line 386, in _make_request
    self._raise_timeout(err=e, url=url, timeout_value=read_timeout)
  File "C:\Users\Administrator\AppData\Local\Programs\Python\Python37-32\lib\site-packages\urllib3\connectionpool.py", line 306, in _raise_timeout
    raise ReadTimeoutError(self, url, "Read timed out. (read timeout=%s)" % timeout_value)
urllib3.exceptions.ReadTimeoutError: HTTPConnectionPool(host='tinyurl.com', port=80): Read timed out. (read timeout=0.5)

During handling of the above exception, another exception occurred:

Traceback (most recent call last):
  File "C:\Users\Administrator\AppData\Local\Programs\Python\Python37-32\lib\site-packages\telegram\ext\dispatcher.py", line 279, in process_update
    handler.handle_update(update, self)
  File "C:\Users\Administrator\AppData\Local\Programs\Python\Python37-32\lib\site-packages\telegram\ext\commandhandler.py", line 173, in handle_update
    return self.callback(dispatcher.bot, update, **optional_args)
  File "telegrambot.py", line 396, in gg
    shorturl = s.short(longurl)
  File "C:\Users\Administrator\AppData\Local\Programs\Python\Python37-32\lib\site-packages\pyshorteners\shorteners\__init__.py", line 115, in short
    self.shorten = self._class(**self.kwargs).short(url)
  File "C:\Users\Administrator\AppData\Local\Programs\Python\Python37-32\lib\site-packages\pyshorteners\shorteners\tinyurl.py", line 13, in short
    response = self._get(self.api_url, params=dict(url=url))
  File "C:\Users\Administrator\AppData\Local\Programs\Python\Python37-32\lib\site-packages\pyshorteners\shorteners\base.py", line 25, in _get
    timeout=self.kwargs['timeout'])
  File "C:\Users\Administrator\AppData\Local\Programs\Python\Python37-32\lib\site-packages\requests\api.py", line 75, in get
    return request('get', url, params=params, **kwargs)
  File "C:\Users\Administrator\AppData\Local\Programs\Python\Python37-32\lib\site-packages\requests\api.py", line 60, in request
    return session.request(method=method, url=url, **kwargs)
  File "C:\Users\Administrator\AppData\Local\Programs\Python\Python37-32\lib\site-packages\requests\sessions.py", line 533, in request
    resp = self.send(prep, **send_kwargs)
  File "C:\Users\Administrator\AppData\Local\Programs\Python\Python37-32\lib\site-packages\requests\sessions.py", line 646, in send
    r = adapter.send(request, **kwargs)
  File "C:\Users\Administrator\AppData\Local\Programs\Python\Python37-32\lib\site-packages\requests\adapters.py", line 529, in send
    raise ReadTimeout(e, request=request)
requests.exceptions.ReadTimeout: HTTPConnectionPool(host='tinyurl.com', port=80): Read timed out. (read timeout=0.5)
2019-05-04 13:16:34,037 - telegram.ext.dispatcher - ERROR - An uncaught error was raised while processing the update
Traceback (most recent call last):
  File "C:\Users\Administrator\AppData\Local\Programs\Python\Python37-32\lib\site-packages\urllib3\connectionpool.py", line 384, in _make_request
    six.raise_from(e, None)
  File "<string>", line 2, in raise_from
  File "C:\Users\Administrator\AppData\Local\Programs\Python\Python37-32\lib\site-packages\urllib3\connectionpool.py", line 380, in _make_request
    httplib_response = conn.getresponse()
  File "C:\Users\Administrator\AppData\Local\Programs\Python\Python37-32\lib\http\client.py", line 1321, in getresponse
    response.begin()
  File "C:\Users\Administrator\AppData\Local\Programs\Python\Python37-32\lib\http\client.py", line 296, in begin
    version, status, reason = self._read_status()
  File "C:\Users\Administrator\AppData\Local\Programs\Python\Python37-32\lib\http\client.py", line 257, in _read_status
    line = str(self.fp.readline(_MAXLINE + 1), "iso-8859-1")
  File "C:\Users\Administrator\AppData\Local\Programs\Python\Python37-32\lib\socket.py", line 589, in readinto
    return self._sock.recv_into(b)
socket.timeout: timed out

During handling of the above exception, another exception occurred:

Traceback (most recent call last):
  File "C:\Users\Administrator\AppData\Local\Programs\Python\Python37-32\lib\site-packages\requests\adapters.py", line 449, in send
    timeout=timeout
  File "C:\Users\Administrator\AppData\Local\Programs\Python\Python37-32\lib\site-packages\urllib3\connectionpool.py", line 638, in urlopen
    _stacktrace=sys.exc_info()[2])
  File "C:\Users\Administrator\AppData\Local\Programs\Python\Python37-32\lib\site-packages\urllib3\util\retry.py", line 367, in increment
    raise six.reraise(type(error), error, _stacktrace)
  File "C:\Users\Administrator\AppData\Local\Programs\Python\Python37-32\lib\site-packages\urllib3\packages\six.py", line 686, in reraise
    raise value
  File "C:\Users\Administrator\AppData\Local\Programs\Python\Python37-32\lib\site-packages\urllib3\connectionpool.py", line 600, in urlopen
    chunked=chunked)
  File "C:\Users\Administrator\AppData\Local\Programs\Python\Python37-32\lib\site-packages\urllib3\connectionpool.py", line 386, in _make_request
    self._raise_timeout(err=e, url=url, timeout_value=read_timeout)
  File "C:\Users\Administrator\AppData\Local\Programs\Python\Python37-32\lib\site-packages\urllib3\connectionpool.py", line 306, in _raise_timeout
    raise ReadTimeoutError(self, url, "Read timed out. (read timeout=%s)" % timeout_value)
urllib3.exceptions.ReadTimeoutError: HTTPConnectionPool(host='tinyurl.com', port=80): Read timed out. (read timeout=0.5)

During handling of the above exception, another exception occurred:

Traceback (most recent call last):
  File "C:\Users\Administrator\AppData\Local\Programs\Python\Python37-32\lib\site-packages\telegram\ext\dispatcher.py", line 279, in process_update
    handler.handle_update(update, self)
  File "C:\Users\Administrator\AppData\Local\Programs\Python\Python37-32\lib\site-packages\telegram\ext\commandhandler.py", line 173, in handle_update
    return self.callback(dispatcher.bot, update, **optional_args)
  File "telegrambot.py", line 396, in gg
    shorturl = s.short(longurl)
  File "C:\Users\Administrator\AppData\Local\Programs\Python\Python37-32\lib\site-packages\pyshorteners\shorteners\__init__.py", line 115, in short
    self.shorten = self._class(**self.kwargs).short(url)
  File "C:\Users\Administrator\AppData\Local\Programs\Python\Python37-32\lib\site-packages\pyshorteners\shorteners\tinyurl.py", line 13, in short
    response = self._get(self.api_url, params=dict(url=url))
  File "C:\Users\Administrator\AppData\Local\Programs\Python\Python37-32\lib\site-packages\pyshorteners\shorteners\base.py", line 25, in _get
    timeout=self.kwargs['timeout'])
  File "C:\Users\Administrator\AppData\Local\Programs\Python\Python37-32\lib\site-packages\requests\api.py", line 75, in get
    return request('get', url, params=params, **kwargs)
  File "C:\Users\Administrator\AppData\Local\Programs\Python\Python37-32\lib\site-packages\requests\api.py", line 60, in request
    return session.request(method=method, url=url, **kwargs)
  File "C:\Users\Administrator\AppData\Local\Programs\Python\Python37-32\lib\site-packages\requests\sessions.py", line 533, in request
    resp = self.send(prep, **send_kwargs)
  File "C:\Users\Administrator\AppData\Local\Programs\Python\Python37-32\lib\site-packages\requests\sessions.py", line 646, in send
    r = adapter.send(request, **kwargs)
  File "C:\Users\Administrator\AppData\Local\Programs\Python\Python37-32\lib\site-packages\requests\adapters.py", line 529, in send
    raise ReadTimeout(e, request=request)
requests.exceptions.ReadTimeout: HTTPConnectionPool(host='tinyurl.com', port=80): Read timed out. (read timeout=0.5)
2019-05-04 13:17:12,264 - telegram.ext.updater - INFO - Received signal 2 (SIGINT), stopping...
2019-05-04 13:20:26,017 - telegram.ext.updater - INFO - Received signal 2 (SIGINT), stopping...
2019-05-04 13:24:27,697 - telegram.ext.updater - INFO - Received signal 2 (SIGINT), stopping...
2019-05-04 13:24:57,869 - telegram.ext.dispatcher - ERROR - An uncaught error was raised while processing the update
Traceback (most recent call last):
  File "C:\Users\Administrator\AppData\Local\Programs\Python\Python37-32\lib\site-packages\telegram\ext\dispatcher.py", line 279, in process_update
    handler.handle_update(update, self)
  File "C:\Users\Administrator\AppData\Local\Programs\Python\Python37-32\lib\site-packages\telegram\ext\commandhandler.py", line 173, in handle_update
    return self.callback(dispatcher.bot, update, **optional_args)
  File "telegrambot.py", line 386, in gg
    for row in data:
  File "C:\Users\Administrator\AppData\Local\Programs\Python\Python37-32\lib\csv.py", line 111, in __next__
    self.fieldnames
  File "C:\Users\Administrator\AppData\Local\Programs\Python\Python37-32\lib\csv.py", line 98, in fieldnames
    self._fieldnames = next(self.reader)
io.UnsupportedOperation: not readable
2019-05-04 13:25:14,605 - telegram.ext.dispatcher - ERROR - An uncaught error was raised while processing the update
Traceback (most recent call last):
  File "C:\Users\Administrator\AppData\Local\Programs\Python\Python37-32\lib\site-packages\telegram\ext\dispatcher.py", line 279, in process_update
    handler.handle_update(update, self)
  File "C:\Users\Administrator\AppData\Local\Programs\Python\Python37-32\lib\site-packages\telegram\ext\commandhandler.py", line 173, in handle_update
    return self.callback(dispatcher.bot, update, **optional_args)
  File "telegrambot.py", line 386, in gg
    for row in data:
  File "C:\Users\Administrator\AppData\Local\Programs\Python\Python37-32\lib\csv.py", line 111, in __next__
    self.fieldnames
  File "C:\Users\Administrator\AppData\Local\Programs\Python\Python37-32\lib\csv.py", line 98, in fieldnames
    self._fieldnames = next(self.reader)
io.UnsupportedOperation: not readable
2019-05-04 13:30:15,960 - telegram.ext.updater - INFO - Received signal 2 (SIGINT), stopping...
2019-05-04 13:39:32,121 - telegram.ext.updater - INFO - Received signal 2 (SIGINT), stopping...
2019-05-04 13:44:01,594 - telegram.ext.updater - INFO - Received signal 2 (SIGINT), stopping...
2019-05-04 13:46:15,361 - telegram.ext.updater - INFO - Received signal 2 (SIGINT), stopping...
2019-05-04 18:08:09,158 - telegram.ext.updater - INFO - Received signal 2 (SIGINT), stopping...
